Workbook
Name pw_Damage: 'PowerLevel'!$B$3
Name pw_Poison: 'PowerLevel'!$B$4
Name pw_Shield: 'PowerLevel'!$B$5
Name pw_Block: 'PowerLevel'!$B$6
Name pw_Teleport: 'PowerLevel'!$B$7
Name pw_Move: 'PowerLevel'!$B$8
Name pw_Health: 'PowerLevel'!$B$9
Name pw_Divisor: 'PowerLevel'!$B$10
Name pw_Heal: 'PowerLevel'!$B$11
Name pw_Strength: 'PowerLevel'!$B$12
Name pw_DoubleNextAttack: 'PowerLevel'!$B$13
Name pw_PoisonBlade: 'PowerLevel'!$B$14
Name pw_Parry: 'PowerLevel'!$B$15
Name pw_Dodge: 'PowerLevel'!$B$16
Name pw_DoubleShield: 'PowerLevel'!$B$17
Name pw_Frozen: 'PowerLevel'!$B$18
Name pw_Rooted: 'PowerLevel'!$B$19
Name pw_Weaken: 'PowerLevel'!$B$20
Name pw_Vulnerable: 'PowerLevel'!$B$21
Name pw_Taunt: 'PowerLevel'!$B$22
Name pw_Stealth: 'PowerLevel'!$B$23
Name pw_Summon: 'PowerLevel'!$B$24
Name pw_SummonHorizon: 'PowerLevel'!$B$25
Name pw_TotemActivations: 'PowerLevel'!$B$26
Name pw_Area: 'PowerLevel'!$B$27
Name pw_Horizon: 'PowerLevel'!$B$28
Name pw_Draw: 'PowerLevel'!$B$29
Name pw_Energy: 'PowerLevel'!$B$30
Name pw_TileEffect: 'PowerLevel'!$B$31
Name pw_SelfDamage: 'PowerLevel'!$B$32
Name pw_ActionScale: 'PowerLevel'!$B$33
Name pw_Tolerance: 'PowerLevel'!$B$34
Name range_Power: 'PowerLevel'!$A$39:$B$44
Name list_Brain: 'Enums'!$A$2:$A$5
Name list_Targeting: 'Enums'!$B$2:$B$12
Name list_Loot: 'Enums'!$C$2:$C$14
Name list_Role: 'Enums'!$D$2:$D$5
Name list_Bool: 'Enums'!$E$2:$E$3
Name list_EnemyCard: 'Enums'!$F$2:$F$49
Name pow_Bat: 'Summoned'!$B$3
Name pow_Goblin: 'Summoned'!$B$4
Name pow_HeavyBandit: 'Summoned'!$B$5
Name pow_LightBandit: 'Summoned'!$B$6
Name pow_Pebble: 'Summoned'!$B$7
Name pow_Skeleton: 'Summoned'!$B$8
Name pow_Slime: 'Summoned'!$B$9
Name pow_BlackKnight: 'BlackKnight'!$B$16
Name pow_EvilKing: 'EvilKing'!$B$16
Name pow_EvilKnight: 'EvilKnight'!$B$16
Name pow_EvilWizard: 'EvilWizard'!$B$16
Name pow_EvilWizard2: 'EvilWizard2'!$B$16
Name pow_EvilWizard3: 'EvilWizard3'!$B$16
Name pow_Reaper: 'Reaper'!$B$16
Name pow_ReinforcedGolem: 'ReinforcedGolem'!$B$16

Sheet README
A1: Boss Design Workbook
A3: One tab per boss and totem, all built from the actual prefabs and cards under Assets/Prefabs/Bosses and Assets/Data/CardData/Enemy - this workbook only READS them today. Ordinary enemies and the ally live in Docs/EnemySheets.xlsx instead.
A5: The tabs
A6: PowerLevel | B6: READ-ONLY here - the pw_* weights are mirrored from Docs\EnemySheets.xlsx on every export so both workbooks score on one scale. Retune them there; anything typed on that tab here is discarded on the next sync.
A7: One tab per body | B7: Health, Actions Per Turn, Brain, Targeting, Loot Table, Role and Deck mirror the prefab's Character component. Card Facts below the deck strip are read from each card's own CardData/CardEffect assets - edit a card's numbers on Docs/CardDesign.xlsx, not here.
A8: One tab per totem | B8: A totem has no health or deck - Totem Power is its auras and reactions, weighted the same way a body's Card Power is.
A9: Roster | B9: Every body side by side, sorted by name, so you can see how they stack up. Fully formula-driven off the individual tabs.
A10: Enums | B10: Dropdown sources for Brain, Targeting, Loot Table and Deck cells.
A11: Summoned | B11: Read-only. Bodies this roster summons but does not own - their power only, so Summon Power on a body tab has something to point at. Their real tabs are in Docs\EnemySheets.xlsx; edit them there.
A13: Reading a body tab
A14: Brandon's Power Level | B14: Hand-authored ground truth - type in what a body feels like it should be worth. Preserved across re-exports.
A15: Estimated Power Level | B15: (Average Card Power * Actions Per Turn * pw_ActionScale + Health * pw_Health) / pw_Divisor. Tune the PowerLevel weights until Delta sits near zero for the bodies you already trust, then trust the estimate for the rest.
A16: Role | B16: Which spawn row(s) this body is eligible for - None (unconstrained), Frontline, Backline or Both. Synced to Character.battleRole; drives BattleManager.SpawnParty and EncounterRoller placement.
A17: Counted | B17: No for a Move-only card or a Cooldown card - excluded from every average. Cooldown cards get scored separately later.
A18: Summon Power | B18: A live reference to the summoned body's (or totem's) own power cell, scaled down if its lifetime is shorter than pw_SummonHorizon.
A20: Syncing back to Unity
A21: One button | B21: In Unity: Tools > Sync Bosses With Sheet. Applies your edits to Health, Actions Per Turn, Brain, Targeting, Loot Table, Role and Deck to the matching prefab, then refreshes this workbook so anything changed in the Inspector shows up here too.
A22: Deck | B22: One card name per column, left to right, no gaps - the first blank cell ends the deck. Duplicates are fine and expected (four Enemy Slash cards is four cells). Pick names from the dropdown so a typo cannot silently drop a card.
A23: Brandon's Power Level and Notes | B23: Never sync anywhere - they are authored HERE and preserved across every re-export.
A24: Card Facts, Card Power, averages, Roster | B24: Never hand-edit - fully derived from the prefab and its cards, rebuilt on every export.
A25: Effective Power and Boss | B25: Not sheet columns you edit directly - Effective Power (Brandon's if set, else Estimated) and Boss (which folder the prefab lives in) are written to Character.powerLevel/isBoss one-way, every sync, regardless of whether anything else on the tab changed. A body with neither Brandon's nor a usable Estimated result is skipped with a warning and can never be drawn by EncounterRoller.
A26: If both sides changed | B26: That body is left alone on BOTH sides and named in the Unity console, the same conflict rule Docs/CardDesign.xlsx follows. Make them agree, or change only one, then sync again.
A27: Regenerating without syncing | B27: Tools > Bosses > Refresh Sheet From Unity discards any sheet edit that has not been synced yet - only for when the sheet is known to be wrong.
A28: The other roster workbook | B28: Enemies, the ally and bosses are two separate workbooks driven by the same engine - Docs/EnemySheets.xlsx and Docs/BossDesign.xlsx - each with its own baseline and its own sync button. A prefab belongs to exactly one of them, decided by which folder it sits in under Assets/Prefabs.

Sheet PowerLevel
A1: READ-ONLY - mirrored from Docs\EnemySheets.xlsx on every export. Edit the weights THERE; anything typed here is discarded on the next sync.
A2: Term | B2: Value | C2: What this counts
A3: pw_Damage | B3: 1 | C3: The numeraire. One point of damage to a hero = 1 power.
A4: pw_Poison | B4: 0.9 | C4: Per point of lifetime damage-over-time (the triangular total of the stacks applied, not the stack count itself).
A5: pw_Shield | B5: 0.5 | C5: Per point. ShieldStatus is wiped at OnTurnStart, so it only ever blocks one round.
A6: pw_Block | B6: 0.5 | C6: Per point actually prevented (BlockStatus.AmountPerHit is a const 5, so a charge is worth 5 of these).
A7: pw_Teleport | B7: 4 | C7: Reserved for a future teleport/swap effect - no enemy card uses this yet.
A8: pw_Move | B8: 1 | C8: Per tile of forced repositioning (Move / Swap). "Move 2" is one Move card whose range reaches 2 tiles.
A9: pw_Health | B9: 0.5 | C9: Per point of max health.
A10: pw_Divisor | B10: 17 | C10: Everything above is summed and divided by this to land in the same range as Brandon's hand-authored numbers.
A11: pw_Heal | B11: 0.8 | C11: Only useful once already damaged, so worth less than the same number as damage.
A12: pw_Strength | B12: 0.9 | C12: Per stack per future attack this enemy is assumed to still make (see pw_Horizon).
A13: pw_DoubleNextAttack | B13: 3 | C13: Per stack. Roughly one extra average hit.
A14: pw_PoisonBlade | B14: 1 | C14: Per stack - the weapon-poison variant, scored the same as Poison stacks.
... A34: pw_Tolerance | B34: 0.25 | C34: How far Estimated Power Level may sit from Brandon's before the Roster tab flags it OVER/UNDER.
A36: Read-only. These weights are whatever Docs\EnemySheets.xlsx holds - retune them there and re-sync, so both workbooks keep scoring on one scale.
A37: Range Power
A38: Range | B38: Power
A39: 1 | B39: 0
A40: 2 | B40: 1.5
A41: 3 | B41: 5
A42: 4 | B42: 6
A43: 5 | B43: 7
A44: 6 | B44: 8
A45: Looked up by nearest Range at or below a card's own Range Max - add a row for a new value; anything past the last row scores the same as it.

Sheet Roster
A1: Name | B1: Boss | C1: Role | D1: Health | E1: Actions | F1: Brain | G1: Targeting | H1: Deck Size | I1: Avg Damage | J1: Avg Status | K1: Avg Summon | L1: Avg Card Power | M1: Estimated | N1: Brandon's | O1: Effective Power | P1: Delta | Q1: Flag
A2: BlackKnight | B2: Yes | C2: ='BlackKnight'!B13 | D2: ='BlackKnight'!B8 | E2: ='BlackKnight'!B9 | F2: ='BlackKnight'!B10 | G2: ='BlackKnight'!B11 | H2: 5 | I2: ='BlackKnight'!B20 | J2: ='BlackKnight'!B21 | K2: ='BlackKnight'!B22 | L2: ='BlackKnight'!B19 | M2: ='BlackKnight'!B16 | N2: ='BlackKnight'!B15 | O2: =IF(N2="",M2,N2) | P2: ='BlackKnight'!B17 | Q2: =IF(P2="","",IF(ABS(P2)<=M2*pw_Tolerance,"OK",IF(P2>0,"OVER","UNDER")))
A3: EvilKing | B3: Yes | C3: ='EvilKing'!B13 | D3: ='EvilKing'!B8 | E3: ='EvilKing'!B9 | F3: ='EvilKing'!B10 | G3: ='EvilKing'!B11 | H3: 7 | I3: ='EvilKing'!B20 | J3: ='EvilKing'!B21 | K3: ='EvilKing'!B22 | L3: ='EvilKing'!B19 | M3: ='EvilKing'!B16 | N3: ='EvilKing'!B15 | O3: =IF(N3="",M3,N3) | P3: ='EvilKing'!B17 | Q3: =IF(P3="","",IF(ABS(P3)<=M3*pw_Tolerance,"OK",IF(P3>0,"OVER","UNDER")))
A4: EvilKnight | B4: Yes | C4: ='EvilKnight'!B13 | D4: ='EvilKnight'!B8 | E4: ='EvilKnight'!B9 | F4: ='EvilKnight'!B10 | G4: ='EvilKnight'!B11 | H4: 7 | I4: ='EvilKnight'!B20 | J4: ='EvilKnight'!B21 | K4: ='EvilKnight'!B22 | L4: ='EvilKnight'!B19 | M4: ='EvilKnight'!B16 | N4: ='EvilKnight'!B15 | O4: =IF(N4="",M4,N4) | P4: ='EvilKnight'!B17 | Q4: =IF(P4="","",IF(ABS(P4)<=M4*pw_Tolerance,"OK",IF(P4>0,"OVER","UNDER")))
A5: EvilWizard | B5: Yes | C5: ='EvilWizard'!B13 | D5: ='EvilWizard'!B8 | E5: ='EvilWizard'!B9 | F5: ='EvilWizard'!B10 | G5: ='EvilWizard'!B11 | H5: 7 | I5: ='EvilWizard'!B20 | J5: ='EvilWizard'!B21 | K5: ='EvilWizard'!B22 | L5: ='EvilWizard'!B19 | M5: ='EvilWizard'!B16 | N5: ='EvilWizard'!B15 | O5: =IF(N5="",M5,N5) | P5: ='EvilWizard'!B17 | Q5: =IF(P5="","",IF(ABS(P5)<=M5*pw_Tolerance,"OK",IF(P5>0,"OVER","UNDER")))
A6: EvilWizard2 | B6: Yes | C6: ='EvilWizard2'!B13 | D6: ='EvilWizard2'!B8 | E6: ='EvilWizard2'!B9 | F6: ='EvilWizard2'!B10 | G6: ='EvilWizard2'!B11 | H6: 7 | I6: ='EvilWizard2'!B20 | J6: ='EvilWizard2'!B21 | K6: ='EvilWizard2'!B22 | L6: ='EvilWizard2'!B19 | M6: ='EvilWizard2'!B16 | N6: ='EvilWizard2'!B15 | O6: =IF(N6="",M6,N6) | P6: ='EvilWizard2'!B17 | Q6: =IF(P6="","",IF(ABS(P6)<=M6*pw_Tolerance,"OK",IF(P6>0,"OVER","UNDER")))
A7: EvilWizard3 | B7: Yes | C7: ='EvilWizard3'!B13 | D7: ='EvilWizard3'!B8 | E7: ='EvilWizard3'!B9 | F7: ='EvilWizard3'!B10 | G7: ='EvilWizard3'!B11 | H7: 7 | I7: ='EvilWizard3'!B20 | J7: ='EvilWizard3'!B21 | K7: ='EvilWizard3'!B22 | L7: ='EvilWizard3'!B19 | M7: ='EvilWizard3'!B16 | N7: ='EvilWizard3'!B15 | O7: =IF(N7="",M7,N7) | P7: ='EvilWizard3'!B17 | Q7: =IF(P7="","",IF(ABS(P7)<=M7*pw_Tolerance,"OK",IF(P7>0,"OVER","UNDER")))
A8: Reaper | B8: Yes | C8: ='Reaper'!B13 | D8: ='Reaper'!B8 | E8: ='Reaper'!B9 | F8: ='Reaper'!B10 | G8: ='Reaper'!B11 | H8: 7 | I8: ='Reaper'!B20 | J8: ='Reaper'!B21 | K8: ='Reaper'!B22 | L8: ='Reaper'!B19 | M8: ='Reaper'!B16 | N8: ='Reaper'!B15 | O8: =IF(N8="",M8,N8) | P8: ='Reaper'!B17 | Q8: =IF(P8="","",IF(ABS(P8)<=M8*pw_Tolerance,"OK",IF(P8>0,"OVER","UNDER")))
A9: ReinforcedGolem | B9: Yes | C9: ='ReinforcedGolem'!B13 | D9: ='ReinforcedGolem'!B8 | E9: ='ReinforcedGolem'!B9 | F9: ='ReinforcedGolem'!B10 | G9: ='ReinforcedGolem'!B11 | H9: 7 | I9: ='ReinforcedGolem'!B20 | J9: ='ReinforcedGolem'!B21 | K9: ='ReinforcedGolem'!B22 | L9: ='ReinforcedGolem'!B19 | M9: ='ReinforcedGolem'!B16 | N9: ='ReinforcedGolem'!B15 | O9: =IF(N9="",M9,N9) | P9: ='ReinforcedGolem'!B17 | Q9: =IF(P9="","",IF(ABS(P9)<=M9*pw_Tolerance,"OK",IF(P9>0,"OVER","UNDER")))

Sheet BlackKnight
A1: Boss Name | B1: BlackKnight
A2: Boss | B2: Yes
A3: GUID | B3: fae9e0d8df06f744cb3eed28f98bb54f
A4: Sync | B4: =IF($B$3="","NEW","Live")
A6: Stats (synced to Unity)
A7: Display Name | B7: Black Knight
A8: Health | B8: 150
A9: Actions Per Turn | B9: 2
A10: Brain | B10: Summoner
A11: Targeting | B11: Strongest
A12: Loot Table | B12: BlackKnightDrop
A13: Role | B13: None
A15: Brandon's Power Level | B15: 2
A16: Estimated Power Level | B16: =IF($B$8="","",ROUND(($B$19*$B$9*pw_ActionScale+$B$8*pw_Health)/pw_Divisor,3))
A17: Delta (Estimated - Brandon's) | B17: =IF($B$15="","",ROUND($B$16-$B$15,3))
A19: Average Card Power | B19: =IFERROR(AVERAGEIF(B$26:F$26,"Yes",B$54:F$54),0)
A20: Average Damage | B20: =IFERROR(AVERAGEIF(B$26:F$26,"Yes",B$32:F$32),0)
A21: Average Status Power | B21: =IFERROR(AVERAGEIF(B$26:F$26,"Yes",B$55:F$55),0)
A22: Average Summon Power | B22: =IFERROR(AVERAGEIF(B$26:F$26,"Yes",B$52:F$52),0)
A24: Deck | B24: DreadCleave | C24: DreadCleave | D24: BlackGuard | E24: CallTheDamned | F24: MoveInnate
A25: Actions from Card | B25: 8 damage | C25: 8 damage | D25: 5 damage, Shield 10 | E25: Summon | F25: Move 1
A26: Counted | B26: Yes | C26: Yes | D26: Yes | E26: No | F26: No
A28: Card Facts
A29: Cost | B29: 1 | C29: 1 | D29: 1 | E29: 0 | F29: 1
A30: Range Max | B30: 1 | C30: 1 | D30: 1 | E30: 3 | F30: 1
A31: Tiles Hit | B31: 9 | C31: 9 | D31: 1 | E31: 1 | F31: 1
A32: Damage | B32: 8 | C32: 8 | D32: 5 | E32: 0 | F32: 0
A33: Range | B33: =IFERROR(VLOOKUP(B$30,range_Power,2,TRUE),0) | C33: =IFERROR(VLOOKUP(C$30,range_Power,2,TRUE),0) | D33: =IFERROR(VLOOKUP(D$30,range_Power,2,TRUE),0) | E33: =IFERROR(VLOOKUP(E$30,range_Power,2,TRUE),0) | F33: =IFERROR(VLOOKUP(F$30,range_Power,2,TRUE),0)
A34: Poison Total | B34: 0 | C34: 0 | D34: 0 | E34: 0 | F34: 0
A35: Heal | B35: 0 | C35: 0 | D35: 0 | E35: 0 | F35: 0
A36: Shield | B36: 0 | C36: 0 | D36: 10 | E36: 0 | F36: 0
A37: Block Total | B37: 0 | C37: 0 | D37: 0 | E37: 0 | F37: 0
A38: Parry | B38: 0 | C38: 0 | D38: 0 | E38: 0 | F38: 0
A39: Dodge | B39: 0 | C39: 0 | D39: 0 | E39: 0 | F39: 0
A40: Strength | B40: 0 | C40: 0 | D40: 0 | E40: 0 | F40: 0
A41: Weaken | B41: 0 | C41: 0 | D41: 0 | E41: 0 | F41: 0
A42: Vulnerable | B42: 0 | C42: 0 | D42: 0 | E42: 0 | F42: 0
A43: Frozen | B43: 0 | C43: 0 | D43: 0 | E43: 0 | F43: 0
A44: Rooted | B44: 0 | C44: 0 | D44: 0 | E44: 0 | F44: 0
A45: Taunt | B45: 0 | C45: 0 | D45: 0 | E45: 0 | F45: 0
...

Sheet EvilKing
A1: Boss Name | B1: EvilKing
A2: Boss | B2: Yes
A3: GUID | B3: e58fd978e913eea4699c373a33b5e08b
A4: Sync | B4: =IF($B$3="","NEW","Live")
A6: Stats (synced to Unity)
A7: Display Name | B7: Evil King
A8: Health | B8: 140
A9: Actions Per Turn | B9: 2
A10: Brain | B10: Summoner
A11: Targeting | B11: Strongest
A12: Loot Table | B12: EvilKingDrop
A13: Role | B13: None
A15: Brandon's Power Level | B15: 2
A16: Estimated Power Level | B16: =IF($B$8="","",ROUND(($B$19*$B$9*pw_ActionScale+$B$8*pw_Health)/pw_Divisor,3))
A17: Delta (Estimated - Brandon's) | B17: =IF($B$15="","",ROUND($B$16-$B$15,3))
A19: Average Card Power | B19: =IFERROR(AVERAGEIF(B$26:H$26,"Yes",B$54:H$54),0)
A20: Average Damage | B20: =IFERROR(AVERAGEIF(B$26:H$26,"Yes",B$32:H$32),0)
A21: Average Status Power | B21: =IFERROR(AVERAGEIF(B$26:H$26,"Yes",B$55:H$55),0)
A22: Average Summon Power | B22: =IFERROR(AVERAGEIF(B$26:H$26,"Yes",B$52:H$52),0)
A24: Deck | B24: ExecutionersBlow | C24: ExecutionersBlow | D24: RoyalGuard | E24: RoyalGuard | F24: RoyalCommand | G24: MoveInnate | H24: MoveInnate
A25: Actions from Card | B25: 9 damage | C25: 9 damage | D25: 5 damage, Shield 10 | E25: 5 damage, Shield 10 | F25: Summon | G25: Move 1 | H25: Move 1
A26: Counted | B26: Yes | C26: Yes | D26: Yes | E26: Yes | F26: No | G26: No | H26: No
A28: Card Facts
A29: Cost | B29: 1 | C29: 1 | D29: 1 | E29: 1 | F29: 0 | G29: 1 | H29: 1
A30: Range Max | B30: 1 | C30: 1 | D30: 1 | E30: 1 | F30: 3 | G30: 1 | H30: 1
A31: Tiles Hit | B31: 1 | C31: 1 | D31: 9 | E31: 9 | F31: 1 | G31: 1 | H31: 1
A32: Damage | B32: 9 | C32: 9 | D32: 5 | E32: 5 | F32: 0 | G32: 0 | H32: 0
A33: Range | B33: =IFERROR(VLOOKUP(B$30,range_Power,2,TRUE),0) | C33: =IFERROR(VLOOKUP(C$30,range_Power,2,TRUE),0) | D33: =IFERROR(VLOOKUP(D$30,range_Power,2,TRUE),0) | E33: =IFERROR(VLOOKUP(E$30,range_Power,2,TRUE),0) | F33: =IFERROR(VLOOKUP(F$30,range_Power,2,TRUE),0) | G33: =IFERROR(VLOOKUP(G$30,range_Power,2,TRUE),0) | H33: =IFERROR(VLOOKUP(H$30,range_Power,2,TRUE),0)
A34: Poison Total | B34: 0 | C34: 0 | D34: 0 | E34: 0 | F34: 0 | G34: 0 | H34: 0
A35: Heal | B35: 0 | C35: 0 | D35: 0 | E35: 0 | F35: 0 | G35: 0 | H35: 0
A36: Shield | B36: 0 | C36: 0 | D36: 10 | E36: 10 | F36: 0 | G36: 0 | H36: 0
A37: Block Total | B37: 0 | C37: 0 | D37: 0 | E37: 0 | F37: 0 | G37: 0 | H37: 0
A38: Parry | B38: 0 | C38: 0 | D38: 0 | E38: 0 | F38: 0 | G38: 0 | H38: 0
A39: Dodge | B39: 0 | C39: 0 | D39: 0 | E39: 0 | F39: 0 | G39: 0 | H39: 0
A40: Strength | B40: 0 | C40: 0 | D40: 0 | E40: 0 | F40: 0 | G40: 0 | H40: 0
A41: Weaken | B41: 0 | C41: 0 | D41: 0 | E41: 0 | F41: 0 | G41: 0 | H41: 0
A42: Vulnerable | B42: 0 | C42: 0 | D42: 0 | E42: 0 | F42: 0 | G42: 0 | H42: 0
A43: Frozen | B43: 0 | C43: 0 | D43: 0 | E43: 0 | F43: 0 | G43: 0 | H43: 0
A44: Rooted | B44: 0 | C44: 0 | D44: 0 | E44: 0 | F44: 0 | G44: 0 | H44: 0
A45: Taunt | B45: 0 | C45: 0 | D45: 0 | E45: 0 | F45: 0 | G45: 0 | H45: 0
...

Sheet EvilKnight
A1: Boss Name | B1: EvilKnight
A2: Boss | B2: Yes
A3: GUID | B3: e6c2dbc2feb811c4dbfea4d90220a6a5
A4: Sync | B4: =IF($B$3="","NEW","Live")
A6: Stats (synced to Unity)
A7: Display Name | B7: Evil Knight
A8: Health | B8: 130
A9: Actions Per Turn | B9: 2
A10: Brain | B10: Summoner
A11: Targeting | B11: Closest
A12: Loot Table | B12: EvilKnightDrop
A13: Role | B13: None
A15: Brandon's Power Level | B15: 2
A16: Estimated Power Level | B16: =IF($B$8="","",ROUND(($B$19*$B$9*pw_ActionScale+$B$8*pw_Health)/pw_Divisor,3))
A17: Delta (Estimated - Brandon's) | B17: =IF($B$15="","",ROUND($B$16-$B$15,3))
A19: Average Card Power | B19: =IFERROR(AVERAGEIF(B$26:H$26,"Yes",B$54:H$54),0)
A20: Average Damage | B20: =IFERROR(AVERAGEIF(B$26:H$26,"Yes",B$32:H$32),0)
A21: Average Status Power | B21: =IFERROR(AVERAGEIF(B$26:H$26,"Yes",B$55:H$55),0)
A22: Average Summon Power | B22: =IFERROR(AVERAGEIF(B$26:H$26,"Yes",B$52:H$52),0)
A24: Deck | B24: Riposte | C24: Riposte | D24: ShieldBash | E24: ShieldBash | F24: Rally | G24: MoveInnate | H24: MoveInnate
A25: Actions from Card | B25: 6 damage, Parry x1 | C25: 6 damage, Parry x1 | D25: 4 damage, Shield 10 | E25: 4 damage, Shield 10 | F25: Summon | G25: Move 1 | H25: Move 1
A26: Counted | B26: Yes | C26: Yes | D26: Yes | E26: Yes | F26: No | G26: No | H26: No
A28: Card Facts
A29: Cost | B29: 1 | C29: 1 | D29: 1 | E29: 1 | F29: 0 | G29: 1 | H29: 1
A30: Range Max | B30: 1 | C30: 1 | D30: 1 | E30: 1 | F30: 3 | G30: 1 | H30: 1
A31: Tiles Hit | B31: 1 | C31: 1 | D31: 1 | E31: 1 | F31: 1 | G31: 1 | H31: 1
A32: Damage | B32: 6 | C32: 6 | D32: 4 | E32: 4 | F32: 0 | G32: 0 | H32: 0
A33: Range | B33: =IFERROR(VLOOKUP(B$30,range_Power,2,TRUE),0) | C33: =IFERROR(VLOOKUP(C$30,range_Power,2,TRUE),0) | D33: =IFERROR(VLOOKUP(D$30,range_Power,2,TRUE),0) | E33: =IFERROR(VLOOKUP(E$30,range_Power,2,TRUE),0) | F33: =IFERROR(VLOOKUP(F$30,range_Power,2,TRUE),0) | G33: =IFERROR(VLOOKUP(G$30,range_Power,2,TRUE),0) | H33: =IFERROR(VLOOKUP(H$30,range_Power,2,TRUE),0)
A34: Poison Total | B34: 0 | C34: 0 | D34: 0 | E34: 0 | F34: 0 | G34: 0 | H34: 0
A35: Heal | B35: 0 | C35: 0 | D35: 0 | E35: 0 | F35: 0 | G35: 0 | H35: 0
A36: Shield | B36: 0 | C36: 0 | D36: 10 | E36: 10 | F36: 0 | G36: 0 | H36: 0
A37: Block Total | B37: 0 | C37: 0 | D37: 0 | E37: 0 | F37: 0 | G37: 0 | H37: 0
A38: Parry | B38: 1 | C38: 1 | D38: 0 | E38: 0 | F38: 0 | G38: 0 | H38: 0
A39: Dodge | B39: 0 | C39: 0 | D39: 0 | E39: 0 | F39: 0 | G39: 0 | H39: 0
A40: Strength | B40: 0 | C40: 0 | D40: 0 | E40: 0 | F40: 0 | G40: 0 | H40: 0
A41: Weaken | B41: 0 | C41: 0 | D41: 0 | E41: 0 | F41: 0 | G41: 0 | H41: 0
A42: Vulnerable | B42: 0 | C42: 0 | D42: 0 | E42: 0 | F42: 0 | G42: 0 | H42: 0
A43: Frozen | B43: 0 | C43: 0 | D43: 0 | E43: 0 | F43: 0 | G43: 0 | H43: 0
A44: Rooted | B44: 0 | C44: 0 | D44: 0 | E44: 0 | F44: 0 | G44: 0 | H44: 0
A45: Taunt | B45: 0 | C45: 0 | D45: 0 | E45: 0 | F45: 0 | G45: 0 | H45: 0
...

Sheet EvilWizard
A1: Boss Name | B1: EvilWizard
A2: Boss | B2: Yes
A3: GUID | B3: 51a9fe976e746be4385a09a12bb4cc36
A4: Sync | B4: =IF($B$3="","NEW","Live")
A6: Stats (synced to Unity)
A7: Display Name | B7: Evil Wizard
A8: Health | B8: 90
A9: Actions Per Turn | B9: 2
A10: Brain | B10: Summoner
A11: Targeting | B11: Weakest
A12: Loot Table | B12: EvilWizardDrop
A13: Role | B13: None
A15: Brandon's Power Level | B15: 2
A16: Estimated Power Level | B16: =IF($B$8="","",ROUND(($B$19*$B$9*pw_ActionScale+$B$8*pw_Health)/pw_Divisor,3))
A17: Delta (Estimated - Brandon's) | B17: =IF($B$15="","",ROUND($B$16-$B$15,3))
A19: Average Card Power | B19: =IFERROR(AVERAGEIF(B$26:H$26,"Yes",B$54:H$54),0)
A20: Average Damage | B20: =IFERROR(AVERAGEIF(B$26:H$26,"Yes",B$32:H$32),0)
A21: Average Status Power | B21: =IFERROR(AVERAGEIF(B$26:H$26,"Yes",B$55:H$55),0)
A22: Average Summon Power | B22: =IFERROR(AVERAGEIF(B$26:H$26,"Yes",B$52:H$52),0)
A24: Deck | B24: DarkBolt | C24: DarkBolt | D24: ShadowWard | E24: ShadowWard | F24: SummonImp | G24: MoveInnate | H24: MoveInnate
A25: Actions from Card | B25: 5 damage | C25: 5 damage | D25: 3 damage, Shield 7 | E25: 3 damage, Shield 7 | F25: Summon | G25: Move 1 | H25: Move 1
A26: Counted | B26: Yes | C26: Yes | D26: Yes | E26: Yes | F26: No | G26: No | H26: No
A28: Card Facts
A29: Cost | B29: 1 | C29: 1 | D29: 1 | E29: 1 | F29: 0 | G29: 1 | H29: 1
A30: Range Max | B30: 5 | C30: 5 | D30: 4 | E30: 4 | F30: 3 | G30: 1 | H30: 1
A31: Tiles Hit | B31: 1 | C31: 1 | D31: 1 | E31: 1 | F31: 1 | G31: 1 | H31: 1
A32: Damage | B32: 5 | C32: 5 | D32: 3 | E32: 3 | F32: 0 | G32: 0 | H32: 0
A33: Range | B33: =IFERROR(VLOOKUP(B$30,range_Power,2,TRUE),0) | C33: =IFERROR(VLOOKUP(C$30,range_Power,2,TRUE),0) | D33: =IFERROR(VLOOKUP(D$30,range_Power,2,TRUE),0) | E33: =IFERROR(VLOOKUP(E$30,range_Power,2,TRUE),0) | F33: =IFERROR(VLOOKUP(F$30,range_Power,2,TRUE),0) | G33: =IFERROR(VLOOKUP(G$30,range_Power,2,TRUE),0) | H33: =IFERROR(VLOOKUP(H$30,range_Power,2,TRUE),0)
A34: Poison Total | B34: 0 | C34: 0 | D34: 0 | E34: 0 | F34: 0 | G34: 0 | H34: 0
A35: Heal | B35: 0 | C35: 0 | D35: 0 | E35: 0 | F35: 0 | G35: 0 | H35: 0
A36: Shield | B36: 0 | C36: 0 | D36: 7 | E36: 7 | F36: 0 | G36: 0 | H36: 0
A37: Block Total | B37: 0 | C37: 0 | D37: 0 | E37: 0 | F37: 0 | G37: 0 | H37: 0
A38: Parry | B38: 0 | C38: 0 | D38: 0 | E38: 0 | F38: 0 | G38: 0 | H38: 0
A39: Dodge | B39: 0 | C39: 0 | D39: 0 | E39: 0 | F39: 0 | G39: 0 | H39: 0
A40: Strength | B40: 0 | C40: 0 | D40: 0 | E40: 0 | F40: 0 | G40: 0 | H40: 0
A41: Weaken | B41: 0 | C41: 0 | D41: 0 | E41: 0 | F41: 0 | G41: 0 | H41: 0
A42: Vulnerable | B42: 0 | C42: 0 | D42: 0 | E42: 0 | F42: 0 | G42: 0 | H42: 0
A43: Frozen | B43: 0 | C43: 0 | D43: 0 | E43: 0 | F43: 0 | G43: 0 | H43: 0
A44: Rooted | B44: 0 | C44: 0 | D44: 0 | E44: 0 | F44: 0 | G44: 0 | H44: 0
A45: Taunt | B45: 0 | C45: 0 | D45: 0 | E45: 0 | F45: 0 | G45: 0 | H45: 0
...

Sheet EvilWizard2
A1: Boss Name | B1: EvilWizard2
A2: Boss | B2: Yes
A3: GUID | B3: 8a02da994bf78784c901145a07a767e4
A4: Sync | B4: =IF($B$3="","NEW","Live")
A6: Stats (synced to Unity)
A7: Display Name | B7: Dread Sorcerer
A8: Health | B8: 95
A9: Actions Per Turn | B9: 2
A10: Brain | B10: Summoner
A11: Targeting | B11: Furthest
A12: Loot Table | B12: EvilWizard2Drop
A13: Role | B13: None
A15: Brandon's Power Level | B15: 2
A16: Estimated Power Level | B16: =IF($B$8="","",ROUND(($B$19*$B$9*pw_ActionScale+$B$8*pw_Health)/pw_Divisor,3))
A17: Delta (Estimated - Brandon's) | B17: =IF($B$15="","",ROUND($B$16-$B$15,3))
A19: Average Card Power | B19: =IFERROR(AVERAGEIF(B$26:H$26,"Yes",B$54:H$54),0)
A20: Average Damage | B20: =IFERROR(AVERAGEIF(B$26:H$26,"Yes",B$32:H$32),0)
A21: Average Status Power | B21: =IFERROR(AVERAGEIF(B$26:H$26,"Yes",B$55:H$55),0)
A22: Average Summon Power | B22: =IFERROR(AVERAGEIF(B$26:H$26,"Yes",B$52:H$52),0)
A24: Deck | B24: ArcaneLance | C24: ArcaneLance | D24: VoidBarrier | E24: VoidBarrier | F24: CallTheSwarm | G24: MoveInnate | H24: MoveInnate
A25: Actions from Card | B25: 6 damage | C25: 6 damage | D25: 3 damage, Block x4 | E25: 3 damage, Block x4 | F25: Summon | G25: Move 1 | H25: Move 1
A26: Counted | B26: Yes | C26: Yes | D26: Yes | E26: Yes | F26: No | G26: No | H26: No
A28: Card Facts
A29: Cost | B29: 1 | C29: 1 | D29: 1 | E29: 1 | F29: 0 | G29: 1 | H29: 1
A30: Range Max | B30: 5 | C30: 5 | D30: 4 | E30: 4 | F30: 3 | G30: 1 | H30: 1
A31: Tiles Hit | B31: 1 | C31: 1 | D31: 1 | E31: 1 | F31: 1 | G31: 1 | H31: 1
A32: Damage | B32: 6 | C32: 6 | D32: 3 | E32: 3 | F32: 0 | G32: 0 | H32: 0
A33: Range | B33: =IFERROR(VLOOKUP(B$30,range_Power,2,TRUE),0) | C33: =IFERROR(VLOOKUP(C$30,range_Power,2,TRUE),0) | D33: =IFERROR(VLOOKUP(D$30,range_Power,2,TRUE),0) | E33: =IFERROR(VLOOKUP(E$30,range_Power,2,TRUE),0) | F33: =IFERROR(VLOOKUP(F$30,range_Power,2,TRUE),0) | G33: =IFERROR(VLOOKUP(G$30,range_Power,2,TRUE),0) | H33: =IFERROR(VLOOKUP(H$30,range_Power,2,TRUE),0)
A34: Poison Total | B34: 0 | C34: 0 | D34: 0 | E34: 0 | F34: 0 | G34: 0 | H34: 0
A35: Heal | B35: 0 | C35: 0 | D35: 0 | E35: 0 | F35: 0 | G35: 0 | H35: 0
A36: Shield | B36: 0 | C36: 0 | D36: 0 | E36: 0 | F36: 0 | G36: 0 | H36: 0
A37: Block Total | B37: 0 | C37: 0 | D37: 20 | E37: 20 | F37: 0 | G37: 0 | H37: 0
A38: Parry | B38: 0 | C38: 0 | D38: 0 | E38: 0 | F38: 0 | G38: 0 | H38: 0
A39: Dodge | B39: 0 | C39: 0 | D39: 0 | E39: 0 | F39: 0 | G39: 0 | H39: 0
A40: Strength | B40: 0 | C40: 0 | D40: 0 | E40: 0 | F40: 0 | G40: 0 | H40: 0
A41: Weaken | B41: 0 | C41: 0 | D41: 0 | E41: 0 | F41: 0 | G41: 0 | H41: 0
A42: Vulnerable | B42: 0 | C42: 0 | D42: 0 | E42: 0 | F42: 0 | G42: 0 | H42: 0
A43: Frozen | B43: 0 | C43: 0 | D43: 0 | E43: 0 | F43: 0 | G43: 0 | H43: 0
A44: Rooted | B44: 0 | C44: 0 | D44: 0 | E44: 0 | F44: 0 | G44: 0 | H44: 0
A45: Taunt | B45: 0 | C45: 0 | D45: 0 | E45: 0 | F45: 0 | G45: 0 | H45: 0
...

Sheet EvilWizard3
A1: Boss Name | B1: EvilWizard3
A2: Boss | B2: Yes
A3: GUID | B3: e47742cc0b6bff34d80516b86f0ed93e
A4: Sync | B4: =IF($B$3="","NEW","Live")
A6: Stats (synced to Unity)
A7: Display Name | B7: Emberlord
A8: Health | B8: 100
A9: Actions Per Turn | B9: 2
A10: Brain | B10: Summoner
A11: Targeting | B11: Strongest
A12: Loot Table | B12: EvilWizard3Drop
A13: Role | B13: None
A15: Brandon's Power Level | B15: 2
A16: Estimated Power Level | B16: =IF($B$8="","",ROUND(($B$19*$B$9*pw_ActionScale+$B$8*pw_Health)/pw_Divisor,3))
A17: Delta (Estimated - Brandon's) | B17: =IF($B$15="","",ROUND($B$16-$B$15,3))
A19: Average Card Power | B19: =IFERROR(AVERAGEIF(B$26:H$26,"Yes",B$54:H$54),0)
A20: Average Damage | B20: =IFERROR(AVERAGEIF(B$26:H$26,"Yes",B$32:H$32),0)
A21: Average Status Power | B21: =IFERROR(AVERAGEIF(B$26:H$26,"Yes",B$55:H$55),0)
A22: Average Summon Power | B22: =IFERROR(AVERAGEIF(B$26:H$26,"Yes",B$52:H$52),0)
A24: Deck | B24: MeteorFall | C24: MeteorFall | D24: EmberShroud | E24: EmberShroud | F24: ConjureOoze | G24: MoveInnate | H24: MoveInnate
A25: Actions from Card | B25: 6 damage | C25: 6 damage | D25: 4 damage, Shield 7 | E25: 4 damage, Shield 7 | F25: Summon | G25: Move 1 | H25: Move 1
A26: Counted | B26: Yes | C26: Yes | D26: Yes | E26: Yes | F26: No | G26: No | H26: No
A28: Card Facts
A29: Cost | B29: 1 | C29: 1 | D29: 1 | E29: 1 | F29: 0 | G29: 1 | H29: 1
A30: Range Max | B30: 5 | C30: 5 | D30: 4 | E30: 4 | F30: 3 | G30: 1 | H30: 1
A31: Tiles Hit | B31: 9 | C31: 9 | D31: 1 | E31: 1 | F31: 1 | G31: 1 | H31: 1
A32: Damage | B32: 6 | C32: 6 | D32: 4 | E32: 4 | F32: 0 | G32: 0 | H32: 0
A33: Range | B33: =IFERROR(VLOOKUP(B$30,range_Power,2,TRUE),0) | C33: =IFERROR(VLOOKUP(C$30,range_Power,2,TRUE),0) | D33: =IFERROR(VLOOKUP(D$30,range_Power,2,TRUE),0) | E33: =IFERROR(VLOOKUP(E$30,range_Power,2,TRUE),0) | F33: =IFERROR(VLOOKUP(F$30,range_Power,2,TRUE),0) | G33: =IFERROR(VLOOKUP(G$30,range_Power,2,TRUE),0) | H33: =IFERROR(VLOOKUP(H$30,range_Power,2,TRUE),0)
A34: Poison Total | B34: 0 | C34: 0 | D34: 0 | E34: 0 | F34: 0 | G34: 0 | H34: 0
A35: Heal | B35: 0 | C35: 0 | D35: 0 | E35: 0 | F35: 0 | G35: 0 | H35: 0
A36: Shield | B36: 0 | C36: 0 | D36: 7 | E36: 7 | F36: 0 | G36: 0 | H36: 0
A37: Block Total | B37: 0 | C37: 0 | D37: 0 | E37: 0 | F37: 0 | G37: 0 | H37: 0
A38: Parry | B38: 0 | C38: 0 | D38: 0 | E38: 0 | F38: 0 | G38: 0 | H38: 0
A39: Dodge | B39: 0 | C39: 0 | D39: 0 | E39: 0 | F39: 0 | G39: 0 | H39: 0
A40: Strength | B40: 0 | C40: 0 | D40: 0 | E40: 0 | F40: 0 | G40: 0 | H40: 0
A41: Weaken | B41: 0 | C41: 0 | D41: 0 | E41: 0 | F41: 0 | G41: 0 | H41: 0
A42: Vulnerable | B42: 0 | C42: 0 | D42: 0 | E42: 0 | F42: 0 | G42: 0 | H42: 0
A43: Frozen | B43: 0 | C43: 0 | D43: 0 | E43: 0 | F43: 0 | G43: 0 | H43: 0
A44: Rooted | B44: 0 | C44: 0 | D44: 0 | E44: 0 | F44: 0 | G44: 0 | H44: 0
A45: Taunt | B45: 0 | C45: 0 | D45: 0 | E45: 0 | F45: 0 | G45: 0 | H45: 0
...

Sheet Reaper
A1: Boss Name | B1: Reaper
A2: Boss | B2: Yes
A3: GUID | B3: f5f2a9fce9bdff34a958576185c3c68b
A4: Sync | B4: =IF($B$3="","NEW","Live")
A6: Stats (synced to Unity)
A7: Display Name | B7: Reaper
A8: Health | B8: 110
A9: Actions Per Turn | B9: 2
A10: Brain | B10: Summoner
A11: Targeting | B11: Weakest
A12: Loot Table | B12: ReaperDrop
A13: Role | B13: None
A15: Brandon's Power Level | B15: 2
A16: Estimated Power Level | B16: =IF($B$8="","",ROUND(($B$19*$B$9*pw_ActionScale+$B$8*pw_Health)/pw_Divisor,3))
A17: Delta (Estimated - Brandon's) | B17: =IF($B$15="","",ROUND($B$16-$B$15,3))
A19: Average Card Power | B19: =IFERROR(AVERAGEIF(B$26:H$26,"Yes",B$54:H$54),0)
A20: Average Damage | B20: =IFERROR(AVERAGEIF(B$26:H$26,"Yes",B$32:H$32),0)
A21: Average Status Power | B21: =IFERROR(AVERAGEIF(B$26:H$26,"Yes",B$55:H$55),0)
A22: Average Summon Power | B22: =IFERROR(AVERAGEIF(B$26:H$26,"Yes",B$52:H$52),0)
A24: Deck | B24: SoulReap | C24: SoulReap | D24: DeathsToll | E24: DeathsToll | F24: RaiseDead | G24: MoveInnate | H24: MoveInnate
A25: Actions from Card | B25: 6 damage, Heal 5 | C25: 6 damage, Heal 5 | D25: 4 damage, Vulnerable 1 | E25: 4 damage, Vulnerable 1 | F25: Summon | G25: Move 1 | H25: Move 1
A26: Counted | B26: Yes | C26: Yes | D26: Yes | E26: Yes | F26: No | G26: No | H26: No
A28: Card Facts
A29: Cost | B29: 1 | C29: 1 | D29: 1 | E29: 1 | F29: 0 | G29: 1 | H29: 1
A30: Range Max | B30: 2 | C30: 2 | D30: 4 | E30: 4 | F30: 4 | G30: 1 | H30: 1
A31: Tiles Hit | B31: 1 | C31: 1 | D31: 9 | E31: 9 | F31: 1 | G31: 1 | H31: 1
A32: Damage | B32: 6 | C32: 6 | D32: 4 | E32: 4 | F32: 0 | G32: 0 | H32: 0
A33: Range | B33: =IFERROR(VLOOKUP(B$30,range_Power,2,TRUE),0) | C33: =IFERROR(VLOOKUP(C$30,range_Power,2,TRUE),0) | D33: =IFERROR(VLOOKUP(D$30,range_Power,2,TRUE),0) | E33: =IFERROR(VLOOKUP(E$30,range_Power,2,TRUE),0) | F33: =IFERROR(VLOOKUP(F$30,range_Power,2,TRUE),0) | G33: =IFERROR(VLOOKUP(G$30,range_Power,2,TRUE),0) | H33: =IFERROR(VLOOKUP(H$30,range_Power,2,TRUE),0)
A34: Poison Total | B34: 0 | C34: 0 | D34: 0 | E34: 0 | F34: 0 | G34: 0 | H34: 0
A35: Heal | B35: 5 | C35: 5 | D35: 0 | E35: 0 | F35: 0 | G35: 0 | H35: 0
A36: Shield | B36: 0 | C36: 0 | D36: 0 | E36: 0 | F36: 0 | G36: 0 | H36: 0
A37: Block Total | B37: 0 | C37: 0 | D37: 0 | E37: 0 | F37: 0 | G37: 0 | H37: 0
A38: Parry | B38: 0 | C38: 0 | D38: 0 | E38: 0 | F38: 0 | G38: 0 | H38: 0
A39: Dodge | B39: 0 | C39: 0 | D39: 0 | E39: 0 | F39: 0 | G39: 0 | H39: 0
A40: Strength | B40: 0 | C40: 0 | D40: 0 | E40: 0 | F40: 0 | G40: 0 | H40: 0
A41: Weaken | B41: 0 | C41: 0 | D41: 0 | E41: 0 | F41: 0 | G41: 0 | H41: 0
A42: Vulnerable | B42: 0 | C42: 0 | D42: 1 | E42: 1 | F42: 0 | G42: 0 | H42: 0
A43: Frozen | B43: 0 | C43: 0 | D43: 0 | E43: 0 | F43: 0 | G43: 0 | H43: 0
A44: Rooted | B44: 0 | C44: 0 | D44: 0 | E44: 0 | F44: 0 | G44: 0 | H44: 0
A45: Taunt | B45: 0 | C45: 0 | D45: 0 | E45: 0 | F45: 0 | G45: 0 | H45: 0
...

Sheet ReinforcedGolem
A1: Boss Name | B1: ReinforcedGolem
A2: Boss | B2: Yes
A3: GUID | B3: 8d47800381e9665459f3b0826adf6b76
A4: Sync | B4: =IF($B$3="","NEW","Live")
A6: Stats (synced to Unity)
A7: Display Name | B7: Reinforced Golem
A8: Health | B8: 150
A9: Actions Per Turn | B9: 2
A10: Brain | B10: Summoner
A11: Targeting | B11: Closest
A12: Loot Table | B12: ReinforcedGolemDrop
A13: Role | B13: None
A15: Brandon's Power Level | B15: 2
A16: Estimated Power Level | B16: =IF($B$8="","",ROUND(($B$19*$B$9*pw_ActionScale+$B$8*pw_Health)/pw_Divisor,3))
A17: Delta (Estimated - Brandon's) | B17: =IF($B$15="","",ROUND($B$16-$B$15,3))
A19: Average Card Power | B19: =IFERROR(AVERAGEIF(B$26:H$26,"Yes",B$54:H$54),0)
A20: Average Damage | B20: =IFERROR(AVERAGEIF(B$26:H$26,"Yes",B$32:H$32),0)
A21: Average Status Power | B21: =IFERROR(AVERAGEIF(B$26:H$26,"Yes",B$55:H$55),0)
A22: Average Summon Power | B22: =IFERROR(AVERAGEIF(B$26:H$26,"Yes",B$52:H$52),0)
A24: Deck | B24: SeismicSlam | C24: SeismicSlam | D24: StoneSkin | E24: StoneSkin | F24: SplinterOff | G24: MoveInnate | H24: MoveInnate
A25: Actions from Card | B25: 7 damage | C25: 7 damage | D25: 4 damage, Shield 10 | E25: 4 damage, Shield 10 | F25: Summon | G25: Move 1 | H25: Move 1
A26: Counted | B26: Yes | C26: Yes | D26: Yes | E26: Yes | F26: No | G26: No | H26: No
A28: Card Facts
A29: Cost | B29: 1 | C29: 1 | D29: 1 | E29: 1 | F29: 0 | G29: 1 | H29: 1
A30: Range Max | B30: 1 | C30: 1 | D30: 1 | E30: 1 | F30: 2 | G30: 1 | H30: 1
A31: Tiles Hit | B31: 9 | C31: 9 | D31: 1 | E31: 1 | F31: 1 | G31: 1 | H31: 1
A32: Damage | B32: 7 | C32: 7 | D32: 4 | E32: 4 | F32: 0 | G32: 0 | H32: 0
A33: Range | B33: =IFERROR(VLOOKUP(B$30,range_Power,2,TRUE),0) | C33: =IFERROR(VLOOKUP(C$30,range_Power,2,TRUE),0) | D33: =IFERROR(VLOOKUP(D$30,range_Power,2,TRUE),0) | E33: =IFERROR(VLOOKUP(E$30,range_Power,2,TRUE),0) | F33: =IFERROR(VLOOKUP(F$30,range_Power,2,TRUE),0) | G33: =IFERROR(VLOOKUP(G$30,range_Power,2,TRUE),0) | H33: =IFERROR(VLOOKUP(H$30,range_Power,2,TRUE),0)
A34: Poison Total | B34: 0 | C34: 0 | D34: 0 | E34: 0 | F34: 0 | G34: 0 | H34: 0
A35: Heal | B35: 0 | C35: 0 | D35: 0 | E35: 0 | F35: 0 | G35: 0 | H35: 0
A36: Shield | B36: 0 | C36: 0 | D36: 10 | E36: 10 | F36: 0 | G36: 0 | H36: 0
A37: Block Total | B37: 0 | C37: 0 | D37: 0 | E37: 0 | F37: 0 | G37: 0 | H37: 0
A38: Parry | B38: 0 | C38: 0 | D38: 0 | E38: 0 | F38: 0 | G38: 0 | H38: 0
A39: Dodge | B39: 0 | C39: 0 | D39: 0 | E39: 0 | F39: 0 | G39: 0 | H39: 0
A40: Strength | B40: 0 | C40: 0 | D40: 0 | E40: 0 | F40: 0 | G40: 0 | H40: 0
A41: Weaken | B41: 0 | C41: 0 | D41: 0 | E41: 0 | F41: 0 | G41: 0 | H41: 0
A42: Vulnerable | B42: 0 | C42: 0 | D42: 0 | E42: 0 | F42: 0 | G42: 0 | H42: 0
A43: Frozen | B43: 0 | C43: 0 | D43: 0 | E43: 0 | F43: 0 | G43: 0 | H43: 0
A44: Rooted | B44: 0 | C44: 0 | D44: 0 | E44: 0 | F44: 0 | G44: 0 | H44: 0
A45: Taunt | B45: 0 | C45: 0 | D45: 0 | E45: 0 | F45: 0 | G45: 0 | H45: 0
...

Sheet Summoned
A1: READ-ONLY - bodies summoned by this workbook's roster but owned by Docs\EnemySheets.xlsx. Refreshed on every export; edit them there.
A2: Prefab | B2: Power | C2: Summoned by
A3: Bat | B3: 2 | C3: EvilWizard2
A4: Goblin | B4: 2 | C4: EvilWizard
A5: HeavyBandit | B5: 2 | C5: EvilKnight
A6: LightBandit | B6: 2 | C6: EvilKing
A7: Pebble | B7: 2 | C7: ReinforcedGolem
A8: Skeleton | B8: 2 | C8: BlackKnight, Reaper
A9: Slime | B9: 2 | C9: EvilWizard3

Sheet Enums
A1: Brain | B1: Targeting | C1: Loot | D1: Role | E1: Bool | F1: EnemyCard | G1: Drives the dropdowns on every body tab. Regenerated on every export.
A2: None | D2: None | E2: Yes | F2: ArcaneLance
A3: Warrior | B3: Closest | C3: BlackKnightDrop | D3: Frontline | E3: No | F3: Backstab
A4: Ranger | B4: Furthest | C4: EarlyGame | D4: Backline | F4: Bite
A5: Summoner | B5: Random | C5: EarlyLevelReward | D5: Both | F5: BlackGuard
B6: RangerTargeting | C6: EvilKingDrop | F6: BoneBulwark
B7: Strongest | C7: EvilKnightDrop | F7: BoneChill
B8: TotemClosest | C8: EvilWizard2Drop | F8: BoulderSmash
B9: TotemFurthest | C9: EvilWizard3Drop | F9: CallReinforcements
B10: TotemWeakest | C10: EvilWizardDrop | F10: CallTheDamned
B11: WarriorTargeting | C11: PoisonSkeleton | F11: CallTheSwarm
B12: Weakest | C12: ReaperDrop | F12: Chomp
C13: ReinforcedGolemDrop | F13: ConjureOoze
C14: TutorialSapDrop | F14: DarkBolt
F15: DeathsToll
F16: DreadCleave
F17: EmberShroud
F18: EnemyArrow
F19: EnemySlash
F20: Engulf
F21: ExecutionersBlow
F22: Gnaw
F23: HeavySwing
F24: LifeLeech
F25: MeteorFall
F26: MoveInnate
... F49: WitheringGaze
