Workbook
Name w_Damage: 'Model'!$B$2
Name w_Heal: 'Model'!$B$3
Name w_Shield: 'Model'!$B$4
Name w_Block: 'Model'!$B$5
Name w_Parry: 'Model'!$B$6
Name w_Poison: 'Model'!$B$7
Name w_Strength: 'Model'!$B$8
Name w_Weaken: 'Model'!$B$9
Name w_Draw: 'Model'!$B$10
Name w_Move: 'Model'!$B$11
Name w_Combo: 'Model'!$B$12
Name w_OccEnemy: 'Model'!$B$13
Name w_OccAlly: 'Model'!$B$14
Name w_MaxEnemies: 'Model'!$B$15
Name w_MaxAllies: 'Model'!$B$16
Name w_Horizon: 'Model'!$B$17
Name curve_Base: 'Model'!$B$18
Name curve_Slope: 'Model'!$B$19
Name tol_Pct: 'Model'!$B$20
Name board_Tiles: 'Model'!$B$21
Name rarity_Mult: 'Model'!$A$25:$B$29
Name list_Class: 'Enums'!$A$2:$A$13
Name list_Rarity: 'Enums'!$B$2:$B$6
Name list_Shape: 'Enums'!$C$2:$C$5
Name list_Aim: 'Enums'!$D$2:$D$3
Name list_Bool: 'Enums'!$E$2:$E$3
Name list_Buildable: 'Enums'!$F$2:$F$6
Name list_Priority: 'Enums'!$G$2:$G$4
Name list_Tag: 'Enums'!$H$2:$H$8
Name list_Keyword: 'Enums'!$I$2:$I$4
Name list_Effect: 'Enums'!$J$2:$J$122
Name list_Folder: 'Enums'!$K$2:$K$35
Name list_Condition: 'Enums'!$L$2:$L$6
Name list_CostCond: 'Enums'!$M$2:$M$6

Sheet README
A1: Card Design Workbook
A3: One button does everything: in Unity, Tools > Sync With Sheet.
A4: It applies your sheet edits to the assets, then rebuilds this workbook so anything you authored in the Inspector appears here. Safe to press whatever you changed and wherever - it works out per column which side moved, and stops rather than guessing when both did.
A6: The tabs
A7: Knight / Mage / Rogue / Cleric / Neutral | B7: THE REAL CARDS. These mirror the .asset files. Everything here syncs to Unity - add a row, change a Description, and it lands in the game.
A8: * Ideas | B8: DESIGN SPACE ONLY. Never imported, whatever the Buildable column says. To build an idea, copy its row onto the matching class tab - the leading columns are identical, so it pastes straight across.
A9: Glossary | B9: Tooltip wording for every status and keyword. Edit Title/Body/Terms and sync to reword what the player reads. Also syncs.
A10: Effects | B10: The shared CardEffect assets under Assets/Data/EffectData. Used By shows how many cards reference each one.
A11: Decks | B11: DeckData contents, one row per (deck, card) with a count.
A12: Model | B12: The balance weights. EDIT THESE - every figure on Balance is a live formula reading this tab.
A13: Balance | B13: One row per card with the derived stats. Never hand-edit; it is rebuilt on every export.
A14: Charts | B14: The four balance charts and their source tables. Also rebuilt every export.
A15: Enums | B15: Sources for the dropdowns. Mirrors the C# enums - change the enum, not this sheet.
A17: Adding a card
A18: 1. | B18: Add a row on a CLASS tab (Knight/Mage/Rogue/Cleric/Neutral) and leave GUID blank. Sync will read NEW. Rows on an Ideas tab are never built.
A19: 2. | B19: Key is the asset filename. Folder decides which sub-folder it lands in.
A20: 3. | B20: Effect 1..3 take the NAME of an effect asset - see the Effects tab. "Damage 7" is fine even if it does not exist yet; the importer creates it.
A21: 4. | B21: Aim is Tile (the clicked tile) or Self (the caster). Area is Single, a radius like "Manhattan 0-2", or "Pattern:Cone3".
A22: 5. | B22: Save and CLOSE the workbook - the sync rewrites this file, so it cannot be open in Excel.
A23: 6. | B23: In Unity: Tools > Sync With Sheet (top of the menu).
A25: Authoring in Unity instead
A26: Just make the asset | B26: Create the CardData in the Inspector as normal. The next sync adds a row for it here - you never add it by hand.
A27: Renaming / refiling | B27: Change Key to rename the .asset, or Folder to move it. Both go through AssetDatabase.MoveAsset, so the GUID survives and decks keep pointing at the card.
A28: Deleting | B28: Deleting a row here does NOT delete the card - it is reported and the asset kept. Delete it in Unity if you mean it.
A30: What the columns mean
A31: Key | B31: Asset filename without extension. The join key - stable even when Card Name changes.
A32: Card Name | B32: The display name shown in game. Often differs from Key.
A33: Class | B33: Which character may hold it. A mask, so Knight+Rogue is legal. Any means everyone.
A34: Cost | B34: Energy. The X axis of the power curve.
A35: Rarity | B35: How good it is as a reward. NotOffered keeps it out of every reward pool.
A36: Range Shape/Min/Max | B36: Which tiles may be clicked, measured from the caster. Chebyshev is a square, Manhattan a diamond.
A37: Area N | B37: The footprint each effect covers around its aim tile. Single is one tile.
A38: Rotatable | B38: TRUE lets the player turn the card's area a quarter turn while aiming (E). Only meaningful with a Pattern area - a Radius area already reads the same after any turn.
A39: Cond N | B39: A board condition on effect N, checked on the caster as the card resolves. "Alone +6" adds 6 to the effect while it holds (Damage 7 with "NextToHero +3" deals 10 next to a hero). "Alone only" makes the effect fire only while it holds. Blank = always. Conditions: NextToTotem, HasShield, HasBlock, NextToHero, Alone (no other hero within 2 tiles).
A40: Cost Cond | B40: A board condition that lowers the whole card's cost while it holds. "NextToHero -1" = costs 1 less next to another hero. Never below 0. Blank = the printed cost always applies.
A41: GUID | B41: Unity asset id. Blank means the card does not exist yet - this is what the importer diffs on.
A42: Buildable | B42: Ideas tabs only, and purely informational now: Yes means the current engine could build it, anything else names what is missing. It does NOT gate anything - Ideas rows are never imported at all.
A43: Quantifiable | B43: Balance tab. Yes = fully scored. Partial = has a numeric core plus an unscored rider (Ice Shard damages AND freezes) - plotted, but Flag reads RIDER because the number is a floor. No = nothing numeric at all, kept off the curve entirely.
A45: Rewording cards and tooltips
A46: Card text | B46: Edit Description on a class tab and sync. The change is written straight to the .asset.
...

Sheet Knight
A1: Card Name | B1: Cost | C1: Rarity | D1: Effect 1 | E1: Effect 2 | F1: Effect 3 | G1: Description | H1: Range Shape | I1: Range Min | J1: Range Max | K1: Key | L1: Class | M1: Folder | N1: Tags | O1: Aim 1 | P1: Area 1 | Q1: Cond 1 | R1: Aim 2 | S1: Area 2 | T1: Cond 2 | U1: Aim 3 | V1: Area 3 | W1: Cond 3 | X1: Cost Cond | Y1: Keywords | Z1: No Reward | AA1: Rotatable | AB1: Animation | AC1: GUID | AD1: Sync | AE1: Notes
A2: Block | B2: 1 | C2: Uncommon | D2: Block 1 | G2: Gain Block. | H2: SelfTile | I2: 0 | J2: 0 | K2: Block | L2: Knight+Rogue | M2: Buff (Defensive) | N2: Defence | O2: Self | P2: Single | Z2: TRUE | AA2: FALSE | AC2: db83bbf36eb240f79a3c309c29ac4ea2 | AD2: =IF($AC2="","NEW","Live")
A3: Brothers in Arms | B3: 1 | C3: Uncommon | D3: Shield 8 | E3: Draw 1 | G3: Gain 8 Shield. Draw 1. Costs 0 next to another hero. | H3: SelfTile | I3: 0 | J3: 0 | K3: Brothers in Arms | L3: Knight | M3: Buff (Defensive) | N3: Defence | O3: Self | P3: Single | R3: Self | S3: Single | X3: NextToHero -1 | Z3: FALSE | AA3: FALSE | AC3: acb8cab12f6147a47bc05d1cc6b132c8 | AD3: =IF($AC3="","NEW","Live")
A4: Bulwark Stance | B4: 1 | C4: Uncommon | D4: Shield 6 | E4: Draw 1 | G4: Gain 6 Shield. Draw 1. Costs 0 while you have Block. | H4: SelfTile | I4: 0 | J4: 0 | K4: Bulwark Stance | L4: Knight | M4: Buff (Defensive) | N4: Defence | O4: Self | P4: Single | R4: Self | S4: Single | X4: HasBlock -1 | Z4: FALSE | AA4: FALSE | AC4: a3c385930ede9634f8443f5f76e4554c | AD4: =IF($AC4="","NEW","Live")
A5: Guard Up | B5: 1 | C5: Uncommon | D5: Shield 6 | G5: Gain 6 Shield. Costs 0 next to a totem. | H5: SelfTile | I5: 0 | J5: 0 | K5: Guard Up | L5: Knight | M5: Buff (Defensive) | N5: Defence | O5: Self | P5: Single | X5: NextToTotem -1 | Z5: FALSE | AA5: FALSE | AC5: 2ae701b8981918a4db193762447f3d09 | AD5: =IF($AC5="","NEW","Live")
A6: Last Bastion | B6: 1 | C6: Rare | D6: Taunt | E6: Shield 6 | F6: Draw 1 | G6: Taunt every enemy within 2. Gain 6 Shield. Alone: gain 12 and draw 1. | H6: SelfTile | I6: 0 | J6: 0 | K6: Last Bastion | L6: Knight | M6: Buff (Defensive) | O6: Self | P6: Chebyshev 1-2 | R6: Self | S6: Single | T6: Alone +6 | U6: Self | V6: Single | W6: Alone only | Z6: FALSE | AA6: FALSE | AC6: d28613fe38df1f7498e6b9630413bdd5 | AD6: =IF($AC6="","NEW","Live")
A7: Lone Stand | B7: 1 | C7: Uncommon | D7: Shield 6 | G7: Gain 6 Shield. Alone: gain 12 instead. | H7: SelfTile | I7: 0 | J7: 0 | K7: Lone Stand | L7: Knight | M7: Buff (Defensive) | N7: Defence | O7: Self | P7: Single | Q7: Alone +6 | Z7: FALSE | AA7: FALSE | AC7: b1cd626d8d06e8a478d67a6d8b23377e | AD7: =IF($AC7="","NEW","Live")
A8: Parry | B8: 1 | C8: Uncommon | D8: Parry 1 | G8: Gain 1 Parry. | H8: SelfTile | I8: 0 | J8: 0 | K8: Parry | L8: Knight | M8: Buff (Defensive) | N8: Defence | O8: Self | P8: Single | Z8: FALSE | AA8: FALSE | AC8: e5962a056448478d8cb8225f4e84306d | AD8: =IF($AC8="","NEW","Live")
A9: Phalanx | B9: 1 | C9: Uncommon | D9: Block 1 | G9: You and allies next to you gain Block. | H9: SelfTile | I9: 0 | J9: 0 | K9: Phalanx | L9: Knight | M9: Buff (Defensive) | N9: Defence | O9: Self | P9: Chebyshev 0-1 | Z9: FALSE | AA9: FALSE | AC9: 3d86e8d90243cd14b8d6ee7739aed90c | AD9: =IF($AC9="","NEW","Live")
A10: Shield | B10: 1 | C10: Common | D10: Shield 7 | G10: Gain 7 Shield. | H10: SelfTile | I10: 0 | J10: 0 | K10: Shield | L10: Knight | M10: Buff (Defensive) | N10: Defence | O10: Self | P10: Single | Z10: TRUE | AA10: FALSE | AC10: 7402495d3e66bfc41b47c4d1fc79004e | AD10: =IF($AC10="","NEW","Live")
A11: Shield Wall | B11: 1 | C11: Rare | D11: Shield 6 | G11: Give 6 Shield to you and allies within 2. | H11: SelfTile | I11: 0 | J11: 0 | K11: Shield Wall | L11: Knight | M11: Buff (Defensive) | N11: Defence | O11: Self | P11: Manhattan 0-2 | Z11: FALSE | AA11: FALSE | AC11: e79ad27300b7c2c45ba217374d91c43d | AD11: =IF($AC11="","NEW","Live")
A12: Shoulder to Shoulder | B12: 1 | C12: Uncommon | D12: Shield 8 | G12: You and allies next to you gain 8 Shield. | H12: SelfTile | I12: 0 | J12: 0 | K12: Shoulder to Shoulder | L12: Knight | M12: Buff (Defensive) | N12: Defence | O12: Self | P12: Chebyshev 0-1 | Z12: FALSE | AA12: FALSE | AC12: 3fde8e39e8151ec4fa50fca0a53d9515 | AD12: =IF($AC12="","NEW","Live")
A13: Solitary Guard | B13: 1 | C13: Uncommon | D13: Block 1 | G13: Gain Block. Alone: gain 2 instead. | H13: SelfTile | I13: 0 | J13: 0 | K13: Solitary Guard | L13: Knight | M13: Buff (Defensive) | N13: Defence | O13: Self | P13: Single | Q13: Alone +1 | Z13: FALSE | AA13: FALSE | AC13: c299cb1c41bf4144bae0fbfb413ac2bf | AD13: =IF($AC13="","NEW","Live")
A14: Steely Resolve | B14: 1 | C14: Uncommon | D14: Shield 5 | E14: Draw 1 | G14: Gain 5 Shield. Draw 1 card. | H14: SelfTile | I14: 0 | J14: 0 | K14: Steely Resolve | L14: Knight | M14: Buff (Defensive) | N14: Defence | O14: Self | P14: Single | R14: Self | S14: Single | Z14: FALSE | AA14: FALSE | AC14: b2d16f22e3045c1baf6d28e51c2f6003 | AD14: =IF($AC14="","NEW","Live")
A15: Taunt | B15: 1 | C15: Uncommon | D15: Taunt | G15: Taunts enemy. | H15: Chebyshev | I15: 1 | J15: 3 | K15: Taunt | L15: Knight | M15: Buff (Defensive) | O15: Tile | P15: Single | Z15: FALSE | AA15: FALSE | AC15: af8bc827dc0c0c043aadfbceb9c91246 | AD15: =IF($AC15="","NEW","Live")
A16: Totem Guard | B16: 1 | C16: Uncommon | D16: Block 1 | E16: Draw 1 | G16: Gain Block. Draw 1. Costs 0 next to a totem. | H16: SelfTile | I16: 0 | J16: 0 | K16: Totem Guard | L16: Knight | M16: Buff (Defensive) | N16: Defence | O16: Self | P16: Single | R16: Self | S16: Single | X16: NextToTotem -1 | Z16: FALSE | AA16: FALSE | AC16: 1a09bbabdf2419140beb812ddc514fc9 | AD16: =IF($AC16="","NEW","Live")
A17: Tower Shield | B17: 1 | C17: Uncommon | D17: Shield 11 | G17: Gain 11 Shield. | H17: SelfTile | I17: 0 | J17: 0 | K17: Tower Shield | L17: Knight | M17: Buff (Defensive) | N17: Defence | O17: Self | P17: Single | Z17: FALSE | AA17: FALSE | AC17: 5b8c141b69b661a47b40f47336b737eb | AD17: =IF($AC17="","NEW","Live")
A18: Guardian's Aegis | B18: 2 | C18: Uncommon | D18: Shield 5 | G18: Give 5 Shield. | H18: SelfTile | I18: 0 | J18: 0 | K18: Guardian's Aegis | L18: Knight | M18: Buff (Defensive) | N18: Defence | O18: Self | P18: Manhattan 0-2 | Z18: TRUE | AA18: FALSE | AC18: 52e101b3e4c5baa4cb2771825ac229a6 | AD18: =IF($AC18="","NEW","Live")
A19: Hold the Line | B19: 2 | C19: Rare | D19: Shield 12 | E19: Draw 1 | G19: You and allies next to you gain 12 Shield. Draw 1. | H19: SelfTile | I19: 0 | J19: 0 | K19: Hold the Line | L19: Knight | M19: Buff (Defensive) | N19: Defence | O19: Self | P19: Chebyshev 0-1 | R19: Self | S19: Single | Z19: FALSE | AA19: FALSE | AC19: d787c8c8eae8ff54a9854dfdca322ce2 | AD19: =IF($AC19="","NEW","Live")
A20: Rally the Line | B20: 2 | C20: Rare | D20: Shield 6 | E20: Draw 1 | G20: Give 6 Shield to you and allies within 2. Draw 1. Costs 1 next to another hero. | H20: SelfTile | I20: 0 | J20: 0 | K20: Rally the Line | L20: Knight | M20: Buff (Defensive) | N20: Defence | O20: Self | P20: Manhattan 0-2 | R20: Self | S20: Single | X20: NextToHero -1 | Z20: FALSE | AA20: FALSE | AC20: 35d0762777460dd43b359e47bbb06133 | AD20: =IF($AC20="","NEW","Live")
A21: Strengthen | B21: 1 | C21: Uncommon | D21: Strength 3 | G21: Gain 3 Strength. | H21: SelfTile | I21: 0 | J21: 0 | K21: Strengthen | L21: Knight | M21: Buff (Offensive) | O21: Tile | P21: Single | Z21: FALSE | AA21: FALSE | AC21: b2d16f22e3045c1baf6d28e51c2f6005 | AD21: =IF($AC21="","NEW","Live")
A22: Buff | B22: 2 | C22: Uncommon | D22: Double Next Attack | G22: Double next attack. | H22: SelfTile | I22: 0 | J22: 0 | K22: Buff | L22: Knight | M22: Buff (Offensive) | O22: Tile | P22: Single | Z22: FALSE | AA22: FALSE | AC22: b2d16f22e3045c1baf6d28e51c2f6006 | AD22: =IF($AC22="","NEW","Live")
A23: Second Wind | B23: 1 | C23: Uncommon | D23: Heal 5 | G23: Heal 5 health. | H23: SelfTile | I23: 0 | J23: 0 | K23: Second Wind | L23: Knight | M23: Heal | O23: Self | P23: Single | Z23: TRUE | AA23: FALSE | AC23: 0a8d0a05e27667d45bd045dcca66021a | AD23: =IF($AC23="","NEW","Live")
A24: Attack and Block | B24: 1 | C24: Uncommon | D24: Damage 5 | E24: Shield 5 | G24: Deal 5 Damage. Gain 5 Shield. | H24: Chebyshev | I24: 1 | J24: 1 | K24: Attack and Block | L24: Knight | M24: Melee Attack | N24: Attack | O24: Tile | P24: Single | R24: Self | S24: Single | Z24: TRUE | AA24: FALSE | AC24: b2d16f22e3045c1baf6d28e51c2f6001 | AD24: =IF($AC24="","NEW","Live")
A25: Cleave | B25: 1 | C25: Uncommon | D25: Damage 5 | G25: Deal 5 Damage. | H25: Manhattan | I25: 1 | J25: 1 | K25: Cleave | L25: Knight | M25: Melee Attack | N25: Attack | O25: Tile | P25: Pattern:Wall3 | Z25: TRUE | AA25: FALSE | AC25: d7c02ed0dade07a49bec6cc971ee05ab | AD25: =IF($AC25="","NEW","Live")
A26: Covering Strike | B26: 1 | C26: Uncommon | D26: Damage 9 | E26: Shield 5 | G26: Deal 9 damage. Allies next to you gain 5 Shield. | H26: Chebyshev | I26: 1 | J26: 1 | K26: Covering Strike | L26: Knight | M26: Melee Attack | N26: Attack | O26: Tile | P26: Single | R26: Self | S26: Chebyshev 1-1 | Z26: FALSE | AA26: FALSE | AC26: 2fa98ecbf47e2584fbadf37aa1be5f83 | AD26: =IF($AC26="","NEW","Live")
A27: Flanking Strike | B27: 1 | C27: Uncommon | D27: Damage 7 | E27: Shield 4 | G27: Deal 7 damage and gain 4 Shield. Next to another hero: deal 11 instead. | H27: Chebyshev | I27: 1 | J27: 1 | K27: Flanking Strike | L27: Knight | M27: Melee Attack | N27: Attack | O27: Tile | P27: Single | Q27: NextToHero +4 | R27: Self | S27: Single | Z27: FALSE | AA27: FALSE | AC27: 6957f431a6921034f8b923e03a242560 | AD27: =IF($AC27="","NEW","Live")
A28: Shield Bash | B28: 1 | C28: Uncommon | D28: Damage 7 | E28: Shield 7 | G28: Deal 7 damage. Gain 7 Shield. | H28: Chebyshev | I28: 1 | J28: 1 | K28: Shield Bash | L28: Knight | M28: Melee Attack | N28: Attack | O28: Tile | P28: Single | R28: Self | S28: Single | Z28: FALSE | AA28: FALSE | AC28: ba1805b5798b8f94fa371b07bdfacf03 | AD28: =IF($AC28="","NEW","Live")
A29: Shield Slam | B29: 1 | C29: Uncommon | D29: Damage 6 | E29: Shield 3 | G29: Deal 6 damage. Gain 3 Shield. Costs 0 while you have Shield. | H29: Chebyshev | I29: 1 | J29: 1 | K29: Shield Slam | L29: Knight | M29: Melee Attack | N29: Attack | O29: Tile | P29: Single | R29: Self | S29: Single | X29: HasShield -1 | Z29: FALSE | AA29: FALSE | AC29: 27e580fcf17bea44b8b94cbb699b7ffe | AD29: =IF($AC29="","NEW","Live")
A30: Shield Strike | B30: 1 | C30: Uncommon | D30: Damage 8 | E30: Draw 1 | G30: Deal 8 damage. Draw 1. Costs 0 while you have Shield. | H30: Chebyshev | I30: 1 | J30: 1 | K30: Shield Strike | L30: Knight | M30: Melee Attack | N30: Attack | O30: Tile | P30: Single | R30: Self | S30: Single | X30: HasShield -1 | Z30: FALSE | AA30: FALSE | AC30: 8dc2760ad1ac66b4994206ef019984f1 | AD30: =IF($AC30="","NEW","Live")
A31: Slash | B31: 1 | C31: Common | D31: Damage 9 | G31: Deals 9 Damage. | H31: Chebyshev | I31: 1 | J31: 1 | K31: Slash | L31: Knight | M31: Melee Attack | N31: Attack | O31: Tile | P31: Single | Z31: TRUE | AA31: FALSE | AC31: d33a9e1db0e9c6e42a163a3bb49dbf0f | AD31: =IF($AC31="","NEW","Live")
A32: Slash+ | B32: 1 | C32: NotOffered | D32: Damage 9 | G32: Deals 3 more damage than Slash. | H32: Chebyshev | I32: 1 | J32: 1 | K32: Slash+ | L32: Knight | M32: Melee Attack | N32: Attack | O32: Tile | P32: Single | Z32: FALSE | AA32: FALSE | AC32: 35c23446db2a2fb42ab67f89753afdbd | AD32: =IF($AC32="","NEW","Live")
A33: Sunder | B33: 1 | C33: Uncommon | D33: Damage 5 | E33: Vulnerable | G33: Deal 5 damage and apply 2 Vulnerable. | H33: Chebyshev | I33: 1 | J33: 1 | K33: Sunder | L33: Knight | M33: Melee Attack | N33: Attack | O33: Tile | P33: Single | R33: Tile | S33: Single | Z33: FALSE | AA33: FALSE | AC33: 473565cf7c9a7a54aa013e0ffab0df43 | AD33: =IF($AC33="","NEW","Live")
A34: Sweeping Blow | B34: 1 | C34: Uncommon | D34: Damage 7 | G34: Deal 7 damage to a line of 3. | H34: Manhattan | I34: 1 | J34: 1 | K34: Sweeping Blow | L34: Knight | M34: Melee Attack | N34: Attack | O34: Tile | P34: Pattern:Wall3 | Z34: FALSE | AA34: FALSE | AC34: 4e721d4776e282b4c811351f74b2281c | AD34: =IF($AC34="","NEW","Live")
A35: Totem Strike | B35: 1 | C35: Uncommon | D35: Damage 12 | E35: Draw 1 | G35: Deal 12 damage. Draw 1. Costs 0 next to a totem. | H35: Chebyshev | I35: 1 | J35: 1 | K35: Totem Strike | L35: Knight | M35: Melee Attack | N35: Attack | O35: Tile | P35: Single | R35: Self | S35: Single | X35: NextToTotem -1 | Z35: FALSE | AA35: FALSE | AC35: 4c61f52b0abbe614ebdc2b6caaa6acb2 | AD35: =IF($AC35="","NEW","Live")
A36: Vanguard's Oath | B36: 1 | C36: Rare | D36: Damage 11 | E36: Draw 1 | G36: Deal 11 damage. Draw 1. Costs 0 next to another hero. | H36: Chebyshev | I36: 1 | J36: 1 | K36: Vanguard's Oath | L36: Knight | M36: Melee Attack | N36: Attack | O36: Tile | P36: Single | R36: Self | S36: Single | X36: NextToHero -1 | Z36: FALSE | AA36: FALSE | AC36: 0bb722efb6adb564ab0b0add2338b868 | AD36: =IF($AC36="","NEW","Live")
A37: Whirlwind | B37: 1 | C37: Rare | D37: Damage 4 | G37: Deal 4 damage. | H37: SelfTile | I37: 0 | J37: 0 | K37: Whirlwind | L37: Knight | M37: Melee Attack | N37: Attack | O37: Self | P37: Chebyshev 0-1 | Z37: FALSE | AA37: FALSE | AC37: 912403e15b047df44945f4d6e0a794b2 | AD37: =IF($AC37="","NEW","Live")
A38: Bloodmoon Totem | B38: 0 | C38: Rare | D38: SummonBloodmoonTotem | G38: Summon Bloodmoon Totem Everyone within 2: +3 damage | H38: Chebyshev | I38: 1 | J38: 3 | K38: Bloodmoon Totem | L38: Knight | M38: Summon | O38: Tile | P38: Single | Z38: FALSE | AA38: FALSE | AC38: 54a4b791120a2294695e570203d59aba | AD38: =IF($AC38="","NEW","Live")
A39: Thornwood Totem | B39: 1 | C39: Uncommon | D39: SummonThornwoodTotem | G39: Summon Thornwood Totem Enemies within 2: take 3 on attack | H39: Chebyshev | I39: 1 | J39: 3 | K39: Thornwood Totem | L39: Knight | M39: Summon | O39: Tile | P39: Single | Z39: FALSE | AA39: FALSE | AC39: 2c52f35d6eee792448391963fba6d347 | AD39: =IF($AC39="","NEW","Live")
A40: Whetstone Totem | B40: 1 | C40: Uncommon | D40: SummonWhetstoneTotem | G40: Summon Whetstone Totem Allies within 2: +3 damage | H40: Chebyshev | I40: 1 | J40: 3 | K40: Whetstone Totem | L40: Knight | M40: Summon | O40: Tile | P40: Single | Z40: FALSE | AA40: FALSE | AC40: 9214dd863c19d7245b675c8862560f40 | AD40: =IF($AC40="","NEW","Live")
...

Sheet Mage
A1: Card Name | B1: Cost | C1: Rarity | D1: Effect 1 | E1: Effect 2 | F1: Effect 3 | G1: Description | H1: Range Shape | I1: Range Min | J1: Range Max | K1: Key | L1: Class | M1: Folder | N1: Tags | O1: Aim 1 | P1: Area 1 | Q1: Cond 1 | R1: Aim 2 | S1: Area 2 | T1: Cond 2 | U1: Aim 3 | V1: Area 3 | W1: Cond 3 | X1: Cost Cond | Y1: Keywords | Z1: No Reward | AA1: Rotatable | AB1: Animation | AC1: GUID | AD1: Sync | AE1: Notes
A2: Dull Blade | B2: 1 | C2: Common | D2: Weaken | G2: Apply Weaken. | H2: Chebyshev | I2: 1 | J2: 4 | K2: Dull Blade | L2: Mage | M2: Debuff | N2: Defence | O2: Tile | P2: Single | Z2: FALSE | AA2: FALSE | AB2: Status | AC2: 5838b385efe02534993ebe2518d61ef3 | AD2: =IF($AC2="","NEW","Live")
A3: Entangle | B3: 1 | C3: Uncommon | D3: Root | G3: Root an Enemy. | H3: Chebyshev | I3: 1 | J3: 4 | K3: Entangle | L3: Mage | M3: Debuff | O3: Tile | P3: Single | Z3: FALSE | AA3: FALSE | AB3: Status | AC3: d628843c186f4896abd388b0e0fb081d | AD3: =IF($AC3="","NEW","Live")
A4: Freeze | B4: 1 | C4: Rare | D4: Freeze | G4: Freeze an Enemy. | H4: Chebyshev | I4: 1 | J4: 4 | K4: Freeze | L4: Mage | M4: Debuff | O4: Tile | P4: Single | Z4: FALSE | AA4: FALSE | AB4: Freeze | AC4: b660e3293e8b4225afcfe9a9a4be0f05 | AD4: =IF($AC4="","NEW","Live")
A5: Rust Armor | B5: 1 | C5: Common | D5: Vulnerable | G5: Apply Vulnerable. | H5: Chebyshev | I5: 1 | J5: 4 | K5: Rust Armor | L5: Mage | M5: Debuff | O5: Tile | P5: Single | Z5: FALSE | AA5: FALSE | AC5: d87d584eefa48da429cd46687b4066b4 | AD5: =IF($AC5="","NEW","Live")
A6: Sap Life | B6: 1 | C6: Common | D6: Damage 3 | E6: Heal 3 | G6: Deal 3 damage. Heal 3. | H6: Chebyshev | I6: 1 | J6: 4 | K6: Sap Life | L6: Mage | M6: Heal | N6: Attack, Healing | O6: Tile | P6: Single | R6: Self | S6: Single | Z6: TRUE | AA6: FALSE | AC6: 2f8157e447d75014091a50790b9cf520 | AD6: =IF($AC6="","NEW","Live")
A7: Teleport | B7: 1 | C7: Common | D7: Move | G7: Move to any tile on the board. | H7: Anywhere | I7: 0 | J7: 0 | K7: Teleport | L7: Mage | M7: Movement | N7: Movement | O7: Tile | P7: Single | Z7: FALSE | AA7: FALSE | AC7: aaf80d8da0ea4c228b87cbad0b9af242 | AD7: =IF($AC7="","NEW","Live")
A8: Fireball | B8: 1 | C8: Rare | D8: Damage 5 | G8: Deal 5 damage. | H8: Chebyshev | I8: 1 | J8: 4 | K8: Fireball | L8: Mage | M8: RangedAttack | N8: Fire, Attack | O8: Tile | P8: Chebyshev 0-1 | Z8: FALSE | AA8: FALSE | AC8: 576ab6616f9067d458e6811318815c6c | AD8: =IF($AC8="","NEW","Live")
A9: Firebolt | B9: 1 | C9: Common | D9: Damage 5 | G9: Deal 5 damage. | H9: Chebyshev | I9: 1 | J9: 5 | K9: Firebolt | L9: Mage | M9: RangedAttack | N9: Fire, Attack | O9: Tile | P9: Single | Z9: FALSE | AA9: FALSE | AB9: Fireball | AC9: 000c1f73e085eb64b8d858c64dfdfcda | AD9: =IF($AC9="","NEW","Live")
A10: Flame Cone | B10: 1 | C10: Rare | D10: Damage 4 | G10: Deal 4 damage. | H10: Chebyshev | I10: 1 | J10: 1 | K10: Flame Cone | L10: Mage | M10: RangedAttack | N10: Fire, Attack | O10: Tile | P10: Pattern:Cone3 | Z10: FALSE | AA10: FALSE | AC10: 93cab38da2c31ed409077c18f3807992 | AD10: =IF($AC10="","NEW","Live")
A11: Ice Shard | B11: 1 | C11: Rare | D11: Damage 5 | E11: Freeze | G11: Deals 3 damage and Freezes. | H11: Chebyshev | I11: 1 | J11: 4 | K11: Ice Shard | L11: Mage | M11: RangedAttack | N11: Attack | O11: Tile | P11: Single | R11: Tile | S11: Single | Z11: FALSE | AA11: FALSE | AC11: 36d01c973ac698e428120b185d709229 | AD11: =IF($AC11="","NEW","Live")
A12: X-Burner | B12: 1 | C12: Rare | D12: Damage 5 | G12: Deal 5 damage. | H12: Chebyshev | I12: 1 | J12: 4 | K12: X-Burner | L12: Mage | M12: RangedAttack | N12: Fire, Attack | O12: Tile | P12: Pattern:X-Pattern | Z12: FALSE | AA12: FALSE | AC12: c8319799a424c03478428ce8d28e8e92 | AD12: =IF($AC12="","NEW","Live")
A13: Chaos Totem | B13: 1 | C13: Rare | D13: SummonChaosTotem | G13: Summon Chaos Totem Everyone within 2: take 3 more damage | H13: Chebyshev | I13: 1 | J13: 3 | K13: Chaos Totem | L13: Mage | M13: Summon | O13: Tile | P13: Single | Z13: FALSE | AA13: FALSE | AC13: be9e8db880616e449b7b9cb36178fba1 | AD13: =IF($AC13="","NEW","Live")
A14: Binding Totem | B14: 2 | C14: Uncommon | D14: SummonBindingTotem | G14: Summon Binding Totem Enemies within 2: double Rooted | H14: Chebyshev | I14: 1 | J14: 3 | K14: Binding Totem | L14: Mage | M14: Summon | O14: Tile | P14: Single | Z14: FALSE | AA14: FALSE | AC14: deb322298a9674d469f81de9d4774b0e | AD14: =IF($AC14="","NEW","Live")
A15: Conduit Totem | B15: 2 | C15: Uncommon | D15: SummonConduitTotem | G15: Summon Conduit Totem Allies within 2: draw on applying a status | H15: Chebyshev | I15: 1 | J15: 3 | K15: Conduit Totem | L15: Mage | M15: Summon | O15: Tile | P15: Single | Z15: FALSE | AA15: FALSE | AC15: 7a62a8d9fb25c9a4f8e9fb484cdfa9ff | AD15: =IF($AC15="","NEW","Live")
A16: Curse Totem | B16: 2 | C16: Rare | D16: SummonCurseTotem | G16: Summon Curse Totem Enemies within 2: double Vulnerable | H16: Chebyshev | I16: 1 | J16: 3 | K16: Curse Totem | L16: Mage | M16: Summon | O16: Tile | P16: Single | Z16: FALSE | AA16: FALSE | AC16: f00124f8df6b1c5469473a59ffe0b357 | AD16: =IF($AC16="","NEW","Live")
A17: Enfeeble Totem | B17: 2 | C17: Uncommon | D17: SummonEnfeebleTotem | G17: Summon Enfeeble Totem Enemies within 2: Weaken +3 stronger | H17: Chebyshev | I17: 1 | J17: 3 | K17: Enfeeble Totem | L17: Mage | M17: Summon | O17: Tile | P17: Single | Z17: FALSE | AA17: FALSE | AC17: a34ba9577dc8af24bb92fb81ee235a5d | AD17: =IF($AC17="","NEW","Live")
A18: Fracture Totem | B18: 2 | C18: Uncommon | D18: SummonFractureTotem | G18: Summon Fracture Totem Enemies within 2: take 3 more damage | H18: Chebyshev | I18: 1 | J18: 3 | K18: Fracture Totem | L18: Mage | M18: Summon | O18: Tile | P18: Single | Z18: FALSE | AA18: FALSE | AC18: 234fcf8ff9522344d9d5ee1022be130f | AD18: =IF($AC18="","NEW","Live")
A19: Hex Totem | B19: 2 | C19: Rare | D19: SummonHexTotem | G19: Summon Hex Totem Enemies within 2: double Weaken | H19: Chebyshev | I19: 1 | J19: 3 | K19: Hex Totem | L19: Mage | M19: Summon | O19: Tile | P19: Single | Z19: FALSE | AA19: FALSE | AC19: e5cd6de7d5df0fc44a67a6d1554ac7f4 | AD19: =IF($AC19="","NEW","Live")
A20: Ruin Totem | B20: 2 | C20: Uncommon | D20: SummonRuinTotem | G20: Summon Ruin Totem Enemies within 2: Vulnerable +3 stronger | H20: Chebyshev | I20: 1 | J20: 3 | K20: Ruin Totem | L20: Mage | M20: Summon | O20: Tile | P20: Single | Z20: FALSE | AA20: FALSE | AC20: e76eca70192ea0342abb35761afe55cf | AD20: =IF($AC20="","NEW","Live")
A21: Sap Totem | B21: 2 | C21: Uncommon | D21: SummonSapTotem | G21: Summon Sap Totem Enemies within 2: deal 3 less damage | H21: Chebyshev | I21: 1 | J21: 3 | K21: Sap Totem | L21: Mage | M21: Summon | O21: Tile | P21: Single | Z21: FALSE | AA21: FALSE | AC21: 8b23e21878068f84ca903b21df587219 | AD21: =IF($AC21="","NEW","Live")
A22: Scholar Totem | B22: 2 | C22: Uncommon | D22: SummonScholarTotem | G22: Summon Scholar Totem Allies within 2: +1 energy on draw | H22: Chebyshev | I22: 1 | J22: 3 | K22: Scholar Totem | L22: Mage | M22: Summon | O22: Tile | P22: Single | Z22: FALSE | AA22: FALSE | AC22: a6bec62ba7837e44ca5fe7aac759f0fb | AD22: =IF($AC22="","NEW","Live")
A23: Shackle Totem | B23: 2 | C23: Uncommon | D23: SummonShackleTotem | G23: Summon Shackle Totem Enemies within 2: Rooted each turn | H23: Chebyshev | I23: 1 | J23: 3 | K23: Shackle Totem | L23: Mage | M23: Summon | O23: Tile | P23: Single | Z23: FALSE | AA23: FALSE | AC23: 51c470e5e0a71854fbe33c2a8ac2db09 | AD23: =IF($AC23="","NEW","Live")
A24: Draw Totem | B24: 2 | C24: Uncommon | D24: SummonDrawTotem | G24: Summon Draw Totem Allies within 2: draw on dealing damage | H24: Chebyshev | I24: 1 | J24: 3 | K24: SummonDrawTotem | L24: Mage | M24: Summon | O24: Tile | P24: Single | Z24: FALSE | AA24: FALSE | AC24: 099a2eb5aca856a4d9a8ff396dc45e20 | AD24: =IF($AC24="","NEW","Live")
A25: Wall of Flames | B25: 2 | C25: Rare | D25: Wall of Flames | G25: Create a Wall of Flames, anything standing ontop will take 4 damage. | H25: Chebyshev | I25: 1 | J25: 3 | K25: WallOfFlames | L25: Mage | M25: Summon | N25: Fire | O25: Tile | P25: Pattern:Wall3 | Z25: FALSE | AA25: TRUE | AC25: a68a20cc6a62a794884b25eda9e5a871 | AD25: =IF($AC25="","NEW","Live")
A26: Wall of Force | B26: 2 | C26: Rare | D26: Push | E26: Wall of Force | G26: Create a Wall of Force, stopping all movement through that area. | H26: Chebyshev | I26: 1 | J26: 3 | K26: WallOfForce | L26: Mage | M26: Summon | N26: Defence | O26: Tile | P26: Pattern:Wall3 | R26: Tile | S26: Pattern:Wall3 | Z26: FALSE | AA26: TRUE | AC26: 317ae1a15cf5e44499040e5816fc71aa | AD26: =IF($AC26="","NEW","Live")
A27: Foresight | B27: 0 | C27: Uncommon | D27: Draw 1 | E27: Discard 1 | G27: Draw a card, then discard a card. | H27: SelfTile | I27: 0 | J27: 0 | K27: Foresight | L27: Mage | M27: Utility | O27: Self | P27: Single | R27: Self | S27: Single | Z27: FALSE | AA27: FALSE | AC27: df9e3bce91e2cd14681ef8aa00618104 | AD27: =IF($AC27="","NEW","Live")

Sheet Rogue
A1: Card Name | B1: Cost | C1: Rarity | D1: Effect 1 | E1: Effect 2 | F1: Effect 3 | G1: Description | H1: Range Shape | I1: Range Min | J1: Range Max | K1: Key | L1: Class | M1: Folder | N1: Tags | O1: Aim 1 | P1: Area 1 | Q1: Cond 1 | R1: Aim 2 | S1: Area 2 | T1: Cond 2 | U1: Aim 3 | V1: Area 3 | W1: Cond 3 | X1: Cost Cond | Y1: Keywords | Z1: No Reward | AA1: Rotatable | AB1: Animation | AC1: GUID | AD1: Sync | AE1: Notes
A2: Dodge | B2: 1 | C2: Uncommon | D2: Dodge | G2: Gain 1 stack of Dodge. | H2: SelfTile | I2: 0 | J2: 0 | K2: Dodge | L2: Rogue | M2: Buff (Defensive) | N2: Defence, Movement | O2: Tile | P2: Single | Z2: FALSE | AA2: FALSE | AC2: 1eea8f6c4d1062d4f9a550078d14e259 | AD2: =IF($AC2="","NEW","Live")
A3: Evasion | B3: 1 | C3: Uncommon | D3: Block 2 | G3: Gain 2 stacks of Block. | H3: SelfTile | I3: 0 | J3: 0 | K3: Evasion | L3: Rogue | M3: Buff (Defensive) | N3: Defence | O3: Self | P3: Single | Z3: FALSE | AA3: FALSE | AC3: ea4ea121456773f47b2377471122e93e | AD3: =IF($AC3="","NEW","Live")
A4: Stealth | B4: 1 | C4: Rare | D4: Stealth 2 | G4: For 2 turns, enemies cannot target you. | H4: SelfTile | I4: 0 | J4: 0 | K4: Stealth | L4: Rogue | M4: Buff (Defensive) | N4: Defence | O4: Self | P4: Single | Z4: FALSE | AA4: FALSE | AC4: 3fb463a3a81ff074ab5a518311ca75e2 | AD4: =IF($AC4="","NEW","Live")
A5: Leeching Blade | B5: 1 | C5: Common | D5: Lifesteal 3 | G5: For 3 turns, your attacks heal you for half the damage dealt. | H5: SelfTile | I5: 0 | J5: 0 | K5: Leeching Blade | L5: Rogue | M5: Buff (Offensive) | N5: Attack, Healing | O5: Self | P5: Single | Z5: TRUE | AA5: FALSE | AC5: 56e43cd12f2be6d468cf6827daaed8bb | AD5: =IF($AC5="","NEW","Live")
A6: Poison Blade | B6: 1 | C6: Uncommon | D6: Poison Blade 3 | G6: For 3 turns, your attacks apply 1 Poison. | H6: SelfTile | I6: 0 | J6: 0 | K6: Poison Blade | L6: Rogue | M6: Buff (Offensive) | N6: Attack, Poison | O6: Self | P6: Single | Z6: FALSE | AA6: FALSE | AC6: 8a487f54103a58548956028d93692641 | AD6: =IF($AC6="","NEW","Live")
A7: Panache | B7: 1 | C7: Uncommon | D7: Weaken 2 | G7: Apply 3 stacks of Weaken. | H7: Chebyshev | I7: 1 | J7: 4 | K7: Panache | L7: Rogue | M7: Debuff | O7: Tile | P7: Single | Z7: FALSE | AA7: FALSE | AC7: 4ead4a101ac64ee4a8dbc0d5917ad849 | AD7: =IF($AC7="","NEW","Live")
A8: Quick Attack | B8: 0 | C8: Uncommon | D8: Damage 3 | G8: Deal 3 damage. | H8: Chebyshev | I8: 1 | J8: 1 | K8: Quick Attack | L8: Rogue | M8: Melee Attack | N8: Attack | O8: Tile | P8: Single | Z8: FALSE | AA8: FALSE | AC8: b2d16f22e3045c1baf6d28e51c2f6002 | AD8: =IF($AC8="","NEW","Live")
A9: Poison Dagger | B9: 1 | C9: Uncommon | D9: Damage 4 | E9: Poison 3 | G9: Deal 4 damage and apply 3 Poison. | H9: Chebyshev | I9: 1 | J9: 1 | K9: Poison Dagger | L9: Any | M9: Melee Attack | N9: Attack | O9: Tile | P9: Single | R9: Tile | S9: Single | Z9: FALSE | AA9: FALSE | AC9: 4b1d872acef079b4b9803f32615146d9 | AD9: =IF($AC9="","NEW","Live")
A10: Shambles | B10: 1 | C10: Rare | D10: Swap | G10: Swap places with any character within 3 tiles. | H10: Chebyshev | I10: 1 | J10: 3 | K10: Shambles | L10: Rogue | M10: Movement | N10: Movement | O10: Tile | P10: Single | Z10: FALSE | AA10: FALSE | AC10: ab457316daf03a740aac2696a6bb616b | AD10: =IF($AC10="","NEW","Live")
A11: Poison Dart | B11: 1 | C11: Common | D11: Poison 4 | G11: Apply 4 stacks of Poison. | H11: Chebyshev | I11: 1 | J11: 4 | K11: Poison Dart | L11: Rogue | M11: RangedAttack | O11: Tile | P11: Single | Z11: FALSE | AA11: FALSE | AC11: 0e3798dd733944d180801d6f2263b739 | AD11: =IF($AC11="","NEW","Live")
A12: Decoy Totem | B12: 1 | C12: Uncommon | D12: SummonDecoyTotem | G12: Summon Decoy Totem Taunt Enemies within 3 | H12: Chebyshev | I12: 1 | J12: 3 | K12: Decoy Totem | L12: Rogue | M12: Summon | O12: Tile | P12: Single | Z12: FALSE | AA12: FALSE | AC12: c08631cd0fb101e42a5d73dbd887945a | AD12: =IF($AC12="","NEW","Live")
A13: Contagion Totem | B13: 2 | C13: Uncommon | D13: SummonContagionTotem | G13: Summon Contagion Totem Enemies within 2: double Poison | H13: Chebyshev | I13: 1 | J13: 3 | K13: Contagion Totem | L13: Rogue | M13: Summon | O13: Tile | P13: Single | Z13: FALSE | AA13: FALSE | AC13: 302ebe6cf5deadf468117453ebf7f0d5 | AD13: =IF($AC13="","NEW","Live")
A14: Fortune Totem | B14: 2 | C14: Uncommon | D14: SummonFortuneTotem | G14: Summon Fortune Totem Allies within 2: double Dodge | H14: Chebyshev | I14: 1 | J14: 3 | K14: Fortune Totem | L14: Rogue | M14: Summon | O14: Tile | P14: Single | Z14: FALSE | AA14: FALSE | AC14: 79fb1797bac377241be137dd9d4684cb | AD14: =IF($AC14="","NEW","Live")
A15: Ghoststep Totem | B15: 2 | C15: Uncommon | D15: SummonGhoststepTotem | G15: Summon Ghoststep Totem Allies within 2: gain 1 Dodge each turn | H15: Chebyshev | I15: 1 | J15: 3 | K15: Ghoststep Totem | L15: Rogue | M15: Summon | O15: Tile | P15: Single | Z15: FALSE | AA15: FALSE | AC15: 887c9ea2036e9fa4caafd48965354572 | AD15: =IF($AC15="","NEW","Live")
A16: Leech Totem | B16: 2 | C16: Uncommon | D16: SummonLeechTotem | G16: Summon Leech Totem Allies within 2: heal half damage dealt | H16: Chebyshev | I16: 1 | J16: 3 | K16: Leech Totem | L16: Rogue | M16: Summon | O16: Tile | P16: Single | Z16: FALSE | AA16: FALSE | AC16: 2d814aeedc0b89f4eb207904f83abdf3 | AD16: =IF($AC16="","NEW","Live")
A17: Rot Totem | B17: 2 | C17: Rare | D17: SummonRotTotem | G17: Summon Rot Totem Enemies within 2: gain 4 Poison each turn | H17: Chebyshev | I17: 1 | J17: 3 | K17: Rot Totem | L17: Rogue | M17: Summon | O17: Tile | P17: Single | Z17: FALSE | AA17: FALSE | AC17: 41c8eeed77695c5478e63466cb1992a3 | AD17: =IF($AC17="","NEW","Live")
A18: Spike Totem | B18: 2 | C18: Uncommon | D18: SummonSpikeTotem | G18: Summon Spike Totem Enemies within 2: take 2 on move | H18: Chebyshev | I18: 1 | J18: 3 | K18: Spike Totem | L18: Rogue | M18: Summon | O18: Tile | P18: Single | Z18: FALSE | AA18: FALSE | AC18: 81681948dc874bd4c9ea08e8e8adafb1 | AD18: =IF($AC18="","NEW","Live")
A19: Veil Totem | B19: 2 | C19: Uncommon | D19: SummonVeilTotem | G19: Summon Veil Totem Allies within 2: can't be targeted | H19: Chebyshev | I19: 1 | J19: 3 | K19: Veil Totem | L19: Rogue | M19: Summon | O19: Tile | P19: Single | Z19: FALSE | AA19: FALSE | AC19: c0769be3baf84ac4196889f3113de54a | AD19: =IF($AC19="","NEW","Live")
A20: Venom Totem | B20: 2 | C20: Rare | D20: SummonVenomTotem | G20: Summon Venom Totem Enemies within 2: gain 2 Poison each turn | H20: Chebyshev | I20: 1 | J20: 3 | K20: Venom Totem | L20: Rogue | M20: Summon | N20: Summon, Poison | O20: Tile | P20: Single | Z20: FALSE | AA20: FALSE | AC20: 139ccd0500259c4429836b43f9a7145a | AD20: =IF($AC20="","NEW","Live")
A21: Venomblade Totem | B21: 2 | C21: Uncommon | D21: SummonVenombladeTotem | G21: Summon Venomblade Totem Allies within 2: hits apply 1 Poison | H21: Chebyshev | I21: 1 | J21: 3 | K21: Venomblade Totem | L21: Rogue | M21: Summon | O21: Tile | P21: Single | Z21: FALSE | AA21: FALSE | AC21: cc7ab5e114f35204796b0438e7e5625f | AD21: =IF($AC21="","NEW","Live")

Sheet Cleric
A1: Card Name | B1: Cost | C1: Rarity | D1: Effect 1 | E1: Effect 2 | F1: Effect 3 | G1: Description | H1: Range Shape | I1: Range Min | J1: Range Max | K1: Key | L1: Class | M1: Folder | N1: Tags | O1: Aim 1 | P1: Area 1 | Q1: Cond 1 | R1: Aim 2 | S1: Area 2 | T1: Cond 2 | U1: Aim 3 | V1: Area 3 | W1: Cond 3 | X1: Cost Cond | Y1: Keywords | Z1: No Reward | AA1: Rotatable | AB1: Animation | AC1: GUID | AD1: Sync | AE1: Notes
A2: Blade Ward | B2: 1 | C2: Uncommon | D2: Block 1 | G2: Give Block. | H2: Chebyshev | I2: 0 | J2: 4 | K2: Blade Ward | L2: Cleric | M2: Buff (Defensive) | N2: Defence | O2: Tile | P2: Single | Z2: TRUE | AA2: FALSE | AC2: 0313f5e3f95e9704d8ddff8d29ecefcd | AD2: =IF($AC2="","NEW","Live")
A3: Blessed Shield | B3: 1 | C3: Uncommon | D3: Shield 10 | G3: Give 10 Shield. | H3: Chebyshev | I3: 0 | J3: 4 | K3: Blessed Shield | L3: Cleric | M3: Buff (Defensive) | N3: Defence | O3: Tile | P3: Single | Z3: FALSE | AA3: FALSE | AC3: 175eddf5ef5df5a4ea59b73185ae3cc3 | AD3: =IF($AC3="","NEW","Live")
A4: Distant Grace | B4: 1 | C4: Uncommon | D4: Shield 6 | G4: Give 6 Shield. Alone: give 10 instead. | H4: Chebyshev | I4: 0 | J4: 4 | K4: Distant Grace | L4: Cleric | M4: Buff (Defensive) | N4: Healing | O4: Tile | P4: Single | Q4: Alone +4 | Z4: FALSE | AA4: FALSE | AC4: 04b40add9afb299408a7ee93bfe48bb0 | AD4: =IF($AC4="","NEW","Live")
A5: Shield of Faith | B5: 1 | C5: Uncommon | D5: Shield 5 | E5: Draw 1 | G5: Give 5 Shield. Next to another hero: give 9 and draw 1. | H5: Chebyshev | I5: 0 | J5: 4 | K5: Shield of Faith | L5: Cleric | M5: Buff (Defensive) | N5: Healing | O5: Tile | P5: Single | Q5: NextToHero +4 | R5: Self | S5: Single | T5: NextToHero only | Z5: FALSE | AA5: FALSE | AC5: 74b79ec5f4457e241a83817f4432ff38 | AD5: =IF($AC5="","NEW","Live")
A6: Shrine Blessing | B6: 1 | C6: Uncommon | D6: Shield 9 | E6: Draw 1 | G6: Give 9 Shield. Draw 1. Costs 0 next to a totem. | H6: Chebyshev | I6: 0 | J6: 4 | K6: Shrine Blessing | L6: Cleric | M6: Buff (Defensive) | N6: Defence | O6: Tile | P6: Single | R6: Self | S6: Single | X6: NextToTotem -1 | Z6: FALSE | AA6: FALSE | AC6: a0b3386d15333644380841641a66851f | AD6: =IF($AC6="","NEW","Live")
A7: Ward Blessing | B7: 1 | C7: Uncommon | D7: Shield 5 | G7: Give 5 Shield. Costs 0 next to another hero. | H7: Chebyshev | I7: 0 | J7: 4 | K7: Ward Blessing | L7: Cleric | M7: Buff (Defensive) | N7: Defence | O7: Tile | P7: Single | X7: NextToHero -1 | Z7: FALSE | AA7: FALSE | AC7: 08b2151905b6ded4990637ecbe601221 | AD7: =IF($AC7="","NEW","Live")
A8: Vengeful Vigor | B8: 1 | C8: Uncommon | D8: Lifesteal 1 | G8: Apply Lifesteal 1. | H8: Chebyshev | I8: 0 | J8: 4 | K8: Vengeful Vigor | L8: Cleric | M8: Buff (Offensive) | O8: Tile | P8: Single | Z8: TRUE | AA8: FALSE | AC8: 03b73a23f7ceebf41b9dc0773a7935bc | AD8: =IF($AC8="","NEW","Live")
A9: Purge | B9: 1 | C9: Uncommon | D9: Purge Poison | G9: Remove all Poison from an ally and afflict the nearest enemy with it. | H9: Chebyshev | I9: 1 | J9: 4 | K9: Purge | L9: Cleric | M9: Debuff | O9: Tile | P9: Single | Z9: TRUE | AA9: FALSE | AC9: 0aca4faf7138a9c4db512e6cf3962233 | AD9: =IF($AC9="","NEW","Live")
A10: Benediction | B10: 1 | C10: Uncommon | D10: Heal 4 | E10: Draw 1 | G10: Heal 4 to an ally and every ally next to them. Draw 1. | H10: Chebyshev | I10: 0 | J10: 4 | K10: Benediction | L10: Cleric | M10: Heal | N10: Healing | O10: Tile | P10: Chebyshev 0-1 | R10: Self | S10: Single | Z10: FALSE | AA10: FALSE | AC10: 5fed507f2b9412840b17c166844be387 | AD10: =IF($AC10="","NEW","Live")
A11: Cleansing Light | B11: 1 | C11: Common | D11: Cleanse Curses Heal | G11: Remove all negative effects from an ally and heal them for the stacks removed. | H11: Chebyshev | I11: 0 | J11: 4 | K11: Cleansing Light | L11: Cleric | M11: Heal | O11: Tile | P11: Single | Z11: TRUE | AA11: FALSE | AC11: 09e3ae3a175a86a44b79648130db2fbf | AD11: =IF($AC11="","NEW","Live")
A12: Close Prayer | B12: 1 | C12: Uncommon | D12: Heal 7 | E12: Draw 1 | G12: Heal 7. Next to another hero: draw 1. | H12: Chebyshev | I12: 0 | J12: 4 | K12: Close Prayer | L12: Cleric | M12: Heal | N12: Healing | O12: Tile | P12: Single | R12: Self | S12: Single | T12: NextToHero only | Z12: FALSE | AA12: FALSE | AC12: 4797ff6a48d6489488f7baf2ce20d159 | AD12: =IF($AC12="","NEW","Live")
A13: Touch Heal | B13: 1 | C13: Uncommon | D13: Heal 10 | G13: Heal 10. | H13: Chebyshev | I13: 0 | J13: 4 | K13: Cure Wounds | L13: Cleric | M13: Heal | N13: Healing | O13: Tile | P13: Single | Z13: FALSE | AA13: FALSE | AC13: b2d16f22e3045c1baf6d28e51c2f6004 | AD13: =IF($AC13="","NEW","Live")
A14: Far Mend | B14: 1 | C14: Uncommon | D14: Heal 7 | E14: Draw 1 | G14: Heal 7. Alone: draw 1. | H14: Chebyshev | I14: 0 | J14: 4 | K14: Far Mend | L14: Cleric | M14: Heal | N14: Healing | O14: Tile | P14: Single | R14: Self | S14: Single | T14: Alone only | Z14: FALSE | AA14: FALSE | AC14: 023721848dd82404c87b4d52af1cab73 | AD14: =IF($AC14="","NEW","Live")
A15: Guiding Smite | B15: 1 | C15: Uncommon | D15: Damage 7 | E15: Heal 4 | G15: Deal 7 damage. You and allies next to you heal 4. | H15: Chebyshev | I15: 1 | J15: 4 | K15: Guiding Smite | L15: Cleric | M15: Heal | N15: Attack | O15: Tile | P15: Single | R15: Self | S15: Chebyshev 0-1 | Z15: FALSE | AA15: FALSE | AC15: 532778b466b668342b2043a76e5820d8 | AD15: =IF($AC15="","NEW","Live")
A16: Heal Word | B16: 1 | C16: Common | D16: Heal 5 | G16: Heal 5. | H16: Chebyshev | I16: 0 | J16: 4 | K16: Heal Word | L16: Cleric | M16: Heal | N16: Healing | O16: Tile | P16: Single | Z16: TRUE | AA16: FALSE | AC16: b0de35f4e0b135845b19e60120fd3205 | AD16: =IF($AC16="","NEW","Live")
A17: Hermit's Smite | B17: 1 | C17: Uncommon | D17: Damage 8 | E17: Heal 3 | G17: Deal 8 damage. Heal 3. Alone: deal 12 instead. | H17: Chebyshev | I17: 1 | J17: 4 | K17: Hermit's Smite | L17: Cleric | M17: Heal | N17: Attack | O17: Tile | P17: Single | Q17: Alone +4 | R17: Self | S17: Single | Z17: FALSE | AA17: FALSE | AC17: f484fb35bb9babc4b9415b6cbbbb5c56 | AD17: =IF($AC17="","NEW","Live")
A18: Holy Smite | B18: 1 | C18: Uncommon | D18: Damage 8 | E18: Heal 4 | G18: Deal 8 damage. Heal 4. | H18: Chebyshev | I18: 1 | J18: 4 | K18: Holy Smite | L18: Cleric | M18: Heal | N18: Attack | O18: Tile | P18: Single | R18: Self | S18: Single | Z18: FALSE | AA18: FALSE | AC18: b6b5763536cee8440bf2d3606de913c4 | AD18: =IF($AC18="","NEW","Live")
A19: Judgement | B19: 1 | C19: Rare | D19: Damage 9 | E19: Draw 1 | G19: Deal 9 damage. Alone: costs 0 and draw 1. | H19: Chebyshev | I19: 1 | J19: 4 | K19: Judgement | L19: Cleric | M19: Heal | N19: Attack | O19: Tile | P19: Single | R19: Self | S19: Single | T19: Alone only | X19: Alone -1 | Z19: FALSE | AA19: FALSE | AC19: abaddd2655a840e449884c0c3bbed34a | AD19: =IF($AC19="","NEW","Live")
A20: Lasting Renewal | B20: 1 | C20: Uncommon | D20: Regeneration 4 | G20: Apply Regeneration 4. | H20: Chebyshev | I20: 0 | J20: 4 | K20: Lasting Renewal | L20: Cleric | M20: Heal | O20: Tile | P20: Single | Z20: FALSE | AA20: FALSE | AC20: 37bf83cfbd3d9bd438346a067e59a00c | AD20: =IF($AC20="","NEW","Live")
A21: Laying on of Hands | B21: 1 | C21: Uncommon | D21: Heal 7 | G21: Heal 7 to you and allies next to you. | H21: SelfTile | I21: 0 | J21: 0 | K21: Laying on of Hands | L21: Cleric | M21: Heal | N21: Healing | O21: Self | P21: Chebyshev 0-1 | Z21: FALSE | AA21: FALSE | AC21: 19032b9f33d0ce24bbca258b3ad9dbff | AD21: =IF($AC21="","NEW","Live")
A22: Mending Light | B22: 1 | C22: Uncommon | D22: Heal 4 | G22: Heal 4. Costs 0 next to another hero. | H22: Chebyshev | I22: 0 | J22: 4 | K22: Mending Light | L22: Cleric | M22: Heal | N22: Healing | O22: Tile | P22: Single | X22: NextToHero -1 | Z22: FALSE | AA22: FALSE | AC22: b366fea67432b594c8ec7e726e7152c8 | AD22: =IF($AC22="","NEW","Live")
A23: Prayer Circle | B23: 1 | C23: Uncommon | D23: Heal 5 | E23: Draw 1 | G23: Heal 5. Draw 1. Costs 0 next to another hero. | H23: Chebyshev | I23: 0 | J23: 4 | K23: Prayer Circle | L23: Cleric | M23: Heal | N23: Healing | O23: Tile | P23: Single | R23: Self | S23: Single | X23: NextToHero -1 | Z23: FALSE | AA23: FALSE | AC23: 593c12d96b73d764ea78f7c8bfb89d5d | AD23: =IF($AC23="","NEW","Live")
A24: Radiant Smite | B24: 1 | C24: Uncommon | D24: Damage 6 | E24: Heal 3 | F24: Draw 1 | G24: Deal 6 damage. Heal 3. Draw 1. Costs 0 while you have Shield. | H24: Chebyshev | I24: 1 | J24: 4 | K24: Radiant Smite | L24: Cleric | M24: Heal | N24: Attack | O24: Tile | P24: Single | R24: Self | S24: Single | U24: Self | V24: Single | X24: HasShield -1 | Z24: FALSE | AA24: FALSE | AC24: d87b16954bfa4774da47f6848afc3e36 | AD24: =IF($AC24="","NEW","Live")
A25: Rejuvenate | B25: 1 | C25: Uncommon | D25: Heal 6 | E25: Draw 1 | G25: Heal 6 and draw a card. | H25: Chebyshev | I25: 0 | J25: 4 | K25: Rejuvenate | L25: Cleric | M25: Heal | O25: Tile | P25: Single | R25: Self | S25: Single | Z25: FALSE | AA25: FALSE | AC25: 2cee7221146827246960b805f60da04d | AD25: =IF($AC25="","NEW","Live")
A26: Renew | B26: 1 | C26: Common | D26: Heal 3 | E26: Draw 1 | G26: Heal 3 and draw a card. | H26: Chebyshev | I26: 0 | J26: 4 | K26: Renew | L26: Cleric | M26: Heal | O26: Tile | P26: Single | R26: Tile | S26: Single | Z26: TRUE | AA26: FALSE | AC26: 940d27453c9c1924499110bc2380e444 | AD26: =IF($AC26="","NEW","Live")
A27: Sanctified Ground | B27: 1 | C27: Rare | D27: Shield 5 | E27: Heal 5 | G27: You and allies next to you gain 5 Shield and heal 5. | H27: SelfTile | I27: 0 | J27: 0 | K27: Sanctified Ground | L27: Cleric | M27: Heal | N27: Healing | O27: Self | P27: Chebyshev 0-1 | R27: Self | S27: Chebyshev 0-1 | Z27: FALSE | AA27: FALSE | AC27: aa90828795c6e6542ac261a74bf024ef | AD27: =IF($AC27="","NEW","Live")
A28: Sanctified Guard | B28: 1 | C28: Uncommon | D28: Heal 5 | E28: Block 1 | G28: Heal 5 and give Block. | H28: Chebyshev | I28: 0 | J28: 4 | K28: Sanctified Guard | L28: Cleric | M28: Heal | O28: Tile | P28: Single | R28: Tile | S28: Single | Z28: FALSE | AA28: FALSE | AC28: 1bb8e3ea252264347bbaeb4b919b5c31 | AD28: =IF($AC28="","NEW","Live")
A29: Smite | B29: 1 | C29: Common | D29: Heal 6 | E29: Heal 3 | G29: Deal 4 damage. Heal 3. | H29: Chebyshev | I29: 1 | J29: 4 | K29: Smite | L29: Cleric | M29: Heal | N29: Attack | O29: Tile | P29: Single | R29: Self | S29: Single | Z29: TRUE | AA29: FALSE | AC29: 96e73bab6c061cd49bf0c98a367e781e | AD29: =IF($AC29="","NEW","Live")
A30: Smite Together | B30: 1 | C30: Uncommon | D30: Damage 7 | E30: Heal 3 | G30: Deal 7 damage. Heal 3. Next to another hero: deal 10 instead. | H30: Chebyshev | I30: 1 | J30: 4 | K30: Smite Together | L30: Cleric | M30: Heal | N30: Attack | O30: Tile | P30: Single | Q30: NextToHero +3 | R30: Self | S30: Single | Z30: FALSE | AA30: FALSE | AC30: 3cf49416bcf904842a9f37f5af23af03 | AD30: =IF($AC30="","NEW","Live")
A31: Communion | B31: 2 | C31: Rare | D31: Heal 5 | E31: Draw 1 | G31: Heal 5 to you and allies within 2. Draw 1. Costs 1 next to another hero. | H31: SelfTile | I31: 0 | J31: 0 | K31: Communion | L31: Cleric | M31: Heal | N31: Defence | O31: Self | P31: Manhattan 0-2 | R31: Self | S31: Single | X31: NextToHero -1 | Z31: FALSE | AA31: FALSE | AC31: ccc6b83e3e58748438b980a73eac90bf | AD31: =IF($AC31="","NEW","Live")
A32: Mend and Fortify | B32: 2 | C32: Uncommon | D32: Heal 5 | E32: Strength 3 | G32: Heal 5 and gain 3 Strength. | H32: Chebyshev | I32: 0 | J32: 4 | K32: Mend and Fortify | L32: Cleric | M32: Heal | O32: Tile | P32: Single | R32: Tile | S32: Single | Z32: FALSE | AA32: FALSE | AC32: 31fea6d7f3b17b54fbfee4ce54165c76 | AD32: =IF($AC32="","NEW","Live")
A33: Mend and Guard | B33: 2 | C33: Uncommon | D33: Heal 5 | E33: Block 1 | G33: Heal 5 and gain Block. | H33: Chebyshev | I33: 0 | J33: 4 | K33: Mend and Guard | L33: Cleric | M33: Heal | O33: Tile | P33: Single | R33: Tile | S33: Single | Z33: TRUE | AA33: FALSE | AC33: b463c182abe12924b8bd14a649d2c3a4 | AD33: =IF($AC33="","NEW","Live")
A34: Renewing Touch | B34: 2 | C34: Uncommon | D34: Regeneration 4 | G34: Apply Regeneration 4. | H34: Chebyshev | I34: 0 | J34: 4 | K34: Renewing Touch | L34: Cleric | M34: Heal | O34: Tile | P34: Single | Z34: TRUE | AA34: FALSE | AC34: 25e5a08179ad2a848b8539a19c5bbfa7 | AD34: =IF($AC34="","NEW","Live")
A35: Vigil | B35: 2 | C35: Rare | D35: Heal 12 | E35: Draw 1 | G35: Heal 12. Draw 1. Costs 1 when alone. | H35: Chebyshev | I35: 0 | J35: 4 | K35: Vigil | L35: Cleric | M35: Heal | N35: Healing | O35: Tile | P35: Single | R35: Self | S35: Single | X35: Alone -1 | Z35: FALSE | AA35: FALSE | AC35: 635cd3ef41882ce44b1bfd1a51701478 | AD35: =IF($AC35="","NEW","Live")
A36: Aegis Totem | B36: 1 | C36: Rare | D36: SummonAegisTotem | G36: Summon Aegis Totem Allies within 2: Block +3 stronger | H36: Chebyshev | I36: 1 | J36: 3 | K36: Aegis Totem | L36: Cleric | M36: Summon | O36: Tile | P36: Single | Z36: FALSE | AA36: FALSE | AC36: 01e630d4f30206f499a5038a0e474c92 | AD36: =IF($AC36="","NEW","Live")
A37: Bastion Totem | B37: 1 | C37: Uncommon | D37: SummonBastionTotem | G37: Summon Bastion Totem Allies within 2: gain 5 Shield each turn | H37: Chebyshev | I37: 1 | J37: 3 | K37: Bastion Totem | L37: Cleric | M37: Summon | O37: Tile | P37: Single | Z37: FALSE | AA37: FALSE | AC37: b5992955f6f71d249bd207dc483e4566 | AD37: =IF($AC37="","NEW","Live")
A38: Beacon Totem | B38: 1 | C38: Uncommon | D38: SummonBeaconTotem | G38: Summon Beacon Totem Taunt Enemies within 2 | H38: Chebyshev | I38: 1 | J38: 2 | K38: Beacon Totem | L38: Cleric | M38: Summon | O38: Tile | P38: Single | Z38: TRUE | AA38: FALSE | AC38: f6d1fbe1cfdd0314f9969e1457bfebe1 | AD38: =IF($AC38="","NEW","Live")
A39: Bloodpact Totem | B39: 1 | C39: Uncommon | D39: SummonBloodpactTotem | G39: Summon Bloodpact Totem Allies within 2: heal 3 on attack | H39: Chebyshev | I39: 1 | J39: 3 | K39: Bloodpact Totem | L39: Cleric | M39: Summon | O39: Tile | P39: Single | Z39: FALSE | AA39: FALSE | AC39: b6d8d70794292df43a53dfecffd26dfe | AD39: =IF($AC39="","NEW","Live")
A40: Echo Totem | B40: 1 | C40: Uncommon | D40: SummonEchoTotem | G40: Summon Echo Totem Allies within 2: 5 Shield on summon | H40: Chebyshev | I40: 1 | J40: 3 | K40: Echo Totem | L40: Cleric | M40: Summon | O40: Tile | P40: Single | Z40: FALSE | AA40: FALSE | AC40: f1df2170a944fd34785c7e3569efd815 | AD40: =IF($AC40="","NEW","Live")
...

Sheet Neutral
A1: Card Name | B1: Cost | C1: Rarity | D1: Effect 1 | E1: Effect 2 | F1: Effect 3 | G1: Description | H1: Range Shape | I1: Range Min | J1: Range Max | K1: Key | L1: Class | M1: Folder | N1: Tags | O1: Aim 1 | P1: Area 1 | Q1: Cond 1 | R1: Aim 2 | S1: Area 2 | T1: Cond 2 | U1: Aim 3 | V1: Area 3 | W1: Cond 3 | X1: Cost Cond | Y1: Keywords | Z1: No Reward | AA1: Rotatable | AB1: Animation | AC1: GUID | AD1: Sync | AE1: Notes
A2: Overflow | B2: 0 | C2: NotOffered | D2: Energy 3 | G2: Gain 3 energy. Returns to your hand. | H2: SelfTile | I2: 0 | J2: 0 | K2: Overflow | L2: Any | O2: Self | P2: Single | Y2: Innate, Rebound | Z2: TRUE | AA2: FALSE | AC2: 400da0a1fb8039847bb2c4bfc31f38d7 | AD2: =IF($AC2="","NEW","Live")
A3: Summon Skeleton Warrior | B3: 0 | C3: NotOffered | D3: SummonSkeletonWarrior | G3: Summon a Skeleton Warrior. | H3: Chebyshev | I3: 1 | J3: 5 | K3: SummonSkeletonWarrior | L3: Any | O3: Tile | P3: Single | Y3: Dormant 3, Cooldown 4 | Z3: FALSE | AA3: FALSE | AC3: e0f2734ed1017c7419f5d21d3fb737f4 | AD3: =IF($AC3="","NEW","Live")
A4: EnemyArrow | B4: 1 | C4: NotOffered | D4: Damage 3 | E4: Vulnerable | G4: Deal 3 damage and apply Vulnerable to an enemy within 4 tiles. | H4: Chebyshev | I4: 1 | J4: 4 | K4: EnemyArrow | L4: Any | O4: Tile | P4: Single | R4: Tile | S4: Single | Z4: FALSE | AA4: FALSE | AB4: EnemyArrow | AC4: bbde0f0e0cc14d529a5088cf2502a322 | AD4: =IF($AC4="","NEW","Live")
B5: 1 | C5: NotOffered | D5: Damage 8 | G5: Deal 5 damage. | H5: Chebyshev | I5: 1 | J5: 1 | K5: EnemySlash | L5: Any | O5: Tile | P5: Single | Z5: FALSE | AA5: FALSE | AC5: 4e6ad46400a24ad49889dba4ec94d0b6 | AD5: =IF($AC5="","NEW","Live")
A6: Move 1 | B6: 1 | C6: Common | D6: Move | G6: Move one tile in any direction. | H6: Chebyshev | I6: 1 | J6: 1 | K6: Move | L6: Any | N6: Movement | O6: Tile | P6: Single | Z6: TRUE | AA6: FALSE | AC6: be5db39fd599473588c5ca05a015d151 | AD6: =IF($AC6="","NEW","Live")
A7: Move 1 | B7: 1 | C7: NotOffered | D7: Move | G7: Move one tile in any direction. | H7: Chebyshev | I7: 1 | J7: 1 | K7: MoveInnate | L7: Any | O7: Tile | P7: Single | Y7: Innate | Z7: FALSE | AA7: FALSE | AC7: 0c8f3a6d2b4e4f9a8c1d7e5b3a2f6c9d | AD7: =IF($AC7="","NEW","Live")
A8: Move 2 | B8: 1 | C8: NotOffered | D8: Move | G8: Move up to two tiles in any direction. | H8: Chebyshev | I8: 1 | J8: 2 | K8: MoveInnate2 | L8: Any | O8: Tile | P8: Single | Y8: Innate | Z8: FALSE | AA8: FALSE | AC8: 4f7b2c91e6a84d3ab0d5c8e27f1a9b64 | AD8: =IF($AC8="","NEW","Live")
A9: Teleport | B9: 1 | C9: NotOffered | D9: Move | G9: Move up to three tiles in any direction, ignoring walls. | H9: Chebyshev | I9: 1 | J9: 3 | K9: TeleportInnate | L9: Any | O9: Tile | P9: Single | Y9: Innate | Z9: TRUE | AA9: FALSE | AC9: c63bc2ac593efc9409d8b2e2b673a08d | AD9: =IF($AC9="","NEW","Live")
A10: Bite | B10: 1 | C10: NotOffered | D10: Damage 5 | G10: Deal 5 damage. | H10: Chebyshev | I10: 1 | J10: 1 | K10: Bite | L10: Any | M10: Bat | N10: Attack | O10: Tile | P10: Single | Z10: FALSE | AA10: FALSE | AC10: ee373f925ba104f43bcc820881e5a445 | AD10: =IF($AC10="","NEW","Live")
A11: Call the Damned | B11: 0 | C11: NotOffered | D11: SummonSkeletonMinion | G11: Summon a Skeleton. | H11: Chebyshev | I11: 1 | J11: 3 | K11: CallTheDamned | L11: Any | M11: BlackKnight | N11: Summon | O11: Tile | P11: Single | Y11: Cooldown 3 | Z11: FALSE | AA11: FALSE | AC11: da46264a9760d4b499106e4057fe349a | AD11: =IF($AC11="","NEW","Live")
A12: Black Guard | B12: 1 | C12: NotOffered | D12: Damage 5 | G12: Deal 5 damage. | H12: Chebyshev | I12: 1 | J12: 1 | K12: BlackGuard | L12: Any | M12: BlackKnight | N12: Attack | O12: Tile | P12: Single | Z12: FALSE | AA12: FALSE | AC12: 9b2ff5c09da592b4aac092835fb9d5f8 | AD12: =IF($AC12="","NEW","Live")
A13: Dread Cleave | B13: 1 | C13: NotOffered | D13: Damage 8 | G13: Deal 8 damage to everything within 1 tile. | H13: Chebyshev | I13: 1 | J13: 1 | K13: DreadCleave | L13: Any | M13: BlackKnight | N13: Attack | O13: Tile | P13: Chebyshev 0-1 | Z13: FALSE | AA13: FALSE | AC13: 911c7b3450e79a1448f794b46caf54e3 | AD13: =IF($AC13="","NEW","Live")
A14: Claw Attack | B14: 1 | C14: NotOffered | D14: Damage 4 | E14: Shield 4 | G14: Deal 4 damage. Gain 4 Shield | H14: Chebyshev | I14: 1 | J14: 1 | K14: ClawAttack | L14: Any | M14: Crab | N14: Attack | O14: Tile | P14: Single | R14: Self | S14: Single | Z14: FALSE | AA14: FALSE | AC14: 2c191dc4234fac04e8738aabc36b6cee | AD14: =IF($AC14="","NEW","Live")
A15: Royal Command | B15: 0 | C15: NotOffered | D15: SummonLightBanditMinion | G15: Summon a Light Bandit. | H15: Chebyshev | I15: 1 | J15: 3 | K15: RoyalCommand | L15: Any | M15: EvilKing | N15: Summon | O15: Tile | P15: Single | Y15: Cooldown 3 | Z15: FALSE | AA15: FALSE | AC15: a1daffbc393702947b8e63307f588d5d | AD15: =IF($AC15="","NEW","Live")
A16: Executioner's Blow | B16: 1 | C16: NotOffered | D16: Damage 4 | G16: Deal 4 damage. | H16: Chebyshev | I16: 1 | J16: 1 | K16: ExecutionersBlow | L16: Any | M16: EvilKing | N16: Attack | O16: Tile | P16: Single | Z16: FALSE | AA16: FALSE | AC16: 8997d569af1bef44aa831ed6fe2aa939 | AD16: =IF($AC16="","NEW","Live")
A17: Royal Guard | B17: 1 | C17: NotOffered | D17: Damage 3 | G17: Deal 3 damage within 1 tile. | H17: Chebyshev | I17: 1 | J17: 1 | K17: RoyalGuard | L17: Any | M17: EvilKing | N17: Attack | O17: Tile | P17: Chebyshev 0-1 | Z17: FALSE | AA17: FALSE | AC17: c330fc715539b424d876b3642e7c9919 | AD17: =IF($AC17="","NEW","Live")
A18: Rally | B18: 0 | C18: NotOffered | D18: SummonHeavyBanditMinion | G18: Summon a line of Heavy Bandits. | H18: Chebyshev | I18: 1 | J18: 3 | K18: Rally | L18: Any | M18: EvilKnight | N18: Summon | O18: Tile | P18: Pattern:Wall3 | Y18: Cooldown 4, Interruptible 2 | Z18: FALSE | AA18: FALSE | AC18: 43b25c70bde2b7645abfca6e8feac7d4 | AD18: =IF($AC18="","NEW","Live")
A19: Riposte | B19: 1 | C19: NotOffered | D19: Damage 6 | E19: Parry 1 | G19: Deal 6 damage. Gain 1 Parry. | H19: Chebyshev | I19: 1 | J19: 1 | K19: Riposte | L19: Any | M19: EvilKnight | N19: Attack | O19: Tile | P19: Single | R19: Self | S19: Single | Z19: FALSE | AA19: FALSE | AC19: aefe57b35c9afe64ba4eb9112efd9883 | AD19: =IF($AC19="","NEW","Live")
A20: Shield Bash | B20: 1 | C20: NotOffered | D20: Damage 4 | E20: Shield 10 | F20: Block 2 | G20: Deal 4 damage. Gain 10 Shield and 2 Block. | H20: Chebyshev | I20: 1 | J20: 1 | K20: ShieldBash | L20: Any | M20: EvilKnight | N20: Attack | O20: Tile | P20: Single | R20: Self | S20: Single | U20: Self | V20: Single | Z20: FALSE | AA20: FALSE | AC20: 51f29b7e912127f43ad357fd5f12663c | AD20: =IF($AC20="","NEW","Live")
A21: Summon Imp | B21: 0 | C21: NotOffered | D21: SummonGoblinMinion | G21: Summon a Goblin. | H21: Chebyshev | I21: 1 | J21: 3 | K21: SummonImp | L21: Any | M21: EvilWizard | N21: Summon | O21: Tile | P21: Single | Y21: Cooldown 3 | Z21: FALSE | AA21: FALSE | AC21: a88d8789fe23d7b4a8803cfab0721cc0 | AD21: =IF($AC21="","NEW","Live")
A22: Dark Bolt | B22: 1 | C22: NotOffered | D22: Damage 5 | G22: Deal 5 damage to everything within 1 tile. | H22: Chebyshev | I22: 2 | J22: 5 | K22: DarkBolt | L22: Any | M22: EvilWizard | N22: Attack | O22: Tile | P22: Chebyshev 0-1 | Z22: FALSE | AA22: FALSE | AB22: Fireball | AC22: d7683e27219ae7a49bbe364a274bfc22 | AD22: =IF($AC22="","NEW","Live")
A23: Shadow Ward | B23: 1 | C23: NotOffered | D23: Damage 3 | E23: Shield 7 | G23: Deal 3 damage. Gain 7 Shield. | H23: Chebyshev | I23: 1 | J23: 4 | K23: ShadowWard | L23: Any | M23: EvilWizard | N23: Attack | O23: Tile | P23: Single | R23: Self | S23: Single | Z23: FALSE | AA23: FALSE | AB23: Status | AC23: 6f6aee052e565334184d68675bbc9306 | AD23: =IF($AC23="","NEW","Live")
A24: Call the Swarm | B24: 0 | C24: NotOffered | D24: SummonBatMinion | G24: Summon a Bat. | H24: Chebyshev | I24: 1 | J24: 3 | K24: CallTheSwarm | L24: Any | M24: EvilWizard2 | N24: Summon | O24: Tile | P24: Single | Y24: Cooldown 2 | Z24: FALSE | AA24: FALSE | AC24: ece43c6ee0d65dd40b59ed491b201779 | AD24: =IF($AC24="","NEW","Live")
A25: Arcane Lance | B25: 1 | C25: NotOffered | D25: Damage 6 | G25: Deal 6 damage. | H25: Chebyshev | I25: 2 | J25: 5 | K25: ArcaneLance | L25: Any | M25: EvilWizard2 | N25: Attack | O25: Tile | P25: Single | Z25: FALSE | AA25: FALSE | AB25: Status | AC25: c31b41c07840eef46872d698ddd854e5 | AD25: =IF($AC25="","NEW","Live")
A26: Void Barrier | B26: 1 | C26: NotOffered | D26: Damage 3 | E26: Weaken | F26: Vulnerable | G26: Deal 3 damage. Apply Weaken and Vulnerable. | H26: Chebyshev | I26: 1 | J26: 4 | K26: VoidBarrier | L26: Any | M26: EvilWizard2 | N26: Attack | O26: Tile | P26: Single | R26: Tile | S26: Single | U26: Tile | V26: Single | Y26: Interruptible 2 | Z26: FALSE | AA26: FALSE | AB26: Status | AC26: 9b758a484d41478459502850e55de625 | AD26: =IF($AC26="","NEW","Live")
A27: Conjure Ooze | B27: 0 | C27: NotOffered | D27: SummonSlimeMinion | G27: Summon a Slime. | H27: Chebyshev | I27: 1 | J27: 3 | K27: ConjureOoze | L27: Any | M27: EvilWizard3 | N27: Summon | O27: Tile | P27: Single | Y27: Cooldown 3 | Z27: FALSE | AA27: FALSE | AC27: 46914671440488144a08d7e55f93496e | AD27: =IF($AC27="","NEW","Live")
