Workbook
Name pw_Damage: 'PowerLevel'!$B$2
Name pw_Poison: 'PowerLevel'!$B$3
Name pw_Shield: 'PowerLevel'!$B$4
Name pw_Block: 'PowerLevel'!$B$5
Name pw_Teleport: 'PowerLevel'!$B$6
Name pw_Move: 'PowerLevel'!$B$7
Name pw_Health: 'PowerLevel'!$B$8
Name pw_Divisor: 'PowerLevel'!$B$9
Name pw_Heal: 'PowerLevel'!$B$10
Name pw_Strength: 'PowerLevel'!$B$11
Name pw_DoubleNextAttack: 'PowerLevel'!$B$12
Name pw_PoisonBlade: 'PowerLevel'!$B$13
Name pw_Parry: 'PowerLevel'!$B$14
Name pw_Dodge: 'PowerLevel'!$B$15
Name pw_DoubleShield: 'PowerLevel'!$B$16
Name pw_Frozen: 'PowerLevel'!$B$17
Name pw_Rooted: 'PowerLevel'!$B$18
Name pw_Weaken: 'PowerLevel'!$B$19
Name pw_Vulnerable: 'PowerLevel'!$B$20
Name pw_Taunt: 'PowerLevel'!$B$21
Name pw_Stealth: 'PowerLevel'!$B$22
Name pw_Summon: 'PowerLevel'!$B$23
Name pw_SummonHorizon: 'PowerLevel'!$B$24
Name pw_TotemActivations: 'PowerLevel'!$B$25
Name pw_Area: 'PowerLevel'!$B$26
Name pw_Horizon: 'PowerLevel'!$B$27
Name pw_Draw: 'PowerLevel'!$B$28
Name pw_Energy: 'PowerLevel'!$B$29
Name pw_TileEffect: 'PowerLevel'!$B$30
Name pw_SelfDamage: 'PowerLevel'!$B$31
Name pw_ActionScale: 'PowerLevel'!$B$32
Name pw_Tolerance: 'PowerLevel'!$B$33
Name range_Power: 'PowerLevel'!$A$38:$B$43
Name list_Brain: 'Enums'!$A$2:$A$5
Name list_Targeting: 'Enums'!$B$2:$B$18
Name list_Loot: 'Enums'!$C$2:$C$14
Name list_Role: 'Enums'!$D$2:$D$5
Name list_Bool: 'Enums'!$E$2:$E$3
Name list_EnemyCard: 'Enums'!$F$2:$F$55
Name pow_SkeletonAlly: 'SkeletonAlly'!$B$16
Name pow_Bat: 'Bat'!$B$16
Name pow_Crab: 'Crab'!$B$16
Name pow_EnemyRanger: 'EnemyRanger'!$B$16
Name pow_FlyingEye: 'FlyingEye'!$B$16
Name pow_Goblin: 'Goblin'!$B$16
Name pow_Golem: 'Golem'!$B$16
Name pow_HeavyBandit: 'HeavyBandit'!$B$16
Name pow_LightBandit: 'LightBandit'!$B$16
Name pow_Mimic: 'Mimic'!$B$16
Name pow_Mushroom: 'Mushroom'!$B$16
Name pow_Pebble: 'Pebble'!$B$16
Name pow_PlagueRat: 'PlagueRat'!$B$16
Name pow_Rat: 'Rat'!$B$16
Name pow_Skeleton: 'Skeleton'!$B$16
Name pow_SkeletonWarrior: 'SkeletonWarrior'!$B$16
Name pow_Skull: 'Skull'!$B$16
Name pow_Slime: 'Slime'!$B$16
Name pow_SpikedSlime: 'SpikedSlime'!$B$16
Name pow_VampireBat: 'VampireBat'!$B$16
Name pow_BrittleSkeleton: 'BrittleSkeleton'!$B$16

Sheet README
A1: Enemy Design Workbook
A3: One tab per enemy, ally and totem, all built from the actual prefabs and cards under Assets/Prefabs and Assets/Data/CardData/Enemy - this workbook only READS them today. Bosses live in Docs/BossDesign.xlsx instead.
A5: The tabs
A6: PowerLevel | B6: The tuning surface. Every pw_* weight here is a named cell - change one and every body tab and Roster recalculate immediately, no re-export needed.
A7: One tab per body | B7: Health, Actions Per Turn, Brain, Targeting, Loot Table, Role and Deck mirror the prefab's Character component. Card Facts below the deck strip are read from each card's own CardData/CardEffect assets - edit a card's numbers on Docs/CardDesign.xlsx, not here.
A8: One tab per totem | B8: A totem has no health or deck - Totem Power is its auras and reactions, weighted the same way a body's Card Power is.
A9: Roster | B9: Every body side by side, sorted by name - the bulk-edit grid. Display Name, Health, Actions Per Turn, Brain, Targeting, Loot Table, Role and Brandon's Power Level are plain values here, synced to the matching body tab exactly like the Inspector - edit either one. Renaming a body is done by typing its new name in the Name column. Boss, Deck Size and the averages stay read-only; Estimated/Effective Power/Delta/Flag recalculate from this row's own Health/Actions/Brandon's as you type, so they never go stale while you're still editing.
A10: Enums | B10: Dropdown sources for Brain, Targeting, Loot Table and Deck cells.
A12: Reading a body tab
A13: Brandon's Power Level | B13: Hand-authored ground truth - type in what a body feels like it should be worth. Preserved across re-exports.
A14: Estimated Power Level | B14: (Average Card Power * Actions Per Turn * pw_ActionScale + Health * pw_Health) / pw_Divisor. Tune the PowerLevel weights until Delta sits near zero for the bodies you already trust, then trust the estimate for the rest.
A15: Role | B15: Which spawn row(s) this body is eligible for - None (unconstrained), Frontline, Backline or Both. Synced to Character.battleRole; drives BattleManager.SpawnParty and EncounterRoller placement.
A16: Counted | B16: No for a Move-only card or a Cooldown card - excluded from every average. Cooldown cards get scored separately later.
A17: Summon Power | B17: A live reference to the summoned body's (or totem's) own power cell, scaled down if its lifetime is shorter than pw_SummonHorizon.
A19: Syncing back to Unity
A20: One button | B20: In Unity: Tools > Sync Enemies With Sheet. Applies your edits - typed on a body tab OR the Roster tab, whichever you used - to the matching prefab: Display Name, Health, Actions Per Turn, Brain, Targeting, Loot Table, Role, Brandon''s Power Level and Deck. Renaming a body''s Name on the Roster tab renames the prefab too, keeping its GUID (so decks and levels still point at it). Then refreshes this workbook so anything changed in the Inspector shows up here.
A21: Deck | B21: One card name per column, left to right, no gaps - the first blank cell ends the deck. Duplicates are fine and expected (four Enemy Slash cards is four cells). Pick names from the dropdown so a typo cannot silently drop a card. Only editable on the body tab - the Roster tab does not carry a Deck column.
A22: Notes | B22: Never syncs anywhere - authored HERE, body tab only, and preserved across every re-export.
A23: Brandon's Power Level | B23: Syncs between the body tab and the Roster tab - whichever one you typed in wins - but never reaches a prefab field directly. It only feeds Effective Power, which is what gets written to Character.powerLevel.
A24: Card Facts, Card Power, averages | B24: Never hand-edit - fully derived from the prefab and its cards, rebuilt on every export. On the Roster tab this is Avg Damage/Status/Summon/Card Power, Deck Size and Boss.
A25: Effective Power and Boss | B25: Not sheet columns you edit directly - Effective Power (Brandon's if set, else Estimated) and Boss (which folder the prefab lives in) are written to Character.powerLevel/isBoss one-way, every sync, regardless of whether anything else on the tab changed. A body with neither Brandon's nor a usable Estimated result is skipped with a warning and can never be drawn by EncounterRoller.
A26: If both sides changed | B26: That body is left alone on BOTH sides and named in the Unity console, the same conflict rule Docs/CardDesign.xlsx follows. Make them agree, or change only one, then sync again.
A27: If the body tab and Roster disagree | B27: Same idea, one layer earlier: whichever of the two changed since the last sync wins, but if BOTH changed - differently - since then, that body is left alone everywhere and named in the console. Make the two tabs agree, or change only one, then sync again.
A28: Regenerating without syncing | B28: Tools > Enemies > Refresh Sheet From Unity discards any sheet edit that has not been synced yet - only for when the sheet is known to be wrong.
A29: The other roster workbook | B29: Enemies, the ally and bosses are two separate workbooks driven by the same engine - Docs/EnemySheets.xlsx and Docs/BossDesign.xlsx - each with its own baseline and its own sync button. A prefab belongs to exactly one of them, decided by which folder it sits in under Assets/Prefabs.

Sheet PowerLevel
A1: Term | B1: Value | C1: What this counts
A2: pw_Damage | B2: 1.5 | C2: The numeraire. One point of damage to a hero = 1 power.
A3: pw_Poison | B3: 0.9 | C3: Per point of lifetime damage-over-time (the triangular total of the stacks applied, not the stack count itself).
A4: pw_Shield | B4: 0.5 | C4: Per point. ShieldStatus is wiped at OnTurnStart, so it only ever blocks one round.
A5: pw_Block | B5: 0.5 | C5: Per point actually prevented (BlockStatus.AmountPerHit is a const 5, so a charge is worth 5 of these).
A6: pw_Teleport | B6: 4 | C6: Reserved for a future teleport/swap effect - no enemy card uses this yet.
A7: pw_Move | B7: 1 | C7: Per tile of forced repositioning (Move / Swap). "Move 2" is one Move card whose range reaches 2 tiles.
A8: pw_Health | B8: 0.5 | C8: Per point of max health.
A9: pw_Divisor | B9: 17 | C9: Everything above is summed and divided by this to land in the same range as Brandon's hand-authored numbers.
A10: pw_Heal | B10: 0.8 | C10: Only useful once already damaged, so worth less than the same number as damage.
A11: pw_Strength | B11: 0.9 | C11: Per stack per future attack this enemy is assumed to still make (see pw_Horizon).
A12: pw_DoubleNextAttack | B12: 3 | C12: Per stack. Roughly one extra average hit.
A13: pw_PoisonBlade | B13: 1 | C13: Per stack - the weapon-poison variant, scored the same as Poison stacks.
... A33: pw_Tolerance | B33: 0.25 | C33: How far Estimated Power Level may sit from Brandon's before the Roster tab flags it OVER/UNDER.
A35: Edit the Value column - every body tab and the Roster tab recalculate. Nothing here is baked into the export script.
A36: Range Power
A37: Range | B37: Power
A38: 1 | B38: 0
A39: 2 | B39: 1.5
A40: 3 | B40: 5
A41: 4 | B41: 6
A42: 5 | B42: 7
A43: 6 | B43: 8
A44: Looked up by nearest Range at or below a card's own Range Max - add a row for a new value; anything past the last row scores the same as it.

Sheet Roster
A1: Name | B1: GUID | C1: Boss | D1: Display Name | E1: Health | F1: Actions | G1: Brain | H1: Targeting | I1: Loot Table | J1: Role | K1: Deck Size | L1: Avg Damage | M1: Avg Status | N1: Avg Summon | O1: Avg Card Power | P1: Estimated | Q1: Brandon's | R1: Effective Power | S1: Delta | T1: Flag
A2: Bat | B2: 51cc0c0b40e7b264ebdf1dc4594559a6 | C2: No | D2: Bat | E2: 20 | F2: 1 | G2: Warrior | H2: TotemClosest | I2: EarlyGame | J2: Frontline | K2: 5 | L2: ='Bat'!B20 | M2: ='Bat'!B21 | N2: ='Bat'!B22 | O2: ='Bat'!B19 | P2: =IF(E2="","",ROUND((O2*F2*pw_ActionScale+E2*pw_Health)/pw_Divisor,3)) | Q2: 1.47 | R2: =IF(Q2="",P2,Q2) | S2: =IF(Q2="","",ROUND(P2-Q2,3)) | T2: =IF(S2="","",IF(ABS(S2)<=P2*pw_Tolerance,"OK",IF(S2>0,"OVER","UNDER")))
A3: BrittleSkeleton | B3: 4cb5e72728f8d3143a2397b50dff133f | C3: No | D3: Brittle Skeleton | E3: 1 | F3: 1 | G3: Warrior | H3: Closest | I3: EarlyGame | J3: Frontline | K3: 5 | L3: ='BrittleSkeleton'!B20 | M3: ='BrittleSkeleton'!B21 | N3: ='BrittleSkeleton'!B22 | O3: ='BrittleSkeleton'!B19 | P3: =IF(E3="","",ROUND((O3*F3*pw_ActionScale+E3*pw_Health)/pw_Divisor,3)) | R3: =IF(Q3="",P3,Q3) | S3: =IF(Q3="","",ROUND(P3-Q3,3)) | T3: =IF(S3="","",IF(ABS(S3)<=P3*pw_Tolerance,"OK",IF(S3>0,"OVER","UNDER")))
A4: Crab | B4: f80d9dc6173669245bd4782952cd1667 | C4: No | D4: Crab | E4: 40 | F4: 1 | G4: Warrior | H4: Closest | I4: EarlyGame | J4: Frontline | K4: 5 | L4: ='Crab'!B20 | M4: ='Crab'!B21 | N4: ='Crab'!B22 | O4: ='Crab'!B19 | P4: =IF(E4="","",ROUND((O4*F4*pw_ActionScale+E4*pw_Health)/pw_Divisor,3)) | Q4: 2 | R4: =IF(Q4="",P4,Q4) | S4: =IF(Q4="","",ROUND(P4-Q4,3)) | T4: =IF(S4="","",IF(ABS(S4)<=P4*pw_Tolerance,"OK",IF(S4>0,"OVER","UNDER")))
A5: EnemyRanger | B5: e40f592bea6dbd64693626dad514798b | C5: No | D5: Ranger | E5: 25 | F5: 1 | G5: Ranger | H5: Totem15Closest | I5: EarlyGame | J5: Backline | K5: 5 | L5: ='EnemyRanger'!B20 | M5: ='EnemyRanger'!B21 | N5: ='EnemyRanger'!B22 | O5: ='EnemyRanger'!B19 | P5: =IF(E5="","",ROUND((O5*F5*pw_ActionScale+E5*pw_Health)/pw_Divisor,3)) | Q5: 3.5 | R5: =IF(Q5="",P5,Q5) | S5: =IF(Q5="","",ROUND(P5-Q5,3)) | T5: =IF(S5="","",IF(ABS(S5)<=P5*pw_Tolerance,"OK",IF(S5>0,"OVER","UNDER")))
A6: FlyingEye | B6: 158567c6103052b45a79feac134a4c3b | C6: No | D6: Flying Eye | E6: 15 | F6: 1 | G6: Ranger | H6: Totem15Closest | I6: EarlyGame | J6: Backline | K6: 5 | L6: ='FlyingEye'!B20 | M6: ='FlyingEye'!B21 | N6: ='FlyingEye'!B22 | O6: ='FlyingEye'!B19 | P6: =IF(E6="","",ROUND((O6*F6*pw_ActionScale+E6*pw_Health)/pw_Divisor,3)) | Q6: 1.68 | R6: =IF(Q6="",P6,Q6) | S6: =IF(Q6="","",ROUND(P6-Q6,3)) | T6: =IF(S6="","",IF(ABS(S6)<=P6*pw_Tolerance,"OK",IF(S6>0,"OVER","UNDER")))
A7: Goblin | B7: fe7fe8169a3ae3f4ab1463af48263a1a | C7: No | D7: Goblin | E7: 20 | F7: 1 | G7: Warrior | H7: Weakest | I7: EarlyGame | J7: Frontline | K7: 5 | L7: ='Goblin'!B20 | M7: ='Goblin'!B21 | N7: ='Goblin'!B22 | O7: ='Goblin'!B19 | P7: =IF(E7="","",ROUND((O7*F7*pw_ActionScale+E7*pw_Health)/pw_Divisor,3)) | Q7: 1.5 | R7: =IF(Q7="",P7,Q7) | S7: =IF(Q7="","",ROUND(P7-Q7,3)) | T7: =IF(S7="","",IF(ABS(S7)<=P7*pw_Tolerance,"OK",IF(S7>0,"OVER","UNDER")))
A8: Golem | B8: 5bdb828176c88144986e3b367ffda1b4 | C8: No | D8: Golem | E8: 60 | F8: 1 | G8: Summoner | H8: Closest | I8: EarlyGame | J8: Frontline | K8: 5 | L8: ='Golem'!B20 | M8: ='Golem'!B21 | N8: ='Golem'!B22 | O8: ='Golem'!B19 | P8: =IF(E8="","",ROUND((O8*F8*pw_ActionScale+E8*pw_Health)/pw_Divisor,3)) | Q8: 2.65 | R8: =IF(Q8="",P8,Q8) | S8: =IF(Q8="","",ROUND(P8-Q8,3)) | T8: =IF(S8="","",IF(ABS(S8)<=P8*pw_Tolerance,"OK",IF(S8>0,"OVER","UNDER")))
A9: HeavyBandit | B9: abb6f217c283d344999e3f27fa36640f | C9: No | D9: Heavy Bandit | E9: 50 | F9: 1 | G9: Warrior | H9: Strongest | I9: EarlyGame | J9: Frontline | K9: 5 | L9: ='HeavyBandit'!B20 | M9: ='HeavyBandit'!B21 | N9: ='HeavyBandit'!B22 | O9: ='HeavyBandit'!B19 | P9: =IF(E9="","",ROUND((O9*F9*pw_ActionScale+E9*pw_Health)/pw_Divisor,3)) | Q9: 3.5 | R9: =IF(Q9="",P9,Q9) | S9: =IF(Q9="","",ROUND(P9-Q9,3)) | T9: =IF(S9="","",IF(ABS(S9)<=P9*pw_Tolerance,"OK",IF(S9>0,"OVER","UNDER")))
A10: LightBandit | B10: df52b2ab92f38fd4eb6d6064e8197a56 | C10: No | D10: Light Bandit | E10: 30 | F10: 1 | G10: Warrior | H10: Weakest | I10: EarlyGame | J10: Backline | K10: 5 | L10: ='LightBandit'!B20 | M10: ='LightBandit'!B21 | N10: ='LightBandit'!B22 | O10: ='LightBandit'!B19 | P10: =IF(E10="","",ROUND((O10*F10*pw_ActionScale+E10*pw_Health)/pw_Divisor,3)) | Q10: 2.5 | R10: =IF(Q10="",P10,Q10) | S10: =IF(Q10="","",ROUND(P10-Q10,3)) | T10: =IF(S10="","",IF(ABS(S10)<=P10*pw_Tolerance,"OK",IF(S10>0,"OVER","UNDER")))
A11: Mimic | B11: 022c86b9aa20aaf44806e866dd6d8971 | C11: No | D11: Mimic | E11: 35 | F11: 1 | G11: Warrior | H11: ClosestIgnoreTotem | I11: EarlyGame | J11: Frontline | K11: 5 | L11: ='Mimic'!B20 | M11: ='Mimic'!B21 | N11: ='Mimic'!B22 | O11: ='Mimic'!B19 | P11: =IF(E11="","",ROUND((O11*F11*pw_ActionScale+E11*pw_Health)/pw_Divisor,3)) | Q11: 2.5 | R11: =IF(Q11="",P11,Q11) | S11: =IF(Q11="","",ROUND(P11-Q11,3)) | T11: =IF(S11="","",IF(ABS(S11)<=P11*pw_Tolerance,"OK",IF(S11>0,"OVER","UNDER")))
A12: Mushroom | B12: f04aa7787f30bab4a96433807a0f06a5 | C12: No | D12: Mushroom | E12: 30 | F12: 1 | G12: Ranger | H12: Closest | I12: EarlyGame | J12: Frontline | K12: 5 | L12: ='Mushroom'!B20 | M12: ='Mushroom'!B21 | N12: ='Mushroom'!B22 | O12: ='Mushroom'!B19 | P12: =IF(E12="","",ROUND((O12*F12*pw_ActionScale+E12*pw_Health)/pw_Divisor,3)) | Q12: 2 | R12: =IF(Q12="",P12,Q12) | S12: =IF(Q12="","",ROUND(P12-Q12,3)) | T12: =IF(S12="","",IF(ABS(S12)<=P12*pw_Tolerance,"OK",IF(S12>0,"OVER","UNDER")))
A13: Pebble | B13: cffb630e9ce4c0f4798ae3e294d1d8e8 | C13: No | D13: Pebble | E13: 5 | F13: 1 | G13: Warrior | H13: TotemClosest | J13: None | K13: 5 | L13: ='Pebble'!B20 | M13: ='Pebble'!B21 | N13: ='Pebble'!B22 | O13: ='Pebble'!B19 | P13: =IF(E13="","",ROUND((O13*F13*pw_ActionScale+E13*pw_Health)/pw_Divisor,3)) | Q13: 0.5 | R13: =IF(Q13="",P13,Q13) | S13: =IF(Q13="","",ROUND(P13-Q13,3)) | T13: =IF(S13="","",IF(ABS(S13)<=P13*pw_Tolerance,"OK",IF(S13>0,"OVER","UNDER")))
A14: PlagueRat | B14: 37960ead296e23e4ca189530884917c3 | C14: No | D14: Plague Rat | E14: 30 | F14: 1 | G14: Warrior | H14: Closest | I14: EarlyGame | J14: Frontline | K14: 5 | L14: ='PlagueRat'!B20 | M14: ='PlagueRat'!B21 | N14: ='PlagueRat'!B22 | O14: ='PlagueRat'!B19 | P14: =IF(E14="","",ROUND((O14*F14*pw_ActionScale+E14*pw_Health)/pw_Divisor,3)) | Q14: 2 | R14: =IF(Q14="",P14,Q14) | S14: =IF(Q14="","",ROUND(P14-Q14,3)) | T14: =IF(S14="","",IF(ABS(S14)<=P14*pw_Tolerance,"OK",IF(S14>0,"OVER","UNDER")))
A15: Rat | B15: b9a57d66ac78e19468a62c235ce3e746 | C15: No | D15: Rat | E15: 25 | F15: 1 | G15: Warrior | H15: Weakest | I15: EarlyGame | J15: Frontline | K15: 5 | L15: ='Rat'!B20 | M15: ='Rat'!B21 | N15: ='Rat'!B22 | O15: ='Rat'!B19 | P15: =IF(E15="","",ROUND((O15*F15*pw_ActionScale+E15*pw_Health)/pw_Divisor,3)) | Q15: 1.5 | R15: =IF(Q15="",P15,Q15) | S15: =IF(Q15="","",ROUND(P15-Q15,3)) | T15: =IF(S15="","",IF(ABS(S15)<=P15*pw_Tolerance,"OK",IF(S15>0,"OVER","UNDER")))
A16: Skeleton | B16: 909b3cba860296d47997ee7846ec93f8 | C16: No | D16: Skeleton | E16: 30 | F16: 1 | G16: Warrior | H16: Closest | I16: EarlyGame | J16: Frontline | K16: 5 | L16: ='Skeleton'!B20 | M16: ='Skeleton'!B21 | N16: ='Skeleton'!B22 | O16: ='Skeleton'!B19 | P16: =IF(E16="","",ROUND((O16*F16*pw_ActionScale+E16*pw_Health)/pw_Divisor,3)) | Q16: 1.5 | R16: =IF(Q16="",P16,Q16) | S16: =IF(Q16="","",ROUND(P16-Q16,3)) | T16: =IF(S16="","",IF(ABS(S16)<=P16*pw_Tolerance,"OK",IF(S16>0,"OVER","UNDER")))
A17: SkeletonAlly | B17: eaade4b777fd45447af03588cf3692e5 | C17: No | D17: Skeleton | E17: 15 | F17: 1 | G17: Warrior | J17: None | K17: 4 | L17: ='SkeletonAlly'!B20 | M17: ='SkeletonAlly'!B21 | N17: ='SkeletonAlly'!B22 | O17: ='SkeletonAlly'!B19 | P17: =IF(E17="","",ROUND((O17*F17*pw_ActionScale+E17*pw_Health)/pw_Divisor,3)) | Q17: 2 | R17: =IF(Q17="",P17,Q17) | S17: =IF(Q17="","",ROUND(P17-Q17,3)) | T17: =IF(S17="","",IF(ABS(S17)<=P17*pw_Tolerance,"OK",IF(S17>0,"OVER","UNDER")))
A18: SkeletonWarrior | B18: d1b7793de9d268945bdf70cf0af39a94 | C18: No | D18: Skeleton Warrior | E18: 40 | F18: 1 | G18: Warrior | H18: Closest | I18: EarlyGame | J18: Frontline | K18: 5 | L18: ='SkeletonWarrior'!B20 | M18: ='SkeletonWarrior'!B21 | N18: ='SkeletonWarrior'!B22 | O18: ='SkeletonWarrior'!B19 | P18: =IF(E18="","",ROUND((O18*F18*pw_ActionScale+E18*pw_Health)/pw_Divisor,3)) | Q18: 3 | R18: =IF(Q18="",P18,Q18) | S18: =IF(Q18="","",ROUND(P18-Q18,3)) | T18: =IF(S18="","",IF(ABS(S18)<=P18*pw_Tolerance,"OK",IF(S18>0,"OVER","UNDER")))
A19: Skull | B19: 40cab8c86b3615741ac4bc8db8156b37 | C19: No | D19: Skull | E19: 15 | F19: 1 | G19: Ranger | H19: Totem30Closest | I19: EarlyGame | J19: Backline | K19: 5 | L19: ='Skull'!B20 | M19: ='Skull'!B21 | N19: ='Skull'!B22 | O19: ='Skull'!B19 | P19: =IF(E19="","",ROUND((O19*F19*pw_ActionScale+E19*pw_Health)/pw_Divisor,3)) | Q19: 1.88 | R19: =IF(Q19="",P19,Q19) | S19: =IF(Q19="","",ROUND(P19-Q19,3)) | T19: =IF(S19="","",IF(ABS(S19)<=P19*pw_Tolerance,"OK",IF(S19>0,"OVER","UNDER")))
A20: Slime | B20: 7902e6bd6fe8b444eab36cf00a8771be | C20: No | D20: Slime | E20: 20 | F20: 1 | G20: Warrior | H20: Closest | I20: EarlyGame | J20: Frontline | K20: 5 | L20: ='Slime'!B20 | M20: ='Slime'!B21 | N20: ='Slime'!B22 | O20: ='Slime'!B19 | P20: =IF(E20="","",ROUND((O20*F20*pw_ActionScale+E20*pw_Health)/pw_Divisor,3)) | Q20: 1.5 | R20: =IF(Q20="",P20,Q20) | S20: =IF(Q20="","",ROUND(P20-Q20,3)) | T20: =IF(S20="","",IF(ABS(S20)<=P20*pw_Tolerance,"OK",IF(S20>0,"OVER","UNDER")))
A21: SpikedSlime | B21: a759c0567adbde54f8e686c473b037cd | C21: No | D21: Spiked Slime | E21: 25 | F21: 1 | G21: Warrior | H21: Closest | I21: EarlyGame | J21: Frontline | K21: 5 | L21: ='SpikedSlime'!B20 | M21: ='SpikedSlime'!B21 | N21: ='SpikedSlime'!B22 | O21: ='SpikedSlime'!B19 | P21: =IF(E21="","",ROUND((O21*F21*pw_ActionScale+E21*pw_Health)/pw_Divisor,3)) | Q21: 2 | R21: =IF(Q21="",P21,Q21) | S21: =IF(Q21="","",ROUND(P21-Q21,3)) | T21: =IF(S21="","",IF(ABS(S21)<=P21*pw_Tolerance,"OK",IF(S21>0,"OVER","UNDER")))
A22: VampireBat | B22: e2566430033deb14c9d648e67fdf80e4 | C22: No | D22: Vampire Bat | E22: 20 | F22: 1 | G22: Warrior | H22: TotemClosest | I22: EarlyGame | J22: Backline | K22: 5 | L22: ='VampireBat'!B20 | M22: ='VampireBat'!B21 | N22: ='VampireBat'!B22 | O22: ='VampireBat'!B19 | P22: =IF(E22="","",ROUND((O22*F22*pw_ActionScale+E22*pw_Health)/pw_Divisor,3)) | Q22: 1.5 | R22: =IF(Q22="",P22,Q22) | S22: =IF(Q22="","",ROUND(P22-Q22,3)) | T22: =IF(S22="","",IF(ABS(S22)<=P22*pw_Tolerance,"OK",IF(S22>0,"OVER","UNDER")))

Sheet Bat
A1: Enemy Name | B1: Bat
A2: Boss | B2: No
A3: GUID | B3: 51cc0c0b40e7b264ebdf1dc4594559a6
A4: Sync | B4: =IF($B$3="","NEW","Live")
A6: Stats (synced to Unity)
A7: Display Name | B7: Bat
A8: Health | B8: 20
A9: Actions Per Turn | B9: 1
A10: Brain | B10: Warrior
A11: Targeting | B11: TotemClosest
A12: Loot Table | B12: EarlyGame
A13: Role | B13: Frontline
A15: Brandon's Power Level | B15: 1.47
A16: Estimated Power Level | B16: =IF($B$8="","",ROUND(($B$19*$B$9*pw_ActionScale+$B$8*pw_Health)/pw_Divisor,3))
A17: Delta (Estimated - Brandon's) | B17: =IF($B$15="","",ROUND($B$16-$B$15,3))
A19: Average Card Power | B19: =IFERROR(AVERAGEIF(B$26:F$26,"Yes",B$54:F$54),0)
A20: Average Damage | B20: =IFERROR(AVERAGEIF(B$26:F$26,"Yes",B$32:F$32),0)
A21: Average Status Power | B21: =IFERROR(AVERAGEIF(B$26:F$26,"Yes",B$55:F$55),0)
A22: Average Summon Power | B22: =IFERROR(AVERAGEIF(B$26:F$26,"Yes",B$52:F$52),0)
A24: Deck | B24: Bite | C24: Bite | D24: Bite | E24: Bite | F24: MoveInnate2
A25: Actions from Card | B25: 5 damage | C25: 5 damage | D25: 5 damage | E25: 5 damage | F25: Move 2
A26: Counted | B26: Yes | C26: Yes | D26: Yes | E26: Yes | F26: No
A28: Card Facts
A29: Cost | B29: 1 | C29: 1 | D29: 1 | E29: 1 | F29: 1
A30: Range Max | B30: 1 | C30: 1 | D30: 1 | E30: 1 | F30: 2
A31: Tiles Hit | B31: 1 | C31: 1 | D31: 1 | E31: 1 | F31: 1
A32: Damage | B32: 5 | C32: 5 | D32: 5 | E32: 5 | F32: 0
A33: Range | B33: =IFERROR(VLOOKUP(B$30,range_Power,2,TRUE),0) | C33: =IFERROR(VLOOKUP(C$30,range_Power,2,TRUE),0) | D33: =IFERROR(VLOOKUP(D$30,range_Power,2,TRUE),0) | E33: =IFERROR(VLOOKUP(E$30,range_Power,2,TRUE),0) | F33: =IFERROR(VLOOKUP(F$30,range_Power,2,TRUE),0)
A34: Poison Total | B34: 0 | C34: 0 | D34: 0 | E34: 0 | F34: 0
A35: Heal | B35: 0 | C35: 0 | D35: 0 | E35: 0 | F35: 0
A36: Shield | B36: 0 | C36: 0 | D36: 0 | E36: 0 | F36: 0
A37: Block Total | B37: 0 | C37: 0 | D37: 0 | E37: 0 | F37: 0
A38: Parry | B38: 0 | C38: 0 | D38: 0 | E38: 0 | F38: 0
A39: Dodge | B39: 0 | C39: 0 | D39: 0 | E39: 0 | F39: 0
A40: Strength | B40: 0 | C40: 0 | D40: 0 | E40: 0 | F40: 0
A41: Weaken | B41: 0 | C41: 0 | D41: 0 | E41: 0 | F41: 0
A42: Vulnerable | B42: 0 | C42: 0 | D42: 0 | E42: 0 | F42: 0
A43: Frozen | B43: 0 | C43: 0 | D43: 0 | E43: 0 | F43: 0
A44: Rooted | B44: 0 | C44: 0 | D44: 0 | E44: 0 | F44: 0
A45: Taunt | B45: 0 | C45: 0 | D45: 0 | E45: 0 | F45: 0
...

Sheet BrittleSkeleton
A1: Enemy Name | B1: BrittleSkeleton
A2: Boss | B2: No
A3: GUID | B3: 4cb5e72728f8d3143a2397b50dff133f
A4: Sync | B4: =IF($B$3="","NEW","Live")
A6: Stats (synced to Unity)
A7: Display Name | B7: Brittle Skeleton
A8: Health | B8: 1
A9: Actions Per Turn | B9: 1
A10: Brain | B10: Warrior
A11: Targeting | B11: Closest
A12: Loot Table | B12: EarlyGame
A13: Role | B13: Frontline
A15: Brandon's Power Level
A16: Estimated Power Level | B16: =IF($B$8="","",ROUND(($B$19*$B$9*pw_ActionScale+$B$8*pw_Health)/pw_Divisor,3))
A17: Delta (Estimated - Brandon's) | B17: =IF($B$15="","",ROUND($B$16-$B$15,3))
A19: Average Card Power | B19: =IFERROR(AVERAGEIF(B$26:F$26,"Yes",B$54:F$54),0)
A20: Average Damage | B20: =IFERROR(AVERAGEIF(B$26:F$26,"Yes",B$32:F$32),0)
A21: Average Status Power | B21: =IFERROR(AVERAGEIF(B$26:F$26,"Yes",B$55:F$55),0)
A22: Average Summon Power | B22: =IFERROR(AVERAGEIF(B$26:F$26,"Yes",B$52:F$52),0)
A24: Deck | B24: BoneBulwark | C24: BoneBulwark | D24: BoneBulwark | E24: MoveInnate | F24: MoveInnate
A25: Actions from Card | B25: 3 damage, Shield 5 | C25: 3 damage, Shield 5 | D25: 3 damage, Shield 5 | E25: Move 1 | F25: Move 1
A26: Counted | B26: Yes | C26: Yes | D26: Yes | E26: No | F26: No
A28: Card Facts
A29: Cost | B29: 1 | C29: 1 | D29: 1 | E29: 1 | F29: 1
A30: Range Max | B30: 1 | C30: 1 | D30: 1 | E30: 1 | F30: 1
A31: Tiles Hit | B31: 1 | C31: 1 | D31: 1 | E31: 1 | F31: 1
A32: Damage | B32: 3 | C32: 3 | D32: 3 | E32: 0 | F32: 0
A33: Range | B33: =IFERROR(VLOOKUP(B$30,range_Power,2,TRUE),0) | C33: =IFERROR(VLOOKUP(C$30,range_Power,2,TRUE),0) | D33: =IFERROR(VLOOKUP(D$30,range_Power,2,TRUE),0) | E33: =IFERROR(VLOOKUP(E$30,range_Power,2,TRUE),0) | F33: =IFERROR(VLOOKUP(F$30,range_Power,2,TRUE),0)
A34: Poison Total | B34: 0 | C34: 0 | D34: 0 | E34: 0 | F34: 0
A35: Heal | B35: 0 | C35: 0 | D35: 0 | E35: 0 | F35: 0
A36: Shield | B36: 5 | C36: 5 | D36: 5 | E36: 0 | F36: 0
A37: Block Total | B37: 0 | C37: 0 | D37: 0 | E37: 0 | F37: 0
A38: Parry | B38: 0 | C38: 0 | D38: 0 | E38: 0 | F38: 0
A39: Dodge | B39: 0 | C39: 0 | D39: 0 | E39: 0 | F39: 0
A40: Strength | B40: 0 | C40: 0 | D40: 0 | E40: 0 | F40: 0
A41: Weaken | B41: 0 | C41: 0 | D41: 0 | E41: 0 | F41: 0
A42: Vulnerable | B42: 0 | C42: 0 | D42: 0 | E42: 0 | F42: 0
A43: Frozen | B43: 0 | C43: 0 | D43: 0 | E43: 0 | F43: 0
A44: Rooted | B44: 0 | C44: 0 | D44: 0 | E44: 0 | F44: 0
A45: Taunt | B45: 0 | C45: 0 | D45: 0 | E45: 0 | F45: 0
...

Sheet Crab
A1: Enemy Name | B1: Crab
A2: Boss | B2: No
A3: GUID | B3: f80d9dc6173669245bd4782952cd1667
A4: Sync | B4: =IF($B$3="","NEW","Live")
A6: Stats (synced to Unity)
A7: Display Name | B7: Crab
A8: Health | B8: 40
A9: Actions Per Turn | B9: 1
A10: Brain | B10: Warrior
A11: Targeting | B11: Closest
A12: Loot Table | B12: EarlyGame
A13: Role | B13: Frontline
A15: Brandon's Power Level | B15: 2
A16: Estimated Power Level | B16: =IF($B$8="","",ROUND(($B$19*$B$9*pw_ActionScale+$B$8*pw_Health)/pw_Divisor,3))
A17: Delta (Estimated - Brandon's) | B17: =IF($B$15="","",ROUND($B$16-$B$15,3))
A19: Average Card Power | B19: =IFERROR(AVERAGEIF(B$26:F$26,"Yes",B$54:F$54),0)
A20: Average Damage | B20: =IFERROR(AVERAGEIF(B$26:F$26,"Yes",B$32:F$32),0)
A21: Average Status Power | B21: =IFERROR(AVERAGEIF(B$26:F$26,"Yes",B$55:F$55),0)
A22: Average Summon Power | B22: =IFERROR(AVERAGEIF(B$26:F$26,"Yes",B$52:F$52),0)
A24: Deck | B24: ClawAttack | C24: ClawAttack | D24: ClawAttack | E24: ClawAttack | F24: MoveInnate
A25: Actions from Card | B25: 4 damage, Shield 4 | C25: 4 damage, Shield 4 | D25: 4 damage, Shield 4 | E25: 4 damage, Shield 4 | F25: Move 1
A26: Counted | B26: Yes | C26: Yes | D26: Yes | E26: Yes | F26: No
A28: Card Facts
A29: Cost | B29: 1 | C29: 1 | D29: 1 | E29: 1 | F29: 1
A30: Range Max | B30: 1 | C30: 1 | D30: 1 | E30: 1 | F30: 1
A31: Tiles Hit | B31: 1 | C31: 1 | D31: 1 | E31: 1 | F31: 1
A32: Damage | B32: 4 | C32: 4 | D32: 4 | E32: 4 | F32: 0
A33: Range | B33: =IFERROR(VLOOKUP(B$30,range_Power,2,TRUE),0) | C33: =IFERROR(VLOOKUP(C$30,range_Power,2,TRUE),0) | D33: =IFERROR(VLOOKUP(D$30,range_Power,2,TRUE),0) | E33: =IFERROR(VLOOKUP(E$30,range_Power,2,TRUE),0) | F33: =IFERROR(VLOOKUP(F$30,range_Power,2,TRUE),0)
A34: Poison Total | B34: 0 | C34: 0 | D34: 0 | E34: 0 | F34: 0
A35: Heal | B35: 0 | C35: 0 | D35: 0 | E35: 0 | F35: 0
A36: Shield | B36: 4 | C36: 4 | D36: 4 | E36: 4 | F36: 0
A37: Block Total | B37: 0 | C37: 0 | D37: 0 | E37: 0 | F37: 0
A38: Parry | B38: 0 | C38: 0 | D38: 0 | E38: 0 | F38: 0
A39: Dodge | B39: 0 | C39: 0 | D39: 0 | E39: 0 | F39: 0
A40: Strength | B40: 0 | C40: 0 | D40: 0 | E40: 0 | F40: 0
A41: Weaken | B41: 0 | C41: 0 | D41: 0 | E41: 0 | F41: 0
A42: Vulnerable | B42: 0 | C42: 0 | D42: 0 | E42: 0 | F42: 0
A43: Frozen | B43: 0 | C43: 0 | D43: 0 | E43: 0 | F43: 0
A44: Rooted | B44: 0 | C44: 0 | D44: 0 | E44: 0 | F44: 0
A45: Taunt | B45: 0 | C45: 0 | D45: 0 | E45: 0 | F45: 0
...

Sheet EnemyRanger
A1: Enemy Name | B1: EnemyRanger
A2: Boss | B2: No
A3: GUID | B3: e40f592bea6dbd64693626dad514798b
A4: Sync | B4: =IF($B$3="","NEW","Live")
A6: Stats (synced to Unity)
A7: Display Name | B7: Ranger
A8: Health | B8: 25
A9: Actions Per Turn | B9: 1
A10: Brain | B10: Ranger
A11: Targeting | B11: Totem15Closest
A12: Loot Table | B12: EarlyGame
A13: Role | B13: Backline
A15: Brandon's Power Level | B15: 3.5
A16: Estimated Power Level | B16: =IF($B$8="","",ROUND(($B$19*$B$9*pw_ActionScale+$B$8*pw_Health)/pw_Divisor,3))
A17: Delta (Estimated - Brandon's) | B17: =IF($B$15="","",ROUND($B$16-$B$15,3))
A19: Average Card Power | B19: =IFERROR(AVERAGEIF(B$26:F$26,"Yes",B$54:F$54),0)
A20: Average Damage | B20: =IFERROR(AVERAGEIF(B$26:F$26,"Yes",B$32:F$32),0)
A21: Average Status Power | B21: =IFERROR(AVERAGEIF(B$26:F$26,"Yes",B$55:F$55),0)
A22: Average Summon Power | B22: =IFERROR(AVERAGEIF(B$26:F$26,"Yes",B$52:F$52),0)
A24: Deck | B24: EnemyArrow | C24: EnemyArrow | D24: EnemyArrow | E24: EnemyArrow | F24: MoveInnate2
A25: Actions from Card | B25: 5 damage, Vulnerable 1 | C25: 5 damage, Vulnerable 1 | D25: 5 damage, Vulnerable 1 | E25: 5 damage, Vulnerable 1 | F25: Move 2
A26: Counted | B26: Yes | C26: Yes | D26: Yes | E26: Yes | F26: No
A28: Card Facts
A29: Cost | B29: 1 | C29: 1 | D29: 1 | E29: 1 | F29: 1
A30: Range Max | B30: 6 | C30: 6 | D30: 6 | E30: 6 | F30: 2
A31: Tiles Hit | B31: 1 | C31: 1 | D31: 1 | E31: 1 | F31: 1
A32: Damage | B32: 5 | C32: 5 | D32: 5 | E32: 5 | F32: 0
A33: Range | B33: =IFERROR(VLOOKUP(B$30,range_Power,2,TRUE),0) | C33: =IFERROR(VLOOKUP(C$30,range_Power,2,TRUE),0) | D33: =IFERROR(VLOOKUP(D$30,range_Power,2,TRUE),0) | E33: =IFERROR(VLOOKUP(E$30,range_Power,2,TRUE),0) | F33: =IFERROR(VLOOKUP(F$30,range_Power,2,TRUE),0)
A34: Poison Total | B34: 0 | C34: 0 | D34: 0 | E34: 0 | F34: 0
A35: Heal | B35: 0 | C35: 0 | D35: 0 | E35: 0 | F35: 0
A36: Shield | B36: 0 | C36: 0 | D36: 0 | E36: 0 | F36: 0
A37: Block Total | B37: 0 | C37: 0 | D37: 0 | E37: 0 | F37: 0
A38: Parry | B38: 0 | C38: 0 | D38: 0 | E38: 0 | F38: 0
A39: Dodge | B39: 0 | C39: 0 | D39: 0 | E39: 0 | F39: 0
A40: Strength | B40: 0 | C40: 0 | D40: 0 | E40: 0 | F40: 0
A41: Weaken | B41: 0 | C41: 0 | D41: 0 | E41: 0 | F41: 0
A42: Vulnerable | B42: 1 | C42: 1 | D42: 1 | E42: 1 | F42: 0
A43: Frozen | B43: 0 | C43: 0 | D43: 0 | E43: 0 | F43: 0
A44: Rooted | B44: 0 | C44: 0 | D44: 0 | E44: 0 | F44: 0
A45: Taunt | B45: 0 | C45: 0 | D45: 0 | E45: 0 | F45: 0
...

Sheet FlyingEye
A1: Enemy Name | B1: FlyingEye
A2: Boss | B2: No
A3: GUID | B3: 158567c6103052b45a79feac134a4c3b
A4: Sync | B4: =IF($B$3="","NEW","Live")
A6: Stats (synced to Unity)
A7: Display Name | B7: Flying Eye
A8: Health | B8: 15
A9: Actions Per Turn | B9: 1
A10: Brain | B10: Ranger
A11: Targeting | B11: Totem15Closest
A12: Loot Table | B12: EarlyGame
A13: Role | B13: Backline
A15: Brandon's Power Level | B15: 1.68
A16: Estimated Power Level | B16: =IF($B$8="","",ROUND(($B$19*$B$9*pw_ActionScale+$B$8*pw_Health)/pw_Divisor,3))
A17: Delta (Estimated - Brandon's) | B17: =IF($B$15="","",ROUND($B$16-$B$15,3))
A19: Average Card Power | B19: =IFERROR(AVERAGEIF(B$26:F$26,"Yes",B$54:F$54),0)
A20: Average Damage | B20: =IFERROR(AVERAGEIF(B$26:F$26,"Yes",B$32:F$32),0)
A21: Average Status Power | B21: =IFERROR(AVERAGEIF(B$26:F$26,"Yes",B$55:F$55),0)
A22: Average Summon Power | B22: =IFERROR(AVERAGEIF(B$26:F$26,"Yes",B$52:F$52),0)
A24: Deck | B24: WitheringGaze | C24: WitheringGaze | D24: WitheringGaze | E24: WitheringGaze | F24: MoveInnate
A25: Actions from Card | B25: 3 damage | C25: 3 damage | D25: 3 damage | E25: 3 damage | F25: Move 1
A26: Counted | B26: Yes | C26: Yes | D26: Yes | E26: Yes | F26: No
A28: Card Facts
A29: Cost | B29: 1 | C29: 1 | D29: 1 | E29: 1 | F29: 1
A30: Range Max | B30: 4 | C30: 4 | D30: 4 | E30: 4 | F30: 1
A31: Tiles Hit | B31: 1 | C31: 1 | D31: 1 | E31: 1 | F31: 1
A32: Damage | B32: 3 | C32: 3 | D32: 3 | E32: 3 | F32: 0
A33: Range | B33: =IFERROR(VLOOKUP(B$30,range_Power,2,TRUE),0) | C33: =IFERROR(VLOOKUP(C$30,range_Power,2,TRUE),0) | D33: =IFERROR(VLOOKUP(D$30,range_Power,2,TRUE),0) | E33: =IFERROR(VLOOKUP(E$30,range_Power,2,TRUE),0) | F33: =IFERROR(VLOOKUP(F$30,range_Power,2,TRUE),0)
A34: Poison Total | B34: 0 | C34: 0 | D34: 0 | E34: 0 | F34: 0
A35: Heal | B35: 0 | C35: 0 | D35: 0 | E35: 0 | F35: 0
A36: Shield | B36: 0 | C36: 0 | D36: 0 | E36: 0 | F36: 0
A37: Block Total | B37: 0 | C37: 0 | D37: 0 | E37: 0 | F37: 0
A38: Parry | B38: 0 | C38: 0 | D38: 0 | E38: 0 | F38: 0
A39: Dodge | B39: 0 | C39: 0 | D39: 0 | E39: 0 | F39: 0
A40: Strength | B40: 0 | C40: 0 | D40: 0 | E40: 0 | F40: 0
A41: Weaken | B41: 0 | C41: 0 | D41: 0 | E41: 0 | F41: 0
A42: Vulnerable | B42: 0 | C42: 0 | D42: 0 | E42: 0 | F42: 0
A43: Frozen | B43: 0 | C43: 0 | D43: 0 | E43: 0 | F43: 0
A44: Rooted | B44: 0 | C44: 0 | D44: 0 | E44: 0 | F44: 0
A45: Taunt | B45: 0 | C45: 0 | D45: 0 | E45: 0 | F45: 0
...

Sheet Goblin
A1: Enemy Name | B1: Goblin
A2: Boss | B2: No
A3: GUID | B3: fe7fe8169a3ae3f4ab1463af48263a1a
A4: Sync | B4: =IF($B$3="","NEW","Live")
A6: Stats (synced to Unity)
A7: Display Name | B7: Goblin
A8: Health | B8: 20
A9: Actions Per Turn | B9: 1
A10: Brain | B10: Warrior
A11: Targeting | B11: Weakest
A12: Loot Table | B12: EarlyGame
A13: Role | B13: Frontline
A15: Brandon's Power Level | B15: 1.5
A16: Estimated Power Level | B16: =IF($B$8="","",ROUND(($B$19*$B$9*pw_ActionScale+$B$8*pw_Health)/pw_Divisor,3))
A17: Delta (Estimated - Brandon's) | B17: =IF($B$15="","",ROUND($B$16-$B$15,3))
A19: Average Card Power | B19: =IFERROR(AVERAGEIF(B$26:F$26,"Yes",B$54:F$54),0)
A20: Average Damage | B20: =IFERROR(AVERAGEIF(B$26:F$26,"Yes",B$32:F$32),0)
A21: Average Status Power | B21: =IFERROR(AVERAGEIF(B$26:F$26,"Yes",B$55:F$55),0)
A22: Average Summon Power | B22: =IFERROR(AVERAGEIF(B$26:F$26,"Yes",B$52:F$52),0)
A24: Deck | B24: Backstab | C24: Backstab | D24: Backstab | E24: Backstab | F24: MoveInnate2
A25: Actions from Card | B25: 5 damage | C25: 5 damage | D25: 5 damage | E25: 5 damage | F25: Move 2
A26: Counted | B26: Yes | C26: Yes | D26: Yes | E26: Yes | F26: No
A28: Card Facts
A29: Cost | B29: 1 | C29: 1 | D29: 1 | E29: 1 | F29: 1
A30: Range Max | B30: 1 | C30: 1 | D30: 1 | E30: 1 | F30: 2
A31: Tiles Hit | B31: 1 | C31: 1 | D31: 1 | E31: 1 | F31: 1
A32: Damage | B32: 5 | C32: 5 | D32: 5 | E32: 5 | F32: 0
A33: Range | B33: =IFERROR(VLOOKUP(B$30,range_Power,2,TRUE),0) | C33: =IFERROR(VLOOKUP(C$30,range_Power,2,TRUE),0) | D33: =IFERROR(VLOOKUP(D$30,range_Power,2,TRUE),0) | E33: =IFERROR(VLOOKUP(E$30,range_Power,2,TRUE),0) | F33: =IFERROR(VLOOKUP(F$30,range_Power,2,TRUE),0)
A34: Poison Total | B34: 0 | C34: 0 | D34: 0 | E34: 0 | F34: 0
A35: Heal | B35: 0 | C35: 0 | D35: 0 | E35: 0 | F35: 0
A36: Shield | B36: 0 | C36: 0 | D36: 0 | E36: 0 | F36: 0
A37: Block Total | B37: 0 | C37: 0 | D37: 0 | E37: 0 | F37: 0
A38: Parry | B38: 0 | C38: 0 | D38: 0 | E38: 0 | F38: 0
A39: Dodge | B39: 0 | C39: 0 | D39: 0 | E39: 0 | F39: 0
A40: Strength | B40: 0 | C40: 0 | D40: 0 | E40: 0 | F40: 0
A41: Weaken | B41: 0 | C41: 0 | D41: 0 | E41: 0 | F41: 0
A42: Vulnerable | B42: 0 | C42: 0 | D42: 0 | E42: 0 | F42: 0
A43: Frozen | B43: 0 | C43: 0 | D43: 0 | E43: 0 | F43: 0
A44: Rooted | B44: 0 | C44: 0 | D44: 0 | E44: 0 | F44: 0
A45: Taunt | B45: 0 | C45: 0 | D45: 0 | E45: 0 | F45: 0
...

Sheet Golem
A1: Enemy Name | B1: Golem
A2: Boss | B2: No
A3: GUID | B3: 5bdb828176c88144986e3b367ffda1b4
A4: Sync | B4: =IF($B$3="","NEW","Live")
A6: Stats (synced to Unity)
A7: Display Name | B7: Golem
A8: Health | B8: 60
A9: Actions Per Turn | B9: 1
A10: Brain | B10: Summoner
A11: Targeting | B11: Closest
A12: Loot Table | B12: EarlyGame
A13: Role | B13: Frontline
A15: Brandon's Power Level | B15: 2.65
A16: Estimated Power Level | B16: =IF($B$8="","",ROUND(($B$19*$B$9*pw_ActionScale+$B$8*pw_Health)/pw_Divisor,3))
A17: Delta (Estimated - Brandon's) | B17: =IF($B$15="","",ROUND($B$16-$B$15,3))
A19: Average Card Power | B19: =IFERROR(AVERAGEIF(B$26:F$26,"Yes",B$54:F$54),0)
A20: Average Damage | B20: =IFERROR(AVERAGEIF(B$26:F$26,"Yes",B$32:F$32),0)
A21: Average Status Power | B21: =IFERROR(AVERAGEIF(B$26:F$26,"Yes",B$55:F$55),0)
A22: Average Summon Power | B22: =IFERROR(AVERAGEIF(B$26:F$26,"Yes",B$52:F$52),0)
A24: Deck | B24: BoulderSmash | C24: BoulderSmash | D24: BoulderSmash | E24: SummonPebble | F24: MoveInnate
A25: Actions from Card | B25: 5 damage | C25: 5 damage | D25: 5 damage | E25: Summon | F25: Move 1
A26: Counted | B26: Yes | C26: Yes | D26: Yes | E26: No | F26: No
A28: Card Facts
A29: Cost | B29: 1 | C29: 1 | D29: 1 | E29: 1 | F29: 1
A30: Range Max | B30: 1 | C30: 1 | D30: 1 | E30: 1 | F30: 1
A31: Tiles Hit | B31: 1 | C31: 1 | D31: 1 | E31: 1 | F31: 1
A32: Damage | B32: 5 | C32: 5 | D32: 5 | E32: 0 | F32: 0
A33: Range | B33: =IFERROR(VLOOKUP(B$30,range_Power,2,TRUE),0) | C33: =IFERROR(VLOOKUP(C$30,range_Power,2,TRUE),0) | D33: =IFERROR(VLOOKUP(D$30,range_Power,2,TRUE),0) | E33: =IFERROR(VLOOKUP(E$30,range_Power,2,TRUE),0) | F33: =IFERROR(VLOOKUP(F$30,range_Power,2,TRUE),0)
A34: Poison Total | B34: 0 | C34: 0 | D34: 0 | E34: 0 | F34: 0
A35: Heal | B35: 0 | C35: 0 | D35: 0 | E35: 0 | F35: 0
A36: Shield | B36: 0 | C36: 0 | D36: 0 | E36: 0 | F36: 0
A37: Block Total | B37: 0 | C37: 0 | D37: 0 | E37: 0 | F37: 0
A38: Parry | B38: 0 | C38: 0 | D38: 0 | E38: 0 | F38: 0
A39: Dodge | B39: 0 | C39: 0 | D39: 0 | E39: 0 | F39: 0
A40: Strength | B40: 0 | C40: 0 | D40: 0 | E40: 0 | F40: 0
A41: Weaken | B41: 0 | C41: 0 | D41: 0 | E41: 0 | F41: 0
A42: Vulnerable | B42: 0 | C42: 0 | D42: 0 | E42: 0 | F42: 0
A43: Frozen | B43: 0 | C43: 0 | D43: 0 | E43: 0 | F43: 0
A44: Rooted | B44: 0 | C44: 0 | D44: 0 | E44: 0 | F44: 0
A45: Taunt | B45: 0 | C45: 0 | D45: 0 | E45: 0 | F45: 0
...

Sheet HeavyBandit
A1: Enemy Name | B1: HeavyBandit
A2: Boss | B2: No
A3: GUID | B3: abb6f217c283d344999e3f27fa36640f
A4: Sync | B4: =IF($B$3="","NEW","Live")
A6: Stats (synced to Unity)
A7: Display Name | B7: Heavy Bandit
A8: Health | B8: 50
A9: Actions Per Turn | B9: 1
A10: Brain | B10: Warrior
A11: Targeting | B11: Strongest
A12: Loot Table | B12: EarlyGame
A13: Role | B13: Frontline
A15: Brandon's Power Level | B15: 3.5
A16: Estimated Power Level | B16: =IF($B$8="","",ROUND(($B$19*$B$9*pw_ActionScale+$B$8*pw_Health)/pw_Divisor,3))
A17: Delta (Estimated - Brandon's) | B17: =IF($B$15="","",ROUND($B$16-$B$15,3))
A19: Average Card Power | B19: =IFERROR(AVERAGEIF(B$26:F$26,"Yes",B$54:F$54),0)
A20: Average Damage | B20: =IFERROR(AVERAGEIF(B$26:F$26,"Yes",B$32:F$32),0)
A21: Average Status Power | B21: =IFERROR(AVERAGEIF(B$26:F$26,"Yes",B$55:F$55),0)
A22: Average Summon Power | B22: =IFERROR(AVERAGEIF(B$26:F$26,"Yes",B$52:F$52),0)
A24: Deck | B24: HeavySwing | C24: HeavySwing | D24: HeavySwing | E24: HeavySwing | F24: MoveInnate
A25: Actions from Card | B25: 6 damage, Shield 5, Block x2 | C25: 6 damage, Shield 5, Block x2 | D25: 6 damage, Shield 5, Block x2 | E25: 6 damage, Shield 5, Block x2 | F25: Move 1
A26: Counted | B26: Yes | C26: Yes | D26: Yes | E26: Yes | F26: No
A28: Card Facts
A29: Cost | B29: 1 | C29: 1 | D29: 1 | E29: 1 | F29: 1
A30: Range Max | B30: 1 | C30: 1 | D30: 1 | E30: 1 | F30: 1
A31: Tiles Hit | B31: 1 | C31: 1 | D31: 1 | E31: 1 | F31: 1
A32: Damage | B32: 6 | C32: 6 | D32: 6 | E32: 6 | F32: 0
A33: Range | B33: =IFERROR(VLOOKUP(B$30,range_Power,2,TRUE),0) | C33: =IFERROR(VLOOKUP(C$30,range_Power,2,TRUE),0) | D33: =IFERROR(VLOOKUP(D$30,range_Power,2,TRUE),0) | E33: =IFERROR(VLOOKUP(E$30,range_Power,2,TRUE),0) | F33: =IFERROR(VLOOKUP(F$30,range_Power,2,TRUE),0)
A34: Poison Total | B34: 0 | C34: 0 | D34: 0 | E34: 0 | F34: 0
A35: Heal | B35: 0 | C35: 0 | D35: 0 | E35: 0 | F35: 0
A36: Shield | B36: 5 | C36: 5 | D36: 5 | E36: 5 | F36: 0
A37: Block Total | B37: 10 | C37: 10 | D37: 10 | E37: 10 | F37: 0
A38: Parry | B38: 0 | C38: 0 | D38: 0 | E38: 0 | F38: 0
A39: Dodge | B39: 0 | C39: 0 | D39: 0 | E39: 0 | F39: 0
A40: Strength | B40: 0 | C40: 0 | D40: 0 | E40: 0 | F40: 0
A41: Weaken | B41: 0 | C41: 0 | D41: 0 | E41: 0 | F41: 0
A42: Vulnerable | B42: 0 | C42: 0 | D42: 0 | E42: 0 | F42: 0
A43: Frozen | B43: 0 | C43: 0 | D43: 0 | E43: 0 | F43: 0
A44: Rooted | B44: 0 | C44: 0 | D44: 0 | E44: 0 | F44: 0
A45: Taunt | B45: 0 | C45: 0 | D45: 0 | E45: 0 | F45: 0
...

Sheet LightBandit
A1: Enemy Name | B1: LightBandit
A2: Boss | B2: No
A3: GUID | B3: df52b2ab92f38fd4eb6d6064e8197a56
A4: Sync | B4: =IF($B$3="","NEW","Live")
A6: Stats (synced to Unity)
A7: Display Name | B7: Light Bandit
A8: Health | B8: 30
A9: Actions Per Turn | B9: 1
A10: Brain | B10: Warrior
A11: Targeting | B11: Weakest
A12: Loot Table | B12: EarlyGame
A13: Role | B13: Backline
A15: Brandon's Power Level | B15: 2.5
A16: Estimated Power Level | B16: =IF($B$8="","",ROUND(($B$19*$B$9*pw_ActionScale+$B$8*pw_Health)/pw_Divisor,3))
A17: Delta (Estimated - Brandon's) | B17: =IF($B$15="","",ROUND($B$16-$B$15,3))
A19: Average Card Power | B19: =IFERROR(AVERAGEIF(B$26:F$26,"Yes",B$54:F$54),0)
A20: Average Damage | B20: =IFERROR(AVERAGEIF(B$26:F$26,"Yes",B$32:F$32),0)
A21: Average Status Power | B21: =IFERROR(AVERAGEIF(B$26:F$26,"Yes",B$55:F$55),0)
A22: Average Summon Power | B22: =IFERROR(AVERAGEIF(B$26:F$26,"Yes",B$52:F$52),0)
A24: Deck | B24: QuickCut | C24: QuickCut | D24: VenomCut | E24: VenomCut | F24: MoveInnate2
A25: Actions from Card | B25: 1 damage, Weaken 1 | C25: 1 damage, Weaken 1 | D25: 1 damage, Poison 3 | E25: 1 damage, Poison 3 | F25: Move 2
A26: Counted | B26: Yes | C26: Yes | D26: Yes | E26: Yes | F26: No
A28: Card Facts
A29: Cost | B29: 1 | C29: 1 | D29: 1 | E29: 1 | F29: 1
A30: Range Max | B30: 4 | C30: 4 | D30: 4 | E30: 4 | F30: 2
A31: Tiles Hit | B31: 9 | C31: 9 | D31: 9 | E31: 9 | F31: 1
A32: Damage | B32: 1 | C32: 1 | D32: 1 | E32: 1 | F32: 0
A33: Range | B33: =IFERROR(VLOOKUP(B$30,range_Power,2,TRUE),0) | C33: =IFERROR(VLOOKUP(C$30,range_Power,2,TRUE),0) | D33: =IFERROR(VLOOKUP(D$30,range_Power,2,TRUE),0) | E33: =IFERROR(VLOOKUP(E$30,range_Power,2,TRUE),0) | F33: =IFERROR(VLOOKUP(F$30,range_Power,2,TRUE),0)
A34: Poison Total | B34: 0 | C34: 0 | D34: 6 | E34: 6 | F34: 0
A35: Heal | B35: 0 | C35: 0 | D35: 0 | E35: 0 | F35: 0
A36: Shield | B36: 0 | C36: 0 | D36: 0 | E36: 0 | F36: 0
A37: Block Total | B37: 0 | C37: 0 | D37: 0 | E37: 0 | F37: 0
A38: Parry | B38: 0 | C38: 0 | D38: 0 | E38: 0 | F38: 0
A39: Dodge | B39: 0 | C39: 0 | D39: 0 | E39: 0 | F39: 0
A40: Strength | B40: 0 | C40: 0 | D40: 0 | E40: 0 | F40: 0
A41: Weaken | B41: 1 | C41: 1 | D41: 0 | E41: 0 | F41: 0
A42: Vulnerable | B42: 0 | C42: 0 | D42: 0 | E42: 0 | F42: 0
A43: Frozen | B43: 0 | C43: 0 | D43: 0 | E43: 0 | F43: 0
A44: Rooted | B44: 0 | C44: 0 | D44: 0 | E44: 0 | F44: 0
A45: Taunt | B45: 0 | C45: 0 | D45: 0 | E45: 0 | F45: 0
...

Sheet Mimic
A1: Enemy Name | B1: Mimic
A2: Boss | B2: No
A3: GUID | B3: 022c86b9aa20aaf44806e866dd6d8971
A4: Sync | B4: =IF($B$3="","NEW","Live")
A6: Stats (synced to Unity)
A7: Display Name | B7: Mimic
A8: Health | B8: 35
A9: Actions Per Turn | B9: 1
A10: Brain | B10: Warrior
A11: Targeting | B11: ClosestIgnoreTotem
A12: Loot Table | B12: EarlyGame
A13: Role | B13: Frontline
A15: Brandon's Power Level | B15: 2.5
A16: Estimated Power Level | B16: =IF($B$8="","",ROUND(($B$19*$B$9*pw_ActionScale+$B$8*pw_Health)/pw_Divisor,3))
A17: Delta (Estimated - Brandon's) | B17: =IF($B$15="","",ROUND($B$16-$B$15,3))
A19: Average Card Power | B19: =IFERROR(AVERAGEIF(B$26:F$26,"Yes",B$54:F$54),0)
A20: Average Damage | B20: =IFERROR(AVERAGEIF(B$26:F$26,"Yes",B$32:F$32),0)
A21: Average Status Power | B21: =IFERROR(AVERAGEIF(B$26:F$26,"Yes",B$55:F$55),0)
A22: Average Summon Power | B22: =IFERROR(AVERAGEIF(B$26:F$26,"Yes",B$52:F$52),0)
A24: Deck | B24: Chomp | C24: Chomp | D24: Chomp | E24: Chomp | F24: MoveInnate
A25: Actions from Card | B25: 7 damage, Root 1t | C25: 7 damage, Root 1t | D25: 7 damage, Root 1t | E25: 7 damage, Root 1t | F25: Move 1
A26: Counted | B26: Yes | C26: Yes | D26: Yes | E26: Yes | F26: No
A28: Card Facts
A29: Cost | B29: 1 | C29: 1 | D29: 1 | E29: 1 | F29: 1
A30: Range Max | B30: 1 | C30: 1 | D30: 1 | E30: 1 | F30: 1
A31: Tiles Hit | B31: 1 | C31: 1 | D31: 1 | E31: 1 | F31: 1
A32: Damage | B32: 7 | C32: 7 | D32: 7 | E32: 7 | F32: 0
A33: Range | B33: =IFERROR(VLOOKUP(B$30,range_Power,2,TRUE),0) | C33: =IFERROR(VLOOKUP(C$30,range_Power,2,TRUE),0) | D33: =IFERROR(VLOOKUP(D$30,range_Power,2,TRUE),0) | E33: =IFERROR(VLOOKUP(E$30,range_Power,2,TRUE),0) | F33: =IFERROR(VLOOKUP(F$30,range_Power,2,TRUE),0)
A34: Poison Total | B34: 0 | C34: 0 | D34: 0 | E34: 0 | F34: 0
A35: Heal | B35: 0 | C35: 0 | D35: 0 | E35: 0 | F35: 0
A36: Shield | B36: 0 | C36: 0 | D36: 0 | E36: 0 | F36: 0
A37: Block Total | B37: 0 | C37: 0 | D37: 0 | E37: 0 | F37: 0
A38: Parry | B38: 0 | C38: 0 | D38: 0 | E38: 0 | F38: 0
A39: Dodge | B39: 0 | C39: 0 | D39: 0 | E39: 0 | F39: 0
A40: Strength | B40: 0 | C40: 0 | D40: 0 | E40: 0 | F40: 0
A41: Weaken | B41: 0 | C41: 0 | D41: 0 | E41: 0 | F41: 0
A42: Vulnerable | B42: 0 | C42: 0 | D42: 0 | E42: 0 | F42: 0
A43: Frozen | B43: 0 | C43: 0 | D43: 0 | E43: 0 | F43: 0
A44: Rooted | B44: 1 | C44: 1 | D44: 1 | E44: 1 | F44: 0
A45: Taunt | B45: 0 | C45: 0 | D45: 0 | E45: 0 | F45: 0
...

Sheet Mushroom
A1: Enemy Name | B1: Mushroom
A2: Boss | B2: No
A3: GUID | B3: f04aa7787f30bab4a96433807a0f06a5
A4: Sync | B4: =IF($B$3="","NEW","Live")
A6: Stats (synced to Unity)
A7: Display Name | B7: Mushroom
A8: Health | B8: 30
A9: Actions Per Turn | B9: 1
A10: Brain | B10: Ranger
A11: Targeting | B11: Closest
A12: Loot Table | B12: EarlyGame
A13: Role | B13: Frontline
A15: Brandon's Power Level | B15: 2
A16: Estimated Power Level | B16: =IF($B$8="","",ROUND(($B$19*$B$9*pw_ActionScale+$B$8*pw_Health)/pw_Divisor,3))
A17: Delta (Estimated - Brandon's) | B17: =IF($B$15="","",ROUND($B$16-$B$15,3))
A19: Average Card Power | B19: =IFERROR(AVERAGEIF(B$26:F$26,"Yes",B$54:F$54),0)
A20: Average Damage | B20: =IFERROR(AVERAGEIF(B$26:F$26,"Yes",B$32:F$32),0)
A21: Average Status Power | B21: =IFERROR(AVERAGEIF(B$26:F$26,"Yes",B$55:F$55),0)
A22: Average Summon Power | B22: =IFERROR(AVERAGEIF(B$26:F$26,"Yes",B$52:F$52),0)
A24: Deck | B24: SporeCloud | C24: SporeCloud | D24: SporeCloud | E24: SporeCloud | F24: MoveInnate
A25: Actions from Card | B25: Poison 3 | C25: Poison 3 | D25: Poison 3 | E25: Poison 3 | F25: Move 1
A26: Counted | B26: Yes | C26: Yes | D26: Yes | E26: Yes | F26: No
A28: Card Facts
A29: Cost | B29: 1 | C29: 1 | D29: 1 | E29: 1 | F29: 1
A30: Range Max | B30: 3 | C30: 3 | D30: 3 | E30: 3 | F30: 1
A31: Tiles Hit | B31: 9 | C31: 9 | D31: 9 | E31: 9 | F31: 1
A32: Damage | B32: 0 | C32: 0 | D32: 0 | E32: 0 | F32: 0
A33: Range | B33: =IFERROR(VLOOKUP(B$30,range_Power,2,TRUE),0) | C33: =IFERROR(VLOOKUP(C$30,range_Power,2,TRUE),0) | D33: =IFERROR(VLOOKUP(D$30,range_Power,2,TRUE),0) | E33: =IFERROR(VLOOKUP(E$30,range_Power,2,TRUE),0) | F33: =IFERROR(VLOOKUP(F$30,range_Power,2,TRUE),0)
A34: Poison Total | B34: 6 | C34: 6 | D34: 6 | E34: 6 | F34: 0
A35: Heal | B35: 0 | C35: 0 | D35: 0 | E35: 0 | F35: 0
A36: Shield | B36: 0 | C36: 0 | D36: 0 | E36: 0 | F36: 0
A37: Block Total | B37: 0 | C37: 0 | D37: 0 | E37: 0 | F37: 0
A38: Parry | B38: 0 | C38: 0 | D38: 0 | E38: 0 | F38: 0
A39: Dodge | B39: 0 | C39: 0 | D39: 0 | E39: 0 | F39: 0
A40: Strength | B40: 0 | C40: 0 | D40: 0 | E40: 0 | F40: 0
A41: Weaken | B41: 0 | C41: 0 | D41: 0 | E41: 0 | F41: 0
A42: Vulnerable | B42: 0 | C42: 0 | D42: 0 | E42: 0 | F42: 0
A43: Frozen | B43: 0 | C43: 0 | D43: 0 | E43: 0 | F43: 0
A44: Rooted | B44: 0 | C44: 0 | D44: 0 | E44: 0 | F44: 0
A45: Taunt | B45: 0 | C45: 0 | D45: 0 | E45: 0 | F45: 0
...

Sheet Pebble
A1: Enemy Name | B1: Pebble
A2: Boss | B2: No
A3: GUID | B3: cffb630e9ce4c0f4798ae3e294d1d8e8
A4: Sync | B4: =IF($B$3="","NEW","Live")
A6: Stats (synced to Unity)
A7: Display Name | B7: Pebble
A8: Health | B8: 5
A9: Actions Per Turn | B9: 1
A10: Brain | B10: Warrior
A11: Targeting | B11: TotemClosest
A12: Loot Table
A13: Role | B13: None
A15: Brandon's Power Level | B15: 0.5
A16: Estimated Power Level | B16: =IF($B$8="","",ROUND(($B$19*$B$9*pw_ActionScale+$B$8*pw_Health)/pw_Divisor,3))
A17: Delta (Estimated - Brandon's) | B17: =IF($B$15="","",ROUND($B$16-$B$15,3))
A19: Average Card Power | B19: =IFERROR(AVERAGEIF(B$26:F$26,"Yes",B$54:F$54),0)
A20: Average Damage | B20: =IFERROR(AVERAGEIF(B$26:F$26,"Yes",B$32:F$32),0)
A21: Average Status Power | B21: =IFERROR(AVERAGEIF(B$26:F$26,"Yes",B$55:F$55),0)
A22: Average Summon Power | B22: =IFERROR(AVERAGEIF(B$26:F$26,"Yes",B$52:F$52),0)
A24: Deck | B24: Roll | C24: Roll | D24: Roll | E24: Roll | F24: MoveInnate2
A25: Actions from Card | B25: 2 damage | C25: 2 damage | D25: 2 damage | E25: 2 damage | F25: Move 2
A26: Counted | B26: Yes | C26: Yes | D26: Yes | E26: Yes | F26: No
A28: Card Facts
A29: Cost | B29: 1 | C29: 1 | D29: 1 | E29: 1 | F29: 1
A30: Range Max | B30: 1 | C30: 1 | D30: 1 | E30: 1 | F30: 2
A31: Tiles Hit | B31: 1 | C31: 1 | D31: 1 | E31: 1 | F31: 1
A32: Damage | B32: 2 | C32: 2 | D32: 2 | E32: 2 | F32: 0
A33: Range | B33: =IFERROR(VLOOKUP(B$30,range_Power,2,TRUE),0) | C33: =IFERROR(VLOOKUP(C$30,range_Power,2,TRUE),0) | D33: =IFERROR(VLOOKUP(D$30,range_Power,2,TRUE),0) | E33: =IFERROR(VLOOKUP(E$30,range_Power,2,TRUE),0) | F33: =IFERROR(VLOOKUP(F$30,range_Power,2,TRUE),0)
A34: Poison Total | B34: 0 | C34: 0 | D34: 0 | E34: 0 | F34: 0
A35: Heal | B35: 0 | C35: 0 | D35: 0 | E35: 0 | F35: 0
A36: Shield | B36: 0 | C36: 0 | D36: 0 | E36: 0 | F36: 0
A37: Block Total | B37: 0 | C37: 0 | D37: 0 | E37: 0 | F37: 0
A38: Parry | B38: 0 | C38: 0 | D38: 0 | E38: 0 | F38: 0
A39: Dodge | B39: 0 | C39: 0 | D39: 0 | E39: 0 | F39: 0
A40: Strength | B40: 0 | C40: 0 | D40: 0 | E40: 0 | F40: 0
A41: Weaken | B41: 0 | C41: 0 | D41: 0 | E41: 0 | F41: 0
A42: Vulnerable | B42: 0 | C42: 0 | D42: 0 | E42: 0 | F42: 0
A43: Frozen | B43: 0 | C43: 0 | D43: 0 | E43: 0 | F43: 0
A44: Rooted | B44: 0 | C44: 0 | D44: 0 | E44: 0 | F44: 0
A45: Taunt | B45: 0 | C45: 0 | D45: 0 | E45: 0 | F45: 0
...

Sheet PlagueRat
A1: Enemy Name | B1: PlagueRat
A2: Boss | B2: No
A3: GUID | B3: 37960ead296e23e4ca189530884917c3
A4: Sync | B4: =IF($B$3="","NEW","Live")
A6: Stats (synced to Unity)
A7: Display Name | B7: Plague Rat
A8: Health | B8: 30
A9: Actions Per Turn | B9: 1
A10: Brain | B10: Warrior
A11: Targeting | B11: Closest
A12: Loot Table | B12: EarlyGame
A13: Role | B13: Frontline
A15: Brandon's Power Level | B15: 2
A16: Estimated Power Level | B16: =IF($B$8="","",ROUND(($B$19*$B$9*pw_ActionScale+$B$8*pw_Health)/pw_Divisor,3))
A17: Delta (Estimated - Brandon's) | B17: =IF($B$15="","",ROUND($B$16-$B$15,3))
A19: Average Card Power | B19: =IFERROR(AVERAGEIF(B$26:F$26,"Yes",B$54:F$54),0)
A20: Average Damage | B20: =IFERROR(AVERAGEIF(B$26:F$26,"Yes",B$32:F$32),0)
A21: Average Status Power | B21: =IFERROR(AVERAGEIF(B$26:F$26,"Yes",B$55:F$55),0)
A22: Average Summon Power | B22: =IFERROR(AVERAGEIF(B$26:F$26,"Yes",B$52:F$52),0)
A24: Deck | B24: PlagueBite | C24: PlagueBite | D24: PlagueBite | E24: PlagueBite | F24: MoveInnate
A25: Actions from Card | B25: 2 damage, Poison 3 | C25: 2 damage, Poison 3 | D25: 2 damage, Poison 3 | E25: 2 damage, Poison 3 | F25: Move 1
A26: Counted | B26: Yes | C26: Yes | D26: Yes | E26: Yes | F26: No
A28: Card Facts
A29: Cost | B29: 1 | C29: 1 | D29: 1 | E29: 1 | F29: 1
A30: Range Max | B30: 1 | C30: 1 | D30: 1 | E30: 1 | F30: 1
A31: Tiles Hit | B31: 1 | C31: 1 | D31: 1 | E31: 1 | F31: 1
A32: Damage | B32: 2 | C32: 2 | D32: 2 | E32: 2 | F32: 0
A33: Range | B33: =IFERROR(VLOOKUP(B$30,range_Power,2,TRUE),0) | C33: =IFERROR(VLOOKUP(C$30,range_Power,2,TRUE),0) | D33: =IFERROR(VLOOKUP(D$30,range_Power,2,TRUE),0) | E33: =IFERROR(VLOOKUP(E$30,range_Power,2,TRUE),0) | F33: =IFERROR(VLOOKUP(F$30,range_Power,2,TRUE),0)
A34: Poison Total | B34: 6 | C34: 6 | D34: 6 | E34: 6 | F34: 0
A35: Heal | B35: 0 | C35: 0 | D35: 0 | E35: 0 | F35: 0
A36: Shield | B36: 0 | C36: 0 | D36: 0 | E36: 0 | F36: 0
A37: Block Total | B37: 0 | C37: 0 | D37: 0 | E37: 0 | F37: 0
A38: Parry | B38: 0 | C38: 0 | D38: 0 | E38: 0 | F38: 0
A39: Dodge | B39: 0 | C39: 0 | D39: 0 | E39: 0 | F39: 0
A40: Strength | B40: 0 | C40: 0 | D40: 0 | E40: 0 | F40: 0
A41: Weaken | B41: 0 | C41: 0 | D41: 0 | E41: 0 | F41: 0
A42: Vulnerable | B42: 0 | C42: 0 | D42: 0 | E42: 0 | F42: 0
A43: Frozen | B43: 0 | C43: 0 | D43: 0 | E43: 0 | F43: 0
A44: Rooted | B44: 0 | C44: 0 | D44: 0 | E44: 0 | F44: 0
A45: Taunt | B45: 0 | C45: 0 | D45: 0 | E45: 0 | F45: 0
...

Sheet Rat
A1: Enemy Name | B1: Rat
A2: Boss | B2: No
A3: GUID | B3: b9a57d66ac78e19468a62c235ce3e746
A4: Sync | B4: =IF($B$3="","NEW","Live")
A6: Stats (synced to Unity)
A7: Display Name | B7: Rat
A8: Health | B8: 25
A9: Actions Per Turn | B9: 1
A10: Brain | B10: Warrior
A11: Targeting | B11: Weakest
A12: Loot Table | B12: EarlyGame
A13: Role | B13: Frontline
A15: Brandon's Power Level | B15: 1.5
A16: Estimated Power Level | B16: =IF($B$8="","",ROUND(($B$19*$B$9*pw_ActionScale+$B$8*pw_Health)/pw_Divisor,3))
A17: Delta (Estimated - Brandon's) | B17: =IF($B$15="","",ROUND($B$16-$B$15,3))
A19: Average Card Power | B19: =IFERROR(AVERAGEIF(B$26:F$26,"Yes",B$54:F$54),0)
A20: Average Damage | B20: =IFERROR(AVERAGEIF(B$26:F$26,"Yes",B$32:F$32),0)
A21: Average Status Power | B21: =IFERROR(AVERAGEIF(B$26:F$26,"Yes",B$55:F$55),0)
A22: Average Summon Power | B22: =IFERROR(AVERAGEIF(B$26:F$26,"Yes",B$52:F$52),0)
A24: Deck | B24: Gnaw | C24: Gnaw | D24: Gnaw | E24: Gnaw | F24: MoveInnate
A25: Actions from Card | B25: 4 damage | C25: 4 damage | D25: 4 damage | E25: 4 damage | F25: Move 1
A26: Counted | B26: Yes | C26: Yes | D26: Yes | E26: Yes | F26: No
A28: Card Facts
A29: Cost | B29: 1 | C29: 1 | D29: 1 | E29: 1 | F29: 1
A30: Range Max | B30: 1 | C30: 1 | D30: 1 | E30: 1 | F30: 1
A31: Tiles Hit | B31: 1 | C31: 1 | D31: 1 | E31: 1 | F31: 1
A32: Damage | B32: 4 | C32: 4 | D32: 4 | E32: 4 | F32: 0
A33: Range | B33: =IFERROR(VLOOKUP(B$30,range_Power,2,TRUE),0) | C33: =IFERROR(VLOOKUP(C$30,range_Power,2,TRUE),0) | D33: =IFERROR(VLOOKUP(D$30,range_Power,2,TRUE),0) | E33: =IFERROR(VLOOKUP(E$30,range_Power,2,TRUE),0) | F33: =IFERROR(VLOOKUP(F$30,range_Power,2,TRUE),0)
A34: Poison Total | B34: 0 | C34: 0 | D34: 0 | E34: 0 | F34: 0
A35: Heal | B35: 0 | C35: 0 | D35: 0 | E35: 0 | F35: 0
A36: Shield | B36: 0 | C36: 0 | D36: 0 | E36: 0 | F36: 0
A37: Block Total | B37: 0 | C37: 0 | D37: 0 | E37: 0 | F37: 0
A38: Parry | B38: 0 | C38: 0 | D38: 0 | E38: 0 | F38: 0
A39: Dodge | B39: 0 | C39: 0 | D39: 0 | E39: 0 | F39: 0
A40: Strength | B40: 0 | C40: 0 | D40: 0 | E40: 0 | F40: 0
A41: Weaken | B41: 0 | C41: 0 | D41: 0 | E41: 0 | F41: 0
A42: Vulnerable | B42: 0 | C42: 0 | D42: 0 | E42: 0 | F42: 0
A43: Frozen | B43: 0 | C43: 0 | D43: 0 | E43: 0 | F43: 0
A44: Rooted | B44: 0 | C44: 0 | D44: 0 | E44: 0 | F44: 0
A45: Taunt | B45: 0 | C45: 0 | D45: 0 | E45: 0 | F45: 0
...

Sheet Skeleton
A1: Enemy Name | B1: Skeleton
A2: Boss | B2: No
A3: GUID | B3: 909b3cba860296d47997ee7846ec93f8
A4: Sync | B4: =IF($B$3="","NEW","Live")
A6: Stats (synced to Unity)
A7: Display Name | B7: Skeleton
A8: Health | B8: 30
A9: Actions Per Turn | B9: 1
A10: Brain | B10: Warrior
A11: Targeting | B11: Closest
A12: Loot Table | B12: EarlyGame
A13: Role | B13: Frontline
A15: Brandon's Power Level | B15: 1.5
A16: Estimated Power Level | B16: =IF($B$8="","",ROUND(($B$19*$B$9*pw_ActionScale+$B$8*pw_Health)/pw_Divisor,3))
A17: Delta (Estimated - Brandon's) | B17: =IF($B$15="","",ROUND($B$16-$B$15,3))
A19: Average Card Power | B19: =IFERROR(AVERAGEIF(B$26:F$26,"Yes",B$54:F$54),0)
A20: Average Damage | B20: =IFERROR(AVERAGEIF(B$26:F$26,"Yes",B$32:F$32),0)
A21: Average Status Power | B21: =IFERROR(AVERAGEIF(B$26:F$26,"Yes",B$55:F$55),0)
A22: Average Summon Power | B22: =IFERROR(AVERAGEIF(B$26:F$26,"Yes",B$52:F$52),0)
A24: Deck | B24: BoneBulwark | C24: BoneBulwark | D24: BoneBulwark | E24: BoneBulwark | F24: MoveInnate
A25: Actions from Card | B25: 3 damage, Shield 5 | C25: 3 damage, Shield 5 | D25: 3 damage, Shield 5 | E25: 3 damage, Shield 5 | F25: Move 1
A26: Counted | B26: Yes | C26: Yes | D26: Yes | E26: Yes | F26: No
A28: Card Facts
A29: Cost | B29: 1 | C29: 1 | D29: 1 | E29: 1 | F29: 1
A30: Range Max | B30: 1 | C30: 1 | D30: 1 | E30: 1 | F30: 1
A31: Tiles Hit | B31: 1 | C31: 1 | D31: 1 | E31: 1 | F31: 1
A32: Damage | B32: 3 | C32: 3 | D32: 3 | E32: 3 | F32: 0
A33: Range | B33: =IFERROR(VLOOKUP(B$30,range_Power,2,TRUE),0) | C33: =IFERROR(VLOOKUP(C$30,range_Power,2,TRUE),0) | D33: =IFERROR(VLOOKUP(D$30,range_Power,2,TRUE),0) | E33: =IFERROR(VLOOKUP(E$30,range_Power,2,TRUE),0) | F33: =IFERROR(VLOOKUP(F$30,range_Power,2,TRUE),0)
A34: Poison Total | B34: 0 | C34: 0 | D34: 0 | E34: 0 | F34: 0
A35: Heal | B35: 0 | C35: 0 | D35: 0 | E35: 0 | F35: 0
A36: Shield | B36: 5 | C36: 5 | D36: 5 | E36: 5 | F36: 0
A37: Block Total | B37: 0 | C37: 0 | D37: 0 | E37: 0 | F37: 0
A38: Parry | B38: 0 | C38: 0 | D38: 0 | E38: 0 | F38: 0
A39: Dodge | B39: 0 | C39: 0 | D39: 0 | E39: 0 | F39: 0
A40: Strength | B40: 0 | C40: 0 | D40: 0 | E40: 0 | F40: 0
A41: Weaken | B41: 0 | C41: 0 | D41: 0 | E41: 0 | F41: 0
A42: Vulnerable | B42: 0 | C42: 0 | D42: 0 | E42: 0 | F42: 0
A43: Frozen | B43: 0 | C43: 0 | D43: 0 | E43: 0 | F43: 0
A44: Rooted | B44: 0 | C44: 0 | D44: 0 | E44: 0 | F44: 0
A45: Taunt | B45: 0 | C45: 0 | D45: 0 | E45: 0 | F45: 0
...

Sheet SkeletonAlly
A1: Enemy Name | B1: SkeletonAlly
A2: Boss | B2: No
A3: GUID | B3: eaade4b777fd45447af03588cf3692e5
A4: Sync | B4: =IF($B$3="","NEW","Live")
A6: Stats (synced to Unity)
A7: Display Name | B7: Skeleton
A8: Health | B8: 15
A9: Actions Per Turn | B9: 1
A10: Brain | B10: Warrior
A11: Targeting
A12: Loot Table
A13: Role | B13: None
A15: Brandon's Power Level | B15: 2
A16: Estimated Power Level | B16: =IF($B$8="","",ROUND(($B$19*$B$9*pw_ActionScale+$B$8*pw_Health)/pw_Divisor,3))
A17: Delta (Estimated - Brandon's) | B17: =IF($B$15="","",ROUND($B$16-$B$15,3))
A19: Average Card Power | B19: =IFERROR(AVERAGEIF(B$26:E$26,"Yes",B$54:E$54),0)
A20: Average Damage | B20: =IFERROR(AVERAGEIF(B$26:E$26,"Yes",B$32:E$32),0)
A21: Average Status Power | B21: =IFERROR(AVERAGEIF(B$26:E$26,"Yes",B$55:E$55),0)
A22: Average Summon Power | B22: =IFERROR(AVERAGEIF(B$26:E$26,"Yes",B$52:E$52),0)
A24: Deck | B24: EnemySlash | C24: EnemySlash | D24: MoveInnate | E24: MoveInnate
A25: Actions from Card | B25: 8 damage | C25: 8 damage | D25: Move 1 | E25: Move 1
A26: Counted | B26: Yes | C26: Yes | D26: No | E26: No
A28: Card Facts
A29: Cost | B29: 1 | C29: 1 | D29: 1 | E29: 1
A30: Range Max | B30: 1 | C30: 1 | D30: 1 | E30: 1
A31: Tiles Hit | B31: 1 | C31: 1 | D31: 1 | E31: 1
A32: Damage | B32: 8 | C32: 8 | D32: 0 | E32: 0
A33: Range | B33: =IFERROR(VLOOKUP(B$30,range_Power,2,TRUE),0) | C33: =IFERROR(VLOOKUP(C$30,range_Power,2,TRUE),0) | D33: =IFERROR(VLOOKUP(D$30,range_Power,2,TRUE),0) | E33: =IFERROR(VLOOKUP(E$30,range_Power,2,TRUE),0)
A34: Poison Total | B34: 0 | C34: 0 | D34: 0 | E34: 0
A35: Heal | B35: 0 | C35: 0 | D35: 0 | E35: 0
A36: Shield | B36: 0 | C36: 0 | D36: 0 | E36: 0
A37: Block Total | B37: 0 | C37: 0 | D37: 0 | E37: 0
A38: Parry | B38: 0 | C38: 0 | D38: 0 | E38: 0
A39: Dodge | B39: 0 | C39: 0 | D39: 0 | E39: 0
A40: Strength | B40: 0 | C40: 0 | D40: 0 | E40: 0
A41: Weaken | B41: 0 | C41: 0 | D41: 0 | E41: 0
A42: Vulnerable | B42: 0 | C42: 0 | D42: 0 | E42: 0
A43: Frozen | B43: 0 | C43: 0 | D43: 0 | E43: 0
A44: Rooted | B44: 0 | C44: 0 | D44: 0 | E44: 0
A45: Taunt | B45: 0 | C45: 0 | D45: 0 | E45: 0
...

Sheet SkeletonWarrior
A1: Enemy Name | B1: SkeletonWarrior
A2: Boss | B2: No
A3: GUID | B3: d1b7793de9d268945bdf70cf0af39a94
A4: Sync | B4: =IF($B$3="","NEW","Live")
A6: Stats (synced to Unity)
A7: Display Name | B7: Skeleton Warrior
A8: Health | B8: 40
A9: Actions Per Turn | B9: 1
A10: Brain | B10: Warrior
A11: Targeting | B11: Closest
A12: Loot Table | B12: EarlyGame
A13: Role | B13: Frontline
A15: Brandon's Power Level | B15: 3
A16: Estimated Power Level | B16: =IF($B$8="","",ROUND(($B$19*$B$9*pw_ActionScale+$B$8*pw_Health)/pw_Divisor,3))
A17: Delta (Estimated - Brandon's) | B17: =IF($B$15="","",ROUND($B$16-$B$15,3))
A19: Average Card Power | B19: =IFERROR(AVERAGEIF(B$26:F$26,"Yes",B$54:F$54),0)
A20: Average Damage | B20: =IFERROR(AVERAGEIF(B$26:F$26,"Yes",B$32:F$32),0)
A21: Average Status Power | B21: =IFERROR(AVERAGEIF(B$26:F$26,"Yes",B$55:F$55),0)
A22: Average Summon Power | B22: =IFERROR(AVERAGEIF(B$26:F$26,"Yes",B$52:F$52),0)
A24: Deck | B24: EnemySlash | C24: MoveInnate2 | D24: EnemySlash | E24: EnemySlash | F24: EnemySlash
A25: Actions from Card | B25: 8 damage | C25: Move 2 | D25: 8 damage | E25: 8 damage | F25: 8 damage
A26: Counted | B26: Yes | C26: No | D26: Yes | E26: Yes | F26: Yes
A28: Card Facts
A29: Cost | B29: 1 | C29: 1 | D29: 1 | E29: 1 | F29: 1
